Workbook

Sheet 趋势查询
A1: 作品名称： | B1: 师途
A2: 在黄色格子里输入作品名，或点右侧小箭头从列表里选；空白表示当时没有数据（未上榜）
A4: 日期 | B4: 付费榜排名 | C4: 人气日增 | D4: 收藏日增 | E4: 点赞日增
A5: 2026-10-05 | B5: =IFERROR(INDEX('付费榜每日排名'!$A$1:$N$362,MATCH($B$1,'付费榜每日排名'!$A$1:$A$362,0),MATCH($A5,'付费榜每日排名'!$A$1:$N$1,0)),NA()) | C5: =IFERROR(INDEX('人气日增'!$A$1:$M$548,MATCH($B$1,'人气日增'!$A$1:$A$548,0),MATCH($A5,'人气日增'!$A$1:$M$1,0)),NA()) | D5: =IFERROR(INDEX('收藏日增'!$A$1:$M$548,MATCH($B$1,'收藏日增'!$A$1:$A$548,0),MATCH($A5,'收藏日增'!$A$1:$M$1,0)),NA()) | E5: =IFERROR(INDEX('点赞日增'!$A$1:$M$548,MATCH($B$1,'点赞日增'!$A$1:$A$548,0),MATCH($A5,'点赞日增'!$A$1:$M$1,0)),NA())
A6: 2026-10-06 | B6: =IFERROR(INDEX('付费榜每日排名'!$A$1:$N$362,MATCH($B$1,'付费榜每日排名'!$A$1:$A$362,0),MATCH($A6,'付费榜每日排名'!$A$1:$N$1,0)),NA()) | C6: =IFERROR(INDEX('人气日增'!$A$1:$M$548,MATCH($B$1,'人气日增'!$A$1:$A$548,0),MATCH($A6,'人气日增'!$A$1:$M$1,0)),NA()) | D6: =IFERROR(INDEX('收藏日增'!$A$1:$M$548,MATCH($B$1,'收藏日增'!$A$1:$A$548,0),MATCH($A6,'收藏日增'!$A$1:$M$1,0)),NA()) | E6: =IFERROR(INDEX('点赞日增'!$A$1:$M$548,MATCH($B$1,'点赞日增'!$A$1:$A$548,0),MATCH($A6,'点赞日增'!$A$1:$M$1,0)),NA())
A7: 2026-10-07 | B7: =IFERROR(INDEX('付费榜每日排名'!$A$1:$N$362,MATCH($B$1,'付费榜每日排名'!$A$1:$A$362,0),MATCH($A7,'付费榜每日排名'!$A$1:$N$1,0)),NA()) | C7: =IFERROR(INDEX('人气日增'!$A$1:$M$548,MATCH($B$1,'人气日增'!$A$1:$A$548,0),MATCH($A7,'人气日增'!$A$1:$M$1,0)),NA()) | D7: =IFERROR(INDEX('收藏日增'!$A$1:$M$548,MATCH($B$1,'收藏日增'!$A$1:$A$548,0),MATCH($A7,'收藏日增'!$A$1:$M$1,0)),NA()) | E7: =IFERROR(INDEX('点赞日增'!$A$1:$M$548,MATCH($B$1,'点赞日增'!$A$1:$A$548,0),MATCH($A7,'点赞日增'!$A$1:$M$1,0)),NA())
A8: 2026-10-08 | B8: =IFERROR(INDEX('付费榜每日排名'!$A$1:$N$362,MATCH($B$1,'付费榜每日排名'!$A$1:$A$362,0),MATCH($A8,'付费榜每日排名'!$A$1:$N$1,0)),NA()) | C8: =IFERROR(INDEX('人气日增'!$A$1:$M$548,MATCH($B$1,'人气日增'!$A$1:$A$548,0),MATCH($A8,'人气日增'!$A$1:$M$1,0)),NA()) | D8: =IFERROR(INDEX('收藏日增'!$A$1:$M$548,MATCH($B$1,'收藏日增'!$A$1:$A$548,0),MATCH($A8,'收藏日增'!$A$1:$M$1,0)),NA()) | E8: =IFERROR(INDEX('点赞日增'!$A$1:$M$548,MATCH($B$1,'点赞日增'!$A$1:$A$548,0),MATCH($A8,'点赞日增'!$A$1:$M$1,0)),NA())
A9: 2026-10-09 | B9: =IFERROR(INDEX('付费榜每日排名'!$A$1:$N$362,MATCH($B$1,'付费榜每日排名'!$A$1:$A$362,0),MATCH($A9,'付费榜每日排名'!$A$1:$N$1,0)),NA()) | C9: =IFERROR(INDEX('人气日增'!$A$1:$M$548,MATCH($B$1,'人气日增'!$A$1:$A$548,0),MATCH($A9,'人气日增'!$A$1:$M$1,0)),NA()) | D9: =IFERROR(INDEX('收藏日增'!$A$1:$M$548,MATCH($B$1,'收藏日增'!$A$1:$A$548,0),MATCH($A9,'收藏日增'!$A$1:$M$1,0)),NA()) | E9: =IFERROR(INDEX('点赞日增'!$A$1:$M$548,MATCH($B$1,'点赞日增'!$A$1:$A$548,0),MATCH($A9,'点赞日增'!$A$1:$M$1,0)),NA())
A10: 2026-10-10 | B10: =IFERROR(INDEX('付费榜每日排名'!$A$1:$N$362,MATCH($B$1,'付费榜每日排名'!$A$1:$A$362,0),MATCH($A10,'付费榜每日排名'!$A$1:$N$1,0)),NA()) | C10: =IFERROR(INDEX('人气日增'!$A$1:$M$548,MATCH($B$1,'人气日增'!$A$1:$A$548,0),MATCH($A10,'人气日增'!$A$1:$M$1,0)),NA()) | D10: =IFERROR(INDEX('收藏日增'!$A$1:$M$548,MATCH($B$1,'收藏日增'!$A$1:$A$548,0),MATCH($A10,'收藏日增'!$A$1:$M$1,0)),NA()) | E10: =IFERROR(INDEX('点赞日增'!$A$1:$M$548,MATCH($B$1,'点赞日增'!$A$1:$A$548,0),MATCH($A10,'点赞日增'!$A$1:$M$1,0)),NA())
A11: 2026-10-11 | B11: =IFERROR(INDEX('付费榜每日排名'!$A$1:$N$362,MATCH($B$1,'付费榜每日排名'!$A$1:$A$362,0),MATCH($A11,'付费榜每日排名'!$A$1:$N$1,0)),NA()) | C11: =IFERROR(INDEX('人气日增'!$A$1:$M$548,MATCH($B$1,'人气日增'!$A$1:$A$548,0),MATCH($A11,'人气日增'!$A$1:$M$1,0)),NA()) | D11: =IFERROR(INDEX('收藏日增'!$A$1:$M$548,MATCH($B$1,'收藏日增'!$A$1:$A$548,0),MATCH($A11,'收藏日增'!$A$1:$M$1,0)),NA()) | E11: =IFERROR(INDEX('点赞日增'!$A$1:$M$548,MATCH($B$1,'点赞日增'!$A$1:$A$548,0),MATCH($A11,'点赞日增'!$A$1:$M$1,0)),NA())
A12: 2026-10-12 | B12: =IFERROR(INDEX('付费榜每日排名'!$A$1:$N$362,MATCH($B$1,'付费榜每日排名'!$A$1:$A$362,0),MATCH($A12,'付费榜每日排名'!$A$1:$N$1,0)),NA()) | C12: =IFERROR(INDEX('人气日增'!$A$1:$M$548,MATCH($B$1,'人气日增'!$A$1:$A$548,0),MATCH($A12,'人气日增'!$A$1:$M$1,0)),NA()) | D12: =IFERROR(INDEX('收藏日增'!$A$1:$M$548,MATCH($B$1,'收藏日增'!$A$1:$A$548,0),MATCH($A12,'收藏日增'!$A$1:$M$1,0)),NA()) | E12: =IFERROR(INDEX('点赞日增'!$A$1:$M$548,MATCH($B$1,'点赞日增'!$A$1:$A$548,0),MATCH($A12,'点赞日增'!$A$1:$M$1,0)),NA())
A13: 2026-10-13 | B13: =IFERROR(INDEX('付费榜每日排名'!$A$1:$N$362,MATCH($B$1,'付费榜每日排名'!$A$1:$A$362,0),MATCH($A13,'付费榜每日排名'!$A$1:$N$1,0)),NA()) | C13: =IFERROR(INDEX('人气日增'!$A$1:$M$548,MATCH($B$1,'人气日增'!$A$1:$A$548,0),MATCH($A13,'人气日增'!$A$1:$M$1,0)),NA()) | D13: =IFERROR(INDEX('收藏日增'!$A$1:$M$548,MATCH($B$1,'收藏日增'!$A$1:$A$548,0),MATCH($A13,'收藏日增'!$A$1:$M$1,0)),NA()) | E13: =IFERROR(INDEX('点赞日增'!$A$1:$M$548,MATCH($B$1,'点赞日增'!$A$1:$A$548,0),MATCH($A13,'点赞日增'!$A$1:$M$1,0)),NA())
A14: 2026-10-14 | B14: =IFERROR(INDEX('付费榜每日排名'!$A$1:$N$362,MATCH($B$1,'付费榜每日排名'!$A$1:$A$362,0),MATCH($A14,'付费榜每日排名'!$A$1:$N$1,0)),NA()) | C14: =IFERROR(INDEX('人气日增'!$A$1:$M$548,MATCH($B$1,'人气日增'!$A$1:$A$548,0),MATCH($A14,'人气日增'!$A$1:$M$1,0)),NA()) | D14: =IFERROR(INDEX('收藏日增'!$A$1:$M$548,MATCH($B$1,'收藏日增'!$A$1:$A$548,0),MATCH($A14,'收藏日增'!$A$1:$M$1,0)),NA()) | E14: =IFERROR(INDEX('点赞日增'!$A$1:$M$548,MATCH($B$1,'点赞日增'!$A$1:$A$548,0),MATCH($A14,'点赞日增'!$A$1:$M$1,0)),NA())
A15: 2026-10-15 | B15: =IFERROR(INDEX('付费榜每日排名'!$A$1:$N$362,MATCH($B$1,'付费榜每日排名'!$A$1:$A$362,0),MATCH($A15,'付费榜每日排名'!$A$1:$N$1,0)),NA()) | C15: =IFERROR(INDEX('人气日增'!$A$1:$M$548,MATCH($B$1,'人气日增'!$A$1:$A$548,0),MATCH($A15,'人气日增'!$A$1:$M$1,0)),NA()) | D15: =IFERROR(INDEX('收藏日增'!$A$1:$M$548,MATCH($B$1,'收藏日增'!$A$1:$A$548,0),MATCH($A15,'收藏日增'!$A$1:$M$1,0)),NA()) | E15: =IFERROR(INDEX('点赞日增'!$A$1:$M$548,MATCH($B$1,'点赞日增'!$A$1:$A$548,0),MATCH($A15,'点赞日增'!$A$1:$M$1,0)),NA())
A16: 2026-10-16 | B16: =IFERROR(INDEX('付费榜每日排名'!$A$1:$N$362,MATCH($B$1,'付费榜每日排名'!$A$1:$A$362,0),MATCH($A16,'付费榜每日排名'!$A$1:$N$1,0)),NA()) | C16: =IFERROR(INDEX('人气日增'!$A$1:$M$548,MATCH($B$1,'人气日增'!$A$1:$A$548,0),MATCH($A16,'人气日增'!$A$1:$M$1,0)),NA()) | D16: =IFERROR(INDEX('收藏日增'!$A$1:$M$548,MATCH($B$1,'收藏日增'!$A$1:$A$548,0),MATCH($A16,'收藏日增'!$A$1:$M$1,0)),NA()) | E16: =IFERROR(INDEX('点赞日增'!$A$1:$M$548,MATCH($B$1,'点赞日增'!$A$1:$A$548,0),MATCH($A16,'点赞日增'!$A$1:$M$1,0)),NA())
A17: 2026-10-17 | B17: =IFERROR(INDEX('付费榜每日排名'!$A$1:$N$362,MATCH($B$1,'付费榜每日排名'!$A$1:$A$362,0),MATCH($A17,'付费榜每日排名'!$A$1:$N$1,0)),NA()) | C17: =IFERROR(INDEX('人气日增'!$A$1:$M$548,MATCH($B$1,'人气日增'!$A$1:$A$548,0),MATCH($A17,'人气日增'!$A$1:$M$1,0)),NA()) | D17: =IFERROR(INDEX('收藏日增'!$A$1:$M$548,MATCH($B$1,'收藏日增'!$A$1:$A$548,0),MATCH($A17,'收藏日增'!$A$1:$M$1,0)),NA()) | E17: =IFERROR(INDEX('点赞日增'!$A$1:$M$548,MATCH($B$1,'点赞日增'!$A$1:$A$548,0),MATCH($A17,'点赞日增'!$A$1:$M$1,0)),NA())

Sheet 付费榜每日排名
A1: 作品名 | B1: 2026-10-05 | C1: 2026-10-06 | D1: 2026-10-07 | E1: 2026-10-08 | F1: 2026-10-09 | G1: 2026-10-10 | H1: 2026-10-11 | I1: 2026-10-12 | J1: 2026-10-13 | K1: 2026-10-14 | L1: 2026-10-15 | M1: 2026-10-16 | N1: 2026-10-17
A2: 师途 | B2: 1 | C2: 1 | D2: 1 | E2: 1 | F2: 1 | G2: 1 | H2: 1 | I2: 1 | J2: 2 | K2: 1 | L2: 1 | M2: 2 | N2: 1
A3: 临帝阙 | B3: 3 | C3: 4 | D3: 6 | E3: 5 | F3: 2 | G3: 2 | H3: 2 | I3: 3 | J3: 3 | K3: 2 | L3: 6 | M3: 3 | N3: 2
A4: 江山千秋万代 | B4: 11 | C4: 10 | D4: 10 | E4: 3 | F4: 4 | G4: 3 | H4: 3 | I4: 8 | J4: 7 | K4: 6 | L4: 3 | M4: 6 | N4: 3
A5: 宫妃 | B5: 6 | C5: 11 | D5: 12 | E5: 9 | F5: 10 | G5: 5 | H5: 4 | I5: 2 | J5: 4 | K5: 5 | L5: 2 | M5: 4 | N5: 4
A6: 星期天不上头条 | B6: 9 | C6: 8 | D6: 7 | E6: 11 | F6: 5 | G6: 6 | H6: 6 | I6: 4 | J6: 1 | K6: 7 | L6: 8 | M6: 1 | N6: 5
A7: 三界衔 | B7: 2 | C7: 3 | D7: 3 | E7: 4 | F7: 3 | G7: 4 | H7: 5 | I7: 5 | J7: 8 | K7: 8 | L7: 7 | M7: 8 | N7: 6
A8: 怪我过分美丽 | B8: 7 | C8: 9 | D8: 8 | E8: 8 | F8: 7 | G8: 7 | H8: 7 | I8: 9 | J8: 6 | K8: 3 | L8: 4 | M8: 5 | N8: 7
A9: 我在京城上头条 | B9: 174 | E9: 134 | G9: 88 | H9: 82 | J9: 83 | L9: 192 | M9: 108 | N9: 8
A10: 仙路漫漫 | B10: 10 | C10: 6 | D10: 9 | E10: 6 | F10: 11 | G10: 9 | H10: 10 | I10: 6 | J10: 5 | K10: 4 | L10: 5 | M10: 7 | N10: 9
A11: 恶女模拟器 | B11: 33 | C11: 30 | D11: 29 | E11: 19 | F11: 16 | G11: 23 | H11: 20 | I11: 18 | J11: 14 | K11: 12 | L11: 10 | M11: 9 | N11: 10
A12: 勿扰修仙中 | B12: 5 | C12: 2 | D12: 2 | E12: 10 | F12: 6 | G12: 11 | H12: 11 | I12: 12 | J12: 10 | K12: 9 | L12: 15 | M12: 10 | N12: 11
A13: 风华临安 | B13: 4 | C13: 5 | D13: 5 | E13: 2 | F13: 9 | G13: 8 | H13: 9 | I13: 7 | J13: 9 | K13: 10 | L13: 11 | M13: 12 | N13: 12
A14: AMNESIA 失忆症 | B14: 12 | C14: 12 | D14: 14 | E14: 14 | F14: 12 | G14: 12 | H14: 8 | I14: 13 | J14: 13 | K14: 13 | L14: 13 | M14: 11 | N14: 13
A15: 朕被迫上位 | B15: 98 | C15: 94 | D15: 115 | E15: 69 | F15: 49 | G15: 48 | H15: 45 | I15: 25 | J15: 18 | K15: 41 | L15: 44 | M15: 18 | N15: 14
A16: 京中叙 | B16: 18 | C16: 15 | D16: 11 | E16: 22 | F16: 19 | G16: 17 | H16: 13 | I16: 22 | J16: 20 | K16: 18 | L16: 24 | M16: 22 | N16: 15
A17: 娱乐圈|热搜预定 | B17: 24 | C17: 20 | D17: 23 | E17: 20 | F17: 20 | G17: 13 | H17: 15 | I17: 17 | J17: 16 | K17: 14 | L17: 18 | M17: 15 | N17: 16
A18: 神也梦春秋 | B18: 8 | C18: 7 | D18: 4 | E18: 12 | F18: 13 | G18: 16 | H18: 14 | I18: 15 | J18: 12 | K18: 11 | L18: 12 | M18: 16 | N18: 17
A19: 古代主母风华录 | B19: 25 | C19: 21 | D19: 28 | E19: 17 | F19: 18 | G19: 20 | H19: 18 | I19: 21 | J19: 21 | K19: 17 | L19: 19 | M19: 20 | N19: 18
A20: 后宫升职手札 | B20: 29 | C20: 38 | D20: 47 | E20: 37 | F20: 22 | G20: 21 | H20: 23 | I20: 31 | J20: 23 | K20: 21 | L20: 26 | M20: 21 | N20: 19
A21: 世家主母日常 | B21: 43 | C21: 44 | D21: 59 | E21: 32 | F21: 25 | G21: 22 | H21: 26 | I21: 27 | J21: 22 | K21: 27 | L21: 21 | M21: 23 | N21: 20
... A24: 替兄嫁了公主后 | B24: 37 | C24: 29 | D24: 44 | E24: 35 | F24: 34 | G24: 29 | H24: 24 | I24: 20 | J24: 33 | K24: 34 | L24: 28 | M24: 31 | N24: 23
A25: 成为团播TOP之后 | D25: 15 | E25: 7 | F25: 8 | G25: 10 | H25: 12 | I25: 11 | J25: 11 | K25: 15 | L25: 16 | M25: 14 | N25: 24
A26: 山河长憾 | B26: 28 | C26: 19 | D26: 21 | E26: 72 | F26: 39 | G26: 42 | H26: 52 | I26: 63 | J26: 63 | K26: 64 | L26: 45 | M26: 57 | N26: 25
A27: 妄情债 | B27: 22 | C27: 25 | D27: 35 | E27: 18 | F27: 33 | G27: 31 | H27: 31 | I27: 38 | J27: 35 | K27: 47 | L27: 30 | M27: 32 | N27: 26
A28: 虔诚之花的晚钟 | B28: 42 | C28: 37 | D28: 54 | E28: 40 | F28: 29 | G28: 24 | H28: 29 | I28: 43 | J28: 32 | K28: 42 | L28: 23 | M28: 30 | N28: 27
A29: 帝宴千秋 | B29: 13 | C29: 16 | D29: 22 | E29: 16 | F29: 15 | G29: 14 | H29: 34 | I29: 28 | J29: 17 | K29: 24 | L29: 31 | M29: 34 | N29: 28
A30: 凭什么我是反派 | B30: 52 | C30: 27 | D30: 39 | E30: 28 | F30: 23 | G30: 15 | H30: 21 | I30: 34 | J30: 28 | K30: 36 | L30: 37 | M30: 40 | N30: 29
A31: 并不是一般穿游 | B31: 39 | C31: 26 | D31: 51 | E31: 21 | F31: 31 | G31: 41 | H31: 39 | I31: 41 | J31: 27 | K31: 20 | L31: 22 | M31: 27 | N31: 30
A32: 天纵 | B32: 35 | C32: 24 | D32: 26 | E32: 36 | F32: 24 | G32: 37 | H32: 28 | I32: 23 | J32: 30 | K32: 35 | L32: 27 | M32: 25 | N32: 31
A33: 你的私有玩物们 | B33: 64 | C33: 62 | D33: 106 | E33: 65 | F33: 46 | G33: 62 | H33: 57 | I33: 70 | J33: 59 | K33: 63 | L33: 51 | M33: 35 | N33: 32
A34: 纵神欢 | B34: 66 | C34: 51 | D34: 57 | E34: 23 | F34: 59 | G34: 40 | H34: 50 | I34: 37 | J34: 44 | K34: 48 | L34: 42 | M34: 36 | N34: 33
A35: 国际女团出道战 | B35: 67 | C35: 112 | D35: 78 | E35: 57 | F35: 48 | G35: 25 | H35: 19 | I35: 80 | J35: 43 | K35: 67 | L35: 60 | M35: 42 | N35: 34
A36: 从寒门开始 | B36: 108 | C36: 98 | D36: 141 | E36: 93 | F36: 105 | G36: 82 | H36: 53 | I36: 72 | J36: 47 | K36: 91 | L36: 84 | N36: 35
A37: 赴韶光 | B37: 27 | C37: 23 | D37: 16 | E37: 15 | F37: 17 | G37: 19 | H37: 30 | I37: 30 | J37: 24 | K37: 37 | L37: 29 | M37: 28 | N37: 36
A38: 闪耀48区 | B38: 93 | C38: 84 | D38: 77 | E38: 159 | F38: 80 | G38: 68 | H38: 87 | I38: 79 | J38: 48 | K38: 40 | L38: 53 | M38: 46 | N38: 37
A39: 仙履奇谈 | B39: 32 | C39: 45 | D39: 38 | E39: 24 | F39: 54 | G39: 66 | H39: 17 | I39: 48 | J39: 68 | K39: 52 | L39: 52 | M39: 105 | N39: 38
A40: 后宫群妃录 | B40: 110 | C40: 107 | D40: 36 | E40: 48 | F40: 52 | G40: 50 | H40: 77 | I40: 40 | J40: 15 | K40: 22 | L40: 34 | M40: 26 | N40: 39
A41: 暗卫他又跑 | B41: 38 | C41: 41 | D41: 37 | E41: 53 | F41: 57 | G41: 75 | H41: 36 | I41: 53 | J41: 42 | K41: 29 | L41: 48 | M41: 41 | N41: 40
A42: 青宫赋 | B42: 36 | C42: 64 | D42: 53 | E42: 44 | F42: 26 | G42: 38 | H42: 42 | I42: 58 | J42: 45 | K42: 31 | L42: 41 | M42: 45 | N42: 41
...

Sheet 人气日增
A1: 作品名 | B1: 2026-10-06 | C1: 2026-10-07 | D1: 2026-10-08 | E1: 2026-10-09 | F1: 2026-10-10 | G1: 2026-10-11 | H1: 2026-10-12 | I1: 2026-10-13 | J1: 2026-10-14 | K1: 2026-10-15 | L1: 2026-10-16 | M1: 2026-10-17
A2: 临帝阙 | B2: 103193 | C2: 94977 | D2: 64808 | E2: 71285 | F2: 75280 | G2: 81087 | H2: 55901 | I2: 52193 | J2: 47717 | K2: 46533 | L2: 63834 | M2: 116905
A3: 江山千秋万代 | B3: 48022 | C3: 53639 | D3: 56539 | E3: 49756 | F3: 39461 | G3: 58116 | H3: 40284 | I3: 36673 | J3: 44904 | K3: 54590 | L3: 46133 | M3: 56646
A4: 师途 | B4: 76181 | C4: 53921 | D4: 45453 | E4: 39073 | F4: 38814 | G4: 48516 | H4: 37392 | I4: 35329 | J4: 33642 | K4: 32512 | L4: 32179 | M4: 53682
A5: 怪我过分美丽 | B5: 39772 | C5: 29506 | D5: 27353 | E5: 35435 | F5: 24561 | G5: 30147 | H5: 44314 | I5: 41789 | J5: 37470 | K5: 37053 | L5: 36300 | M5: 43209
A6: 捉鬼师后日谈 | B6: 53815 | C6: 39853 | D6: 22703 | E6: 19426 | F6: 21808 | G6: 36764 | H6: 21425 | I6: 20546 | J6: 14304 | K6: 21129 | L6: 19897 | M6: 42443
A7: 三界衔 | B7: 74410 | C7: 55994 | D7: 30894 | E7: 34405 | F7: 32543 | G7: 42446 | H7: 30359 | I7: 22539 | J7: 20203 | K7: 22216 | L7: 25862 | M7: 35151
A8: 勿扰修仙中 | B8: 48669 | C8: 37484 | D8: 32441 | E8: 22460 | F8: 20984 | G8: 24472 | H8: 18250 | I8: 16826 | J8: 12807 | K8: 16864 | L8: 19544 | M8: 34353
A9: 星期天不上头条 | B9: 43755 | C9: 30616 | D9: 28075 | E9: 32313 | F9: 31964 | G9: 41356 | H9: 31825 | I9: 34139 | J9: 26654 | K9: 28958 | L9: 23273 | M9: 33433
A10: 京中叙 | B10: 41622 | C10: 38275 | D10: 12922 | E10: 21147 | F10: 14200 | G10: 38682 | H10: 15794 | I10: 11951 | J10: 18237 | K10: 15371 | L10: 17133 | M10: 30307
A11: 风华临安 | B11: 53313 | C11: 42032 | D11: 28571 | E11: 27532 | F11: 26191 | G11: 34463 | H11: 20718 | I11: 21319 | J11: 19198 | K11: 18172 | L11: 21325 | M11: 26294
A12: 娱乐圈|热搜预定 | B12: 43797 | C12: 30162 | D12: 28815 | E12: 28633 | F12: 23899 | G12: 37226 | H12: 30114 | I12: 23176 | J12: 17685 | K12: 24549 | L12: 28430 | M12: 25390
A13: 世家主母日常 | B13: 14481 | C13: 10357 | D13: 9364 | E13: 8900 | F13: 17677 | G13: 14884 | H13: 10344 | I13: 9519 | J13: 8631 | K13: 8272 | L13: 8803 | M13: 25101
... A19: 并不是一般穿游 | B19: 26536 | C19: 17205 | D19: 12405 | E19: 11408 | F19: 13402 | G19: 17405 | H19: 13066 | I19: 28373 | J19: 13031 | K19: 16223 | L19: 13195 | M19: 20857
A20: 第六视角 | M20: 20736
A21: 山河长憾 | B21: 16883 | C21: 20923 | D21: 10029 | E21: 12069 | F21: 10839 | G21: 14336 | H21: 6628 | I21: 7271 | J21: 10049 | K21: 6978 | L21: 11640 | M21: 20498
A22: 仙路漫漫 | B22: 31194 | C22: 19315 | D22: 16054 | E22: 13047 | F22: 12819 | G22: 15911 | H22: 16946 | I22: 16249 | J22: 13827 | K22: 13571 | L22: 13587 | M22: 20200
A23: AMNESIA 失忆症 | B23: 24293 | C23: 17939 | D23: 12459 | E23: 10700 | F23: 11660 | G23: 18200 | H23: 10820 | I23: 10128 | J23: 8629 | K23: 9236 | L23: 10102 | M23: 19171
A24: 妄情债 | B24: 22344 | C24: 18317 | D24: 12690 | E24: 9124 | F24: 8847 | G24: 16368 | H24: 10395 | I24: 8371 | J24: 8095 | K24: 10915 | L24: 14442 | M24: 15824
A25: 凭什么我是反派 | B25: 10924 | C25: 8099 | D25: 6520 | E25: 5564 | F25: 9429 | G25: 12856 | H25: 7106 | I25: 6173 | J25: 4239 | K25: 5846 | L25: 6256 | M25: 15460
A26: 金珠遗梦 | B26: 13309 | C26: 16760 | D26: 9337 | E26: 10685 | F26: 7907 | G26: 9421 | H26: 12024 | I26: 8412 | J26: 6540 | K26: 5589 | L26: 7543 | M26: 15206
A27: 成为团播TOP之后 | D27: 19204 | E27: 18095 | F27: 19616 | G27: 23630 | H27: 12481 | I27: 12978 | J27: 10785 | K27: 9037 | L27: 15249 | M27: 14654
A28: 宫妃 | B28: 12347 | C28: 8465 | D28: 8289 | E28: 7664 | F28: 7874 | G28: 10438 | H28: 9972 | I28: 9761 | J28: 8822 | K28: 8331 | L28: 8552 | M28: 14206
A29: 世系长歌 | B29: 17724 | C29: 12556 | D29: 7972 | E29: 11147 | F29: 11023 | G29: 11503 | H29: 7436 | I29: 10096 | J29: 7607 | K29: 7820 | L29: 9714 | M29: 14055
A30: 入罗帷 | B30: 16859 | C30: 15230 | D30: 10430 | E30: 9433 | F30: 11047 | G30: 13998 | H30: 7359 | I30: 8631 | J30: 6942 | K30: 5468 | L30: 10076 | M30: 13813
A31: 由我改君命 | B31: 25950 | C31: 18876 | D31: 6550 | E31: 5833 | F31: 6562 | G31: 12789 | H31: 5038 | I31: 5384 | J31: 5045 | K31: 4557 | L31: 6140 | M31: 12493
A32: 帝宴千秋 | B32: 26108 | C32: 17298 | D32: 13857 | E32: 12402 | F32: 13602 | G32: 15004 | H32: 11663 | I32: 10398 | J32: 10399 | K32: 7213 | L32: 7923 | M32: 12392
A33: 后妃成长录 | B33: 12597 | C33: 11703 | D33: 10587 | E33: 10248 | F33: 7650 | G33: 11607 | H33: 9068 | I33: 10819 | J33: 6600 | K33: 8407 | L33: 7425 | M33: 11567
A34: 残霜烬 | B34: 14313 | C34: 9264 | D34: 4355 | E34: 4783 | F34: 5791 | G34: 10935 | H34: 4914 | I34: 4883 | J34: 4467 | K34: 4530 | L34: 6366 | M34: 11514
A35: 古代主母风华录 | B35: 12630 | C35: 8946 | D35: 13303 | E35: 8371 | F35: 11230 | G35: 9977 | H35: 7375 | I35: 10988 | J35: 6542 | K35: 7665 | L35: 6680 | M35: 10950
A36: 谋仙渡 | B36: 26327 | C36: 18563 | D36: 10868 | E36: 7104 | F36: 6365 | G36: 14202 | H36: 6743 | I36: 5363 | J36: 6231 | K36: 6049 | L36: 7146 | M36: 10639
A37: 恐游病娇boss爱的追逐战 | B37: 13466 | C37: 9380 | D37: 5852 | E37: 5015 | F37: 5507 | G37: 10033 | H37: 6200 | I37: 5511 | J37: 4136 | K37: 6051 | L37: 4974 | M37: 10477
A38: 朕被迫上位 | B38: 10424 | C38: 6828 | D38: 4927 | E38: 7212 | F38: 7051 | G38: 8785 | H38: 6035 | I38: 7118 | J38: 7700 | K38: 4903 | L38: 6269 | M38: 10346
A39: 青宫赋 | B39: 22210 | C39: 17945 | D39: 9709 | E39: 11038 | F39: 7684 | G39: 13134 | H39: 5379 | I39: 5747 | J39: 8305 | K39: 6297 | L39: 8582 | M39: 10261
... A56: 恋春深 | B56: 3193 | C56: 2096 | D56: 1429 | E56: 1425 | F56: 1634 | G56: 2343 | H56: 2600 | I56: 4326 | J56: 4119 | K56: 4202 | L56: 5170 | M56: 7836
A57: 娱乐圈·逐梦星光 | G57: 29986 | H57: 9801 | I57: 6368 | J57: 5214 | K57: 4103 | L57: 5270 | M57: 7722
A58: 夏日相悖论 | B58: 14551 | C58: 10835 | D58: 5321 | E58: 4911 | F58: 4759 | G58: 8599 | H58: 3734 | I58: 3622 | J58: 3488 | K58: 3206 | L58: 4330 | M58: 7483
A59: 替兄嫁了公主后 | B59: 13186 | C59: 12132 | D59: 5650 | E59: 5235 | F59: 5354 | G59: 6967 | H59: 7321 | I59: 6387 | J59: 4457 | K59: 3766 | L59: 4800 | M59: 7459
A60: 我在古代当首富￥ | B60: 18850 | C60: 14853 | D60: 8710 | E60: 7211 | F60: 7058 | G60: 12252 | H60: 9396 | I60: 8307 | J60: 9509 | K60: 8259 | L60: 7603 | M60: 7390
A61: 我竟然是个女魔头 | B61: 4317 | C61: 3540 | D61: 4135 | E61: 2744 | F61: 2372 | G61: 2912 | H61: 5769 | I61: 5898 | J61: 4104 | K61: 6969 | L61: 4801 | M61: 7227
...

Sheet 收藏日增
A1: 作品名 | B1: 2026-10-06 | C1: 2026-10-07 | D1: 2026-10-08 | E1: 2026-10-09 | F1: 2026-10-10 | G1: 2026-10-11 | H1: 2026-10-12 | I1: 2026-10-13 | J1: 2026-10-14 | K1: 2026-10-15 | L1: 2026-10-16 | M1: 2026-10-17
A2: 我在京城上头条 | B2: 0 | C2: 47 | D2: 59 | E2: 23 | F2: 74 | G2: 43 | H2: 42 | I2: 41 | J2: 24 | K2: 48 | L2: 54 | M2: 1360
A3: 呼叫请按铃 | B3: 443 | C3: 511 | D3: 106 | E3: 209 | F3: 416 | G3: 103 | H3: 419 | I3: 11 | J3: 145 | M3: 1266
A4: AMNESIA 失忆症 | B4: 1423 | C4: 1170 | D4: 699 | E4: 642 | F4: 858 | G4: 1129 | H4: 549 | I4: 501 | J4: 457 | K4: 531 | L4: 745 | M4: 1204
A5: 我和我哥哥 | B5: 407 | C5: 582 | D5: 608 | E5: 377 | F5: 707 | G5: 876 | H5: 309 | I5: 296 | J5: 215 | K5: 332 | L5: 537 | M5: 1052
A6: 捉鬼师后日谈 | B6: 1244 | C6: 943 | D6: 491 | E6: 417 | F6: 540 | G6: 782 | H6: 486 | I6: 348 | J6: 362 | K6: 442 | L6: 494 | M6: 1051
A7: 恶女模拟器 | B7: 196 | C7: 204 | D7: 167 | E7: 167 | F7: 138 | G7: 164 | H7: 187 | I7: 335 | J7: 363 | K7: 452 | L7: 632 | M7: 834
A8: 御妖名单 | C8: 19 | I8: 349 | J8: 196 | K8: 355 | L8: 616 | M8: 741
A9: 京中叙 | B9: 691 | C9: 513 | D9: 290 | E9: 348 | F9: 336 | G9: 515 | H9: 233 | I9: 254 | J9: 247 | K9: 195 | L9: 317 | M9: 739
A10: 统治者们 | B10: 76 | C10: 103 | D10: 63 | E10: 27 | F10: 105 | G10: 156 | H10: 313 | I10: 327 | J10: 358 | K10: 355 | L10: 447 | M10: 699
A11: 灰日告白 | B11: 705 | C11: 641 | D11: 237 | E11: 186 | F11: 267 | G11: 368 | H11: 318 | I11: 161 | J11: 156 | K11: 342 | L11: 390 | M11: 665
A12: Time,Ordinary | B12: 674 | C12: 680 | D12: 286 | E12: 273 | F12: 352 | G12: 501 | H12: 207 | I12: 196 | J12: 189 | K12: 169 | L12: 256 | M12: 658
A13: 临帝阙 | B13: 738 | C13: 551 | D13: 344 | E13: 362 | F13: 409 | G13: 527 | H13: 318 | I13: 298 | J13: 290 | K13: 286 | L13: 362 | M13: 647
A14: 可视化收容所 | M14: 603
A15: 邻居是个阴湿男 | B15: 315 | C15: 307 | D15: 296 | E15: 164 | F15: 133 | G15: 202 | H15: 96 | I15: 89 | J15: 94 | K15: 105 | L15: 129 | M15: 594
A16: 江山千秋万代 | B16: 491 | C16: 402 | D16: 471 | E16: 363 | F16: 500 | G16: 594 | H16: 292 | I16: 294 | J16: 317 | K16: 307 | L16: 291 | M16: 563
A17: 姐姐请带我回家 | B17: 417 | C17: 365 | D17: 192 | E17: 293 | F17: 146 | G17: 105 | H17: 139 | I17: 138 | J17: 124 | K17: 233 | L17: 252 | M17: 540
A18: 虔诚之花的晚钟 | B18: 544 | C18: 443 | D18: 302 | E18: 287 | F18: 385 | G18: 530 | H18: 271 | I18: 222 | J18: 228 | K18: 264 | L18: 332 | M18: 538
A19: 成为团播TOP之后 | D19: 491 | E19: 607 | F19: 840 | G19: 736 | H19: 499 | I19: 452 | J19: 347 | K19: 455 | L19: 399 | M19: 531
A20: 风华临安 | B20: 898 | C20: 690 | D20: 456 | E20: 471 | F20: 497 | G20: 567 | H20: 411 | I20: 331 | J20: 356 | K20: 398 | L20: 359 | M20: 519
A21: 由我改君命 | B21: 691 | C21: 572 | D21: 241 | E21: 224 | F21: 312 | G21: 446 | H21: 229 | I21: 312 | J21: 218 | K21: 205 | L21: 300 | M21: 511
A22: 宫妃 | B22: 242 | C22: 186 | D22: 176 | E22: 227 | F22: 276 | G22: 373 | H22: 299 | I22: 313 | J22: 300 | K22: 282 | L22: 371 | M22: 506
A23: 兄长大人请赐教 | M23: 503
A24: 师途 | B24: 504 | C24: 465 | D24: 288 | E24: 270 | F24: 349 | G24: 428 | H24: 249 | I24: 229 | J24: 214 | K24: 257 | L24: 261 | M24: 483
A25: 异常代码 | C25: 175 | D25: 115 | E25: 163 | F25: 178 | G25: 387 | H25: 29 | I25: 233 | J25: 36 | K25: 94 | L25: 113 | M25: 480
A26: 恋春深 | B26: 153 | C26: 86 | D26: 67 | E26: 81 | F26: 106 | G26: 98 | H26: 198 | I26: 207 | J26: 221 | K26: 247 | L26: 290 | M26: 479
A27: 朕被迫上位 | B27: 285 | C27: 223 | D27: 202 | E27: 174 | F27: 243 | G27: 331 | H27: 302 | I27: 313 | J27: 179 | K27: 143 | L27: 297 | M27: 472
A28: 恶役大小姐养成计划 | H28: 222 | I28: 237 | J28: 255 | K28: 222 | L28: 326 | M28: 463
A29: 勿扰修仙中 | B29: 714 | C29: 575 | D29: 374 | E29: 272 | F29: 383 | G29: 323 | H29: 229 | I29: 189 | J29: 156 | K29: 163 | L29: 241 | M29: 451
A30: 吞噬：Swallow | B30: 459 | C30: 302 | D30: 179 | E30: 145 | F30: 221 | G30: 338 | H30: 193 | I30: 156 | J30: 123 | K30: 182 | L30: 177 | M30: 439
A31: 缠梦症 | B31: 398 | C31: 314 | D31: 193 | E31: 238 | F31: 246 | G31: 403 | H31: 139 | I31: 107 | J31: 152 | K31: 181 | L31: 300 | M31: 431
A32: 你的私有玩物们 | B32: 295 | C32: 222 | D32: 135 | E32: 204 | F32: 230 | G32: 259 | H32: 156 | I32: 162 | J32: 142 | K32: 208 | L32: 356 | M32: 429
A33: 我亲爱的跟踪狂 | B33: 535 | C33: 305 | D33: 111 | E33: 95 | F33: 287 | G33: 401 | H33: 162 | I33: 166 | J33: 114 | K33: 129 | L33: 191 | M33: 407
A34: 临江二中学生论坛 | B34: 445 | C34: 175 | D34: 112 | E34: 213 | F34: 224 | G34: 302 | H34: 175 | I34: 141 | J34: 165 | K34: 218 | L34: 218 | M34: 404
A35: 囚她欢 | I35: 119 | J35: 172 | K35: 176 | L35: 163 | M35: 401
A36: 非正常异能恋爱指南 | B36: 472 | C36: 372 | D36: 168 | E36: 157 | F36: 250 | G36: 305 | H36: 157 | I36: 180 | J36: 130 | K36: 181 | L36: 198 | M36: 385
A37: 被反派驯养的三十天 | I37: 192 | J37: 171 | K37: 199 | L37: 255 | M37: 378
A38: 妄情债 | B38: 505 | C38: 462 | D38: 230 | E38: 162 | F38: 221 | G38: 367 | H38: 181 | I38: 157 | J38: 204 | K38: 222 | L38: 244 | M38: 377
A39: 夏日相悖论 | B39: 334 | C39: 337 | D39: 215 | E39: 160 | F39: 257 | G39: 304 | H39: 152 | I39: 151 | J39: 147 | K39: 193 | L39: 239 | M39: 370
A40: 残霜烬 | B40: 84 | C40: 64 | D40: 19 | E40: 5 | F40: 102 | G40: 100 | H40: 39 | I40: 44 | J40: 62 | K40: 85 | L40: 223 | M40: 366
...

Sheet 点赞日增
A1: 作品名 | B1: 2026-10-06 | C1: 2026-10-07 | D1: 2026-10-08 | E1: 2026-10-09 | F1: 2026-10-10 | G1: 2026-10-11 | H1: 2026-10-12 | I1: 2026-10-13 | J1: 2026-10-14 | K1: 2026-10-15 | L1: 2026-10-16 | M1: 2026-10-17
A2: 捉鬼师后日谈 | B2: 422 | C2: 347 | D2: 136 | E2: 155 | F2: 162 | G2: 276 | H2: 157 | I2: 136 | J2: 145 | K2: 140 | L2: 164 | M2: 379
A3: AMNESIA 失忆症 | B3: 326 | C3: 269 | D3: 148 | E3: 125 | F3: 190 | G3: 253 | H3: 114 | I3: 102 | J3: 112 | K3: 108 | L3: 156 | M3: 280
A4: 呼叫请按铃 | B4: 101 | C4: 97 | D4: 20 | E4: 33 | F4: 66 | G4: 10 | H4: 77 | I4: 1 | J4: 20 | M4: 224
A5: 临帝阙 | B5: 196 | C5: 151 | D5: 94 | E5: 96 | F5: 114 | G5: 160 | H5: 77 | I5: 92 | J5: 84 | K5: 69 | L5: 125 | M5: 202
A6: 我在京城上头条 | B6: 0 | C6: 12 | D6: 5 | E6: 3 | F6: 5 | G6: 6 | H6: 1 | I6: 6 | J6: 2 | K6: 5 | L6: 9 | M6: 165
A7: 由我改君命 | B7: 164 | C7: 135 | D7: 52 | E7: 60 | F7: 73 | G7: 117 | H7: 48 | I7: 61 | J7: 53 | K7: 41 | L7: 65 | M7: 156
A8: 我和我哥哥 | B8: 61 | C8: 74 | D8: 84 | E8: 50 | F8: 83 | G8: 117 | H8: 44 | I8: 52 | J8: 35 | K8: 48 | L8: 69 | M8: 153
A9: 第六视角 | M9: 138
A10: 京中叙 | B10: 149 | C10: 63 | D10: 57 | E10: 67 | F10: 61 | G10: 110 | H10: 41 | I10: 44 | J10: 38 | K10: 49 | L10: 51 | M10: 135
A11: 灰日告白 | B11: 154 | C11: 138 | D11: 42 | E11: 36 | F11: 46 | G11: 90 | H11: 47 | I11: 33 | J11: 46 | K11: 66 | L11: 68 | M11: 133
A12: 风华临安 | B12: 258 | C12: 197 | D12: 150 | E12: 105 | F12: 113 | G12: 162 | H12: 90 | I12: 89 | J12: 91 | K12: 94 | L12: 100 | M12: 123
A13: 邻居是个阴湿男 | B13: 75 | C13: 77 | D13: 67 | E13: 29 | F13: 36 | G13: 56 | H13: 24 | I13: 25 | J13: 21 | K13: 18 | L13: 27 | M13: 120
A14: 可视化收容所 | M14: 120
A15: 师途 | B15: 137 | C15: 112 | D15: 86 | E15: 69 | F15: 84 | G15: 108 | H15: 62 | I15: 72 | J15: 58 | K15: 61 | L15: 74 | M15: 119
A16: 恶女模拟器 | B16: 39 | C16: 40 | D16: 19 | E16: 25 | F16: 16 | G16: 31 | H16: 18 | I16: 40 | J16: 53 | K16: 62 | L16: 80 | M16: 111
A17: 江山千秋万代 | B17: 93 | C17: 52 | D17: 64 | E17: 49 | F17: 92 | G17: 108 | H17: 47 | I17: 42 | J17: 53 | K17: 35 | L17: 62 | M17: 111
A18: Time,Ordinary | B18: 137 | C18: 161 | D18: 49 | E18: 41 | F18: 62 | G18: 116 | H18: 38 | I18: 33 | J18: 25 | K18: 36 | L18: 58 | M18: 111
A19: 三界衔 | B19: 141 | C19: 121 | D19: 80 | E19: 88 | F19: 112 | G19: 108 | H19: 60 | I19: 56 | J19: 51 | K19: 52 | L19: 56 | M19: 111
A20: 兄长大人请赐教 | M20: 100
A21: 恐游病娇boss爱的追逐战 | B21: 98 | C21: 60 | D21: 51 | E21: 31 | F21: 47 | G21: 113 | H21: 49 | I21: 45 | J21: 35 | K21: 41 | L21: 45 | M21: 98
A22: 残霜烬 | B22: 47 | C22: 37 | D22: 19 | E22: 15 | F22: 23 | G22: 42 | H22: 10 | I22: 8 | J22: 21 | K22: 29 | L22: 37 | M22: 97
A23: 非正常异能恋爱指南 | B23: 135 | C23: 87 | D23: 54 | E23: 49 | F23: 56 | G23: 87 | H23: 35 | I23: 33 | J23: 27 | K23: 42 | L23: 46 | M23: 96
A24: 统治者们 | B24: 21 | C24: 21 | D24: 10 | E24: 2 | F24: 7 | G24: 21 | H24: 45 | I24: 41 | J24: 47 | K24: 38 | L24: 46 | M24: 92
A25: 御妖名单 | C25: 5 | I25: 39 | J25: 17 | K25: 50 | L25: 89 | M25: 89
A26: 妄情债 | B26: 80 | C26: 81 | D26: 50 | E26: 39 | F26: 36 | G26: 73 | H26: 27 | I26: 35 | J26: 36 | K26: 32 | L26: 55 | M26: 88
A27: 吞噬：Swallow | B27: 115 | C27: 60 | D27: 37 | E27: 21 | F27: 52 | G27: 81 | H27: 26 | I27: 33 | J27: 26 | K27: 31 | L27: 38 | M27: 86
A28: 虔诚之花的晚钟 | B28: 99 | C28: 71 | D28: 61 | E28: 41 | F28: 54 | G28: 88 | H28: 50 | I28: 43 | J28: 46 | K28: 35 | L28: 54 | M28: 85
A29: 临江二中学生论坛 | B29: 114 | C29: 46 | D29: 12 | E29: 42 | F29: 47 | G29: 56 | H29: 21 | I29: 20 | J29: 38 | K29: 35 | L29: 38 | M29: 85
A30: 我亲爱的跟踪狂 | B30: 106 | C30: 66 | D30: 22 | E30: 20 | F30: 52 | G30: 87 | H30: 32 | I30: 30 | J30: 27 | K30: 21 | L30: 35 | M30: 81
A31: 姐姐请带我回家 | B31: 58 | C31: 47 | D31: 27 | E31: 57 | F31: 18 | G31: 15 | H31: 31 | I31: 18 | J31: 16 | K31: 36 | L31: 27 | M31: 81
A32: 宫妃 | B32: 28 | C32: 22 | D32: 16 | E32: 15 | F32: 40 | G32: 36 | H32: 45 | I32: 36 | J32: 44 | K32: 27 | L32: 49 | M32: 79
A33: 成为团播TOP之后 | D33: 100 | E33: 65 | F33: 119 | G33: 104 | H33: 55 | I33: 61 | J33: 57 | K33: 50 | L33: 59 | M33: 78
A34: 夏日相悖论 | B34: 101 | C34: 49 | D34: 48 | E34: 25 | F34: 46 | G34: 65 | H34: 30 | I34: 19 | J34: 29 | K34: 38 | L34: 40 | M34: 76
A35: 异常代码 | C35: 31 | D35: 15 | E35: 22 | F35: 20 | G35: 42 | H35: 1 | I35: 28 | J35: 5 | K35: 6 | L35: 12 | M35: 72
A36: 纵神欢 | B36: 24 | C36: 25 | D36: 15 | E36: 13 | F36: 33 | G36: 29 | H36: 22 | I36: 13 | J36: 21 | K36: 19 | L36: 34 | M36: 69
A37: 囚她欢 | I37: 17 | J37: 17 | K37: 30 | L37: 21 | M37: 69
A38: 勿扰修仙中 | B38: 114 | C38: 106 | D38: 74 | E38: 49 | F38: 57 | G38: 72 | H38: 46 | I38: 36 | J38: 25 | K38: 28 | L38: 43 | M38: 67
A39: 冒犯哥哥对不起了 | B39: 121 | C39: 72 | D39: 43 | E39: 39 | F39: 35 | G39: 63 | H39: 41 | I39: 41 | J39: 34 | K39: 40 | L39: 34 | M39: 66
A40: 缠梦症 | B40: 75 | C40: 41 | D40: 33 | E40: 35 | F40: 33 | G40: 59 | H40: 25 | I40: 10 | J40: 27 | K40: 32 | L40: 47 | M40: 62
...

Sheet 每日数据
A1: 每天的数值取当天最后一次抓取；日增 = 当天 − 前一天（前一天没数据则为空）
A3: 日期 | B3: 作品名 | C3: 作品ID | D3: 人气 | E3: 人气日增 | F3: 收藏 | G3: 收藏日增 | H3: 点赞 | I3: 点赞日增
A4: 2026-10-05 | B4: AMNESIA 失忆症 | C4: 3862 | D4: 9142820 | F4: 494062 | H4: 105088
A5: 2026-10-05 | B5: 宫妃 | C5: 8075 | D5: 38218500 | F5: 493452 | H5: 105917
A6: 2026-10-05 | B6: 宫斗这件小事新版 | C6: 18216 | D6: 83816412 | F6: 1051871 | H6: 236000
A7: 2026-10-05 | B7: 师途 | C7: 32351 | D7: 158628511 | F7: 1694848 | H7: 440829
A8: 2026-10-05 | B8: 仙路漫漫 | C8: 35066 | D8: 92905076 | F8: 908260 | H8: 219956
A9: 2026-10-05 | B9: 这届宫斗玩不起 | C9: 36214 | D9: 13309937 | F9: 191500 | H9: 34749
A10: 2026-10-05 | B10: 恶役大小姐养成计划 | C10: 40929 | D10: 4709103 | F10: 124664 | H10: 26157
A11: 2026-10-05 | B11: 虔诚之花的晚钟 | C11: 44385 | D11: 5994218 | F11: 316349 | H11: 54281
A12: 2026-10-05 | B12: 田园深处【完结】 | C12: 47293 | D12: 8500558 | F12: 120093 | H12: 17385
A13: 2026-10-05 | B13: 三国攻略手札 | C13: 61744 | D13: 11563909 | F13: 229719 | H13: 42953
A14: 2026-10-05 | B14: 宫妃风华录 | C14: 66777 | D14: 25307784 | F14: 473636 | H14: 67991
A15: 2026-10-05 | B15: 半荀来袭 | C15: 78606 | D15: 4737615 | F15: 143145 | H15: 21690
... A305: 2026-10-05 | B305: 我和我哥哥 | C305: 2423982 | D305: 1834 | F305: 2799 | H305: 54
A306: 2026-10-06 | B306: 临帝阙 | C306: 178176 | D306: 140532387 | E306: 103193 | F306: 1633052 | G306: 738 | H306: 330113 | I306: 196
A307: 2026-10-06 | B307: 师途 | C307: 32351 | D307: 158704692 | E307: 76181 | F307: 1695352 | G307: 504 | H307: 440966 | I307: 137
A308: 2026-10-06 | B308: 三界衔 | C308: 1561773 | D308: 2203609 | E308: 74410 | F308: 361189 | G308: 27 | H308: 18580 | I308: 141
A309: 2026-10-06 | B309: 渡皇朝 | C309: 2201939 | D309: 484089 | E309: 60582 | F309: 210572 | G309: -443 | H309: 4179 | I309: 165
A310: 2026-10-06 | B310: 捉鬼师后日谈 | C310: 436436 | D310: 29660372 | E310: 53815 | F310: 853291 | G310: 1244 | H310: 244041 | I310: 422
A311: 2026-10-06 | B311: 梦人间 | C311: 437355 | D311: 152120064 | E311: 53327 | F311: 2175222 | G311: 587 | H311: 590688 | I311: 163
A312: 2026-10-06 | B312: 风华临安 | C312: 1644173 | D312: 5414342 | E312: 53313 | F312: 209193 | G312: 898 | H312: 30347 | I312: 258
A313: 2026-10-06 | B313: 勿扰修仙中 | C313: 397723 | D313: 15019782 | E313: 48669 | F313: 321485 | G313: 714 | H313: 44473 | I313: 114
A314: 2026-10-06 | B314: 江山千秋万代 | C314: 368816 | D314: 36887615 | E314: 48022 | F314: 461283 | G314: 491 | H314: 60873 | I314: 93
A315: 2026-10-06 | B315: 娱乐圈|热搜预定 | C315: 802492 | D315: 15500338 | E315: 43797 | F315: 312331 | G315: 401 | H315: 40476 | I315: 81
A316: 2026-10-06 | B316: 星期天不上头条 | C316: 468214 | D316: 8018571 | E316: 43755 | F316: 188301 | G316: 286 | H316: 16268 | I316: 55
A317: 2026-10-06 | B317: 京中叙 | C317: 1544579 | D317: 5905327 | E317: 41622 | F317: 335430 | G317: 691 | H317: 28996 | I317: 149
... A589: 2026-10-06 | B589: 我在京城上头条 | C589: 992127 | D589: 1167194 | E589: 0 | F589: 107733 | G589: 0 | H589: 6039 | I589: 0
A590: 2026-10-06 | B590: Clock Zero 终焉之一秒 | C590: 3863 | D590: 3034373 | F590: 156661 | H590: 27177
A591: 2026-10-06 | B591: 御妖名单 | C591: 19681 | D591: 1294211 | F591: 62270 | H591: 10041
A592: 2026-10-06 | B592: 九韶 | C592: 35092 | D592: 10559944 | F592: 113475 | H592: 22595
A593: 2026-10-06 | B593: 江月迭年 | C593: 45243 | D593: 5915066 | F593: 81101 | H593: 14506
A594: 2026-10-06 | B594: 震惊！主上有病？ | C594: 47142 | D594: 6946053 | F594: 179702 | H594: 34667
A595: 2026-10-06 | B595: 仙门第一纨绔 | C595: 49957 | D595: 15623236 | F595: 405662 | H595: 64844
A596: 2026-10-06 | B596: 万人迷翻车后努力求生 | C596: 93236 | D596: 4400147 | F596: 126657 | H596: 19659
A597: 2026-10-06 | B597: 随身仙府记 | C597: 97387 | D597: 5686269 | F597: 145241 | H597: 20694
A598: 2026-10-06 | B598: 反派教你做人 | C598: 108050 | D598: 2851130 | F598: 80563 | H598: 12207
A599: 2026-10-06 | B599: 宫墙柳下 | C599: 112300 | D599: 4710505 | F599: 135598 | H599: 15251
A600: 2026-10-06 | B600: 少女英雄主义 | C600: 137321 | D600: 16856550 | F600: 281003 | H600: 59986
A601: 2026-10-06 | B601: 闲庭梦落花 | C601: 157924 | D601: 3835748 | F601: 121787 | H601: 19477
...

Sheet 付费榜每日最终
A1: 日期 | B1: 榜单更新时间 | C1: 排名 | D1: 作品名 | E1: 作品ID
A2: 2026-10-05 | B2: 2026-10-06 00:00 | C2: 1 | D2: 师途 | E2: 32351
A3: 2026-10-05 | B3: 2026-10-06 00:00 | C3: 2 | D3: 三界衔 | E3: 1561773
A4: 2026-10-05 | B4: 2026-10-06 00:00 | C4: 3 | D4: 临帝阙 | E4: 178176
A5: 2026-10-05 | B5: 2026-10-06 00:00 | C5: 4 | D5: 风华临安 | E5: 1644173
A6: 2026-10-05 | B6: 2026-10-06 00:00 | C6: 5 | D6: 勿扰修仙中 | E6: 397723
A7: 2026-10-05 | B7: 2026-10-06 00:00 | C7: 6 | D7: 宫妃 | E7: 8075
A8: 2026-10-05 | B8: 2026-10-06 00:00 | C8: 7 | D8: 怪我过分美丽 | E8: 103593
A9: 2026-10-05 | B9: 2026-10-06 00:00 | C9: 8 | D9: 神也梦春秋 | E9: 325672
A10: 2026-10-05 | B10: 2026-10-06 00:00 | C10: 9 | D10: 星期天不上头条 | E10: 468214
A11: 2026-10-05 | B11: 2026-10-06 00:00 | C11: 10 | D11: 仙路漫漫 | E11: 35066
A12: 2026-10-05 | B12: 2026-10-06 00:00 | C12: 11 | D12: 江山千秋万代 | E12: 368816
A13: 2026-10-05 | B13: 2026-10-06 00:00 | C13: 12 | D13: AMNESIA 失忆症 | E13: 3862
... A2597: 2026-10-17 | B2597: 2026-10-18 00:00 | C2597: 200 | D2597: 哥哥的私有物 | E2597: 2368166

Sheet 作品列表
A1: .帝王风月录.
A2: 24小时心动挑战
A3: 404区
A4: 44号居民楼
A5: ABO：成为四位Alpha大佬的心尖宠
A6: AMNESIA 失忆症
A7: Bking出场后又被追杀了
A8: Clock Zero 终焉之一秒
A9: Fold
A10: Omega的监狱生活
A11: The Placebo Effect.
A12: Time,Ordinary
... A935: 龙榻囚臣
