Workbook

Sheet 付费榜当日最终
A1: 2026-10-21 付费榜最终排名（当天最后一次抓取，榜单时间 2026-10-22 00:00）
A3: 排名 | B3: 作品名 | C3: 作品ID | D3: 人气 | E3: 收藏 | F3: 点赞
A4: 1 | B4: 师途 | C4: 32351 | D4: 159285984 | E4: 1699824 | F4: 442092
A5: 2 | B5: 江山千秋万代 | C5: 368816 | D5: 37605180 | E5: 467052 | F5: 61811
A6: 3 | B6: 临帝阙 | C6: 178176 | D6: 141520384 | E6: 1638770 | F6: 331718
A7: 4 | B7: 宫妃 | C7: 8075 | D7: 38366496 | E7: 498007 | F7: 106474
A8: 5 | B8: 仙路漫漫 | C8: 35066 | D8: 93156528 | E8: 910476 | F8: 220350
A9: 6 | B9: 怪我过分美丽 | C9: 103593 | D9: 62817657 | E9: 716391 | F9: 123668
A10: 7 | B10: 风华临安 | C10: 1644173 | D10: 5882090 | E10: 216639 | F10: 32245
A11: 8 | B11: 星期天不上头条 | C11: 468214 | D11: 8464060 | E11: 191414 | F11: 16788
A12: 9 | B12: 三界衔 | C12: 1561773 | D12: 2641245 | E12: 364328 | F12: 19702
A13: 10 | B13: 恶女模拟器 | C13: 495331 | D13: 10699765 | E13: 399621 | F13: 36910
A14: 11 | B14: AMNESIA 失忆症 | C14: 3862 | D14: 9348839 | E14: 506602 | F14: 107879
A15: 12 | B15: 我竟然是个女魔头 | C15: 566957 | D15: 1712477 | E15: 174909 | F15: 24428
... A203: 200 | B203: 成凰本纪 | C203: 1478127 | D203: 776777 | E203: 108895 | F203: 3284

Sheet 当日增长
A1: 2026-10-21 人气/收藏/点赞增长 = 今天最后一次抓取 − 昨天最后一次抓取；只统计当天上过付费榜或活跃榜的作品
A3: 作品名 | B3: 作品ID | C3: 人气 | D3: 人气增长 | E3: 收藏 | F3: 收藏增长 | G3: 点赞 | H3: 点赞增长
A4: 江山千秋万代 | B4: 368816 | C4: 37605180 | D4: 48142 | E4: 467052 | F4: 294 | G4: 61811 | H4: 42
A5: 风华临安 | B5: 1644173 | C5: 5882090 | D5: 42555 | E5: 216639 | F5: 597 | G5: 32245 | H5: 110
A6: 临帝阙 | B6: 178176 | C6: 141520384 | D6: 42075 | E6: 1638770 | F6: 302 | G6: 331718 | H6: 75
A7: 师途 | B7: 32351 | C7: 159285984 | D7: 26070 | E7: 1699824 | F7: 191 | G7: 442092 | H7: 47
A8: 三界衔 | B8: 1561773 | C8: 2641245 | D8: 22803 | E8: 364328 | F8: 181 | G8: 19702 | H8: 56
A9: 娱乐圈|热搜预定 | B9: 802492 | C9: 15906242 | D9: 22553 | E9: 315483 | F9: 146 | G9: 41082 | H9: 22
A10: 星期天不上头条 | B10: 468214 | C10: 8464060 | D10: 21889 | E10: 191414 | F10: 100 | G10: 16788 | H10: 26
A11: 京中叙 | B11: 1544579 | C11: 6231338 | D11: 21661 | E11: 340866 | F11: 220 | G11: 29954 | H11: 46
A12: 怪我过分美丽 | B12: 103593 | C12: 62817657 | D12: 20801 | E12: 716391 | F12: 143 | G12: 123668 | H12: 16
A13: 勿扰修仙中 | B13: 397723 | C13: 15348739 | D13: 16971 | E13: 325569 | F13: 135 | G13: 45230 | H13: 23
A14: 捉鬼师后日谈 | B14: 436436 | C14: 30031304 | D14: 15878 | E14: 861797 | F14: 351 | G14: 247003 | H14: 122
A15: 后宫升职手札 | B15: 379597 | C15: 10338107 | D15: 14069 | E15: 298487 | F15: 150 | G15: 32225 | H15: 20
... A350: 二殿下不想被强制爱 | B350: 1927221 | C350: 164479 | D350: 77 | E350: 36067 | F350: 0 | G350: 821 | H350: 0
A351: 时忆：Sweet Spark | B351: 11266 | C351: 12258862 | E351: 242459 | G351: 68780
A352: 震惊！主上有病？ | B352: 47142 | C352: 6953661 | E352: 179807 | G352: 34691
A353: 古代女子成长录 | B353: 62279 | C353: 4866234 | E353: 111801 | G353: 16117
A354: 山海食珍录 | B354: 68615 | C354: 1724579 | E354: 47250 | G354: 6278
A355: 天下倾歌 | B355: 78987 | C355: 11547001 | E355: 211398 | G355: 44717
A356: 无耻之徒 | B356: 80508 | C356: 8132454 | E356: 193201 | G356: 35054
A357: 修罗场逃生指南 | B357: 85756 | C357: 2467807 | E357: 73178 | G357: 11667
A358: 我当宗主那些年 | B358: 98292 | C358: 4925771 | E358: 127433 | G358: 17595
A359: 风月十二录 | B359: 115099 | C359: 11951874 | E359: 266565 | G359: 35823
A360: 诱敌深入 | B360: 120323 | C360: 655873 | E360: 25224 | G360: 3639
A361: 他们都恨我是块木 | B361: 126064 | C361: 4847303 | E361: 123123 | G361: 19151
A362: 继母准则 | B362: 127772 | C362: 6480956 | E362: 175200 | G362: 24205
... A484: 最后的你是否抛弃我 | B484: 2441294 | C484: 772 | E484: 170 | G484: 29

Sheet 趋势查询
A1: 作品名称： | B1: 江山千秋万代
A2: 在黄色格子里输入作品名，或点右侧小箭头从列表里选；空白表示当时没有数据（未上榜）
A4: 榜单时间 | B4: 付费榜 | C4: 活跃榜 | D4: 人气 | E4: 收藏 | F4: 点赞
A5: 2026-10-21 00:30 | B5: =IFERROR(INDEX('付费榜排名变化'!$A$1:$AT$404,MATCH($B$1,'付费榜排名变化'!$A$1:$A$404,0),MATCH($A5,'付费榜排名变化'!$A$1:$AT$1,0)),NA()) | C5: =IFERROR(INDEX('活跃榜排名变化'!$A$1:$AT$352,MATCH($B$1,'活跃榜排名变化'!$A$1:$A$352,0),MATCH($A5,'活跃榜排名变化'!$A$1:$AT$1,0)),NA()) | D5: =IFERROR(INDEX('人气变化'!$A$1:$AT$482,MATCH($B$1,'人气变化'!$A$1:$A$482,0),MATCH($A5,'人气变化'!$A$1:$AT$1,0)),NA()) | E5: =IFERROR(INDEX('收藏变化'!$A$1:$AT$482,MATCH($B$1,'收藏变化'!$A$1:$A$482,0),MATCH($A5,'收藏变化'!$A$1:$AT$1,0)),NA()) | F5: =IFERROR(INDEX('点赞变化'!$A$1:$AT$482,MATCH($B$1,'点赞变化'!$A$1:$A$482,0),MATCH($A5,'点赞变化'!$A$1:$AT$1,0)),NA())
A6: 2026-10-21 01:00 | B6: =IFERROR(INDEX('付费榜排名变化'!$A$1:$AT$404,MATCH($B$1,'付费榜排名变化'!$A$1:$A$404,0),MATCH($A6,'付费榜排名变化'!$A$1:$AT$1,0)),NA()) | C6: =IFERROR(INDEX('活跃榜排名变化'!$A$1:$AT$352,MATCH($B$1,'活跃榜排名变化'!$A$1:$A$352,0),MATCH($A6,'活跃榜排名变化'!$A$1:$AT$1,0)),NA()) | D6: =IFERROR(INDEX('人气变化'!$A$1:$AT$482,MATCH($B$1,'人气变化'!$A$1:$A$482,0),MATCH($A6,'人气变化'!$A$1:$AT$1,0)),NA()) | E6: =IFERROR(INDEX('收藏变化'!$A$1:$AT$482,MATCH($B$1,'收藏变化'!$A$1:$A$482,0),MATCH($A6,'收藏变化'!$A$1:$AT$1,0)),NA()) | F6: =IFERROR(INDEX('点赞变化'!$A$1:$AT$482,MATCH($B$1,'点赞变化'!$A$1:$A$482,0),MATCH($A6,'点赞变化'!$A$1:$AT$1,0)),NA())
A7: 2026-10-21 01:30 | B7: =IFERROR(INDEX('付费榜排名变化'!$A$1:$AT$404,MATCH($B$1,'付费榜排名变化'!$A$1:$A$404,0),MATCH($A7,'付费榜排名变化'!$A$1:$AT$1,0)),NA()) | C7: =IFERROR(INDEX('活跃榜排名变化'!$A$1:$AT$352,MATCH($B$1,'活跃榜排名变化'!$A$1:$A$352,0),MATCH($A7,'活跃榜排名变化'!$A$1:$AT$1,0)),NA()) | D7: =IFERROR(INDEX('人气变化'!$A$1:$AT$482,MATCH($B$1,'人气变化'!$A$1:$A$482,0),MATCH($A7,'人气变化'!$A$1:$AT$1,0)),NA()) | E7: =IFERROR(INDEX('收藏变化'!$A$1:$AT$482,MATCH($B$1,'收藏变化'!$A$1:$A$482,0),MATCH($A7,'收藏变化'!$A$1:$AT$1,0)),NA()) | F7: =IFERROR(INDEX('点赞变化'!$A$1:$AT$482,MATCH($B$1,'点赞变化'!$A$1:$A$482,0),MATCH($A7,'点赞变化'!$A$1:$AT$1,0)),NA())
A8: 2026-10-21 02:00 | B8: =IFERROR(INDEX('付费榜排名变化'!$A$1:$AT$404,MATCH($B$1,'付费榜排名变化'!$A$1:$A$404,0),MATCH($A8,'付费榜排名变化'!$A$1:$AT$1,0)),NA()) | C8: =IFERROR(INDEX('活跃榜排名变化'!$A$1:$AT$352,MATCH($B$1,'活跃榜排名变化'!$A$1:$A$352,0),MATCH($A8,'活跃榜排名变化'!$A$1:$AT$1,0)),NA()) | D8: =IFERROR(INDEX('人气变化'!$A$1:$AT$482,MATCH($B$1,'人气变化'!$A$1:$A$482,0),MATCH($A8,'人气变化'!$A$1:$AT$1,0)),NA()) | E8: =IFERROR(INDEX('收藏变化'!$A$1:$AT$482,MATCH($B$1,'收藏变化'!$A$1:$A$482,0),MATCH($A8,'收藏变化'!$A$1:$AT$1,0)),NA()) | F8: =IFERROR(INDEX('点赞变化'!$A$1:$AT$482,MATCH($B$1,'点赞变化'!$A$1:$A$482,0),MATCH($A8,'点赞变化'!$A$1:$AT$1,0)),NA())
A9: 2026-10-21 02:30 | B9: =IFERROR(INDEX('付费榜排名变化'!$A$1:$AT$404,MATCH($B$1,'付费榜排名变化'!$A$1:$A$404,0),MATCH($A9,'付费榜排名变化'!$A$1:$AT$1,0)),NA()) | C9: =IFERROR(INDEX('活跃榜排名变化'!$A$1:$AT$352,MATCH($B$1,'活跃榜排名变化'!$A$1:$A$352,0),MATCH($A9,'活跃榜排名变化'!$A$1:$AT$1,0)),NA()) | D9: =IFERROR(INDEX('人气变化'!$A$1:$AT$482,MATCH($B$1,'人气变化'!$A$1:$A$482,0),MATCH($A9,'人气变化'!$A$1:$AT$1,0)),NA()) | E9: =IFERROR(INDEX('收藏变化'!$A$1:$AT$482,MATCH($B$1,'收藏变化'!$A$1:$A$482,0),MATCH($A9,'收藏变化'!$A$1:$AT$1,0)),NA()) | F9: =IFERROR(INDEX('点赞变化'!$A$1:$AT$482,MATCH($B$1,'点赞变化'!$A$1:$A$482,0),MATCH($A9,'点赞变化'!$A$1:$AT$1,0)),NA())
A10: 2026-10-21 03:15 | B10: =IFERROR(INDEX('付费榜排名变化'!$A$1:$AT$404,MATCH($B$1,'付费榜排名变化'!$A$1:$A$404,0),MATCH($A10,'付费榜排名变化'!$A$1:$AT$1,0)),NA()) | C10: =IFERROR(INDEX('活跃榜排名变化'!$A$1:$AT$352,MATCH($B$1,'活跃榜排名变化'!$A$1:$A$352,0),MATCH($A10,'活跃榜排名变化'!$A$1:$AT$1,0)),NA()) | D10: =IFERROR(INDEX('人气变化'!$A$1:$AT$482,MATCH($B$1,'人气变化'!$A$1:$A$482,0),MATCH($A10,'人气变化'!$A$1:$AT$1,0)),NA()) | E10: =IFERROR(INDEX('收藏变化'!$A$1:$AT$482,MATCH($B$1,'收藏变化'!$A$1:$A$482,0),MATCH($A10,'收藏变化'!$A$1:$AT$1,0)),NA()) | F10: =IFERROR(INDEX('点赞变化'!$A$1:$AT$482,MATCH($B$1,'点赞变化'!$A$1:$A$482,0),MATCH($A10,'点赞变化'!$A$1:$AT$1,0)),NA())
A11: 2026-10-21 03:45 | B11: =IFERROR(INDEX('付费榜排名变化'!$A$1:$AT$404,MATCH($B$1,'付费榜排名变化'!$A$1:$A$404,0),MATCH($A11,'付费榜排名变化'!$A$1:$AT$1,0)),NA()) | C11: =IFERROR(INDEX('活跃榜排名变化'!$A$1:$AT$352,MATCH($B$1,'活跃榜排名变化'!$A$1:$A$352,0),MATCH($A11,'活跃榜排名变化'!$A$1:$AT$1,0)),NA()) | D11: =IFERROR(INDEX('人气变化'!$A$1:$AT$482,MATCH($B$1,'人气变化'!$A$1:$A$482,0),MATCH($A11,'人气变化'!$A$1:$AT$1,0)),NA()) | E11: =IFERROR(INDEX('收藏变化'!$A$1:$AT$482,MATCH($B$1,'收藏变化'!$A$1:$A$482,0),MATCH($A11,'收藏变化'!$A$1:$AT$1,0)),NA()) | F11: =IFERROR(INDEX('点赞变化'!$A$1:$AT$482,MATCH($B$1,'点赞变化'!$A$1:$A$482,0),MATCH($A11,'点赞变化'!$A$1:$AT$1,0)),NA())
A12: 2026-10-21 04:15 | B12: =IFERROR(INDEX('付费榜排名变化'!$A$1:$AT$404,MATCH($B$1,'付费榜排名变化'!$A$1:$A$404,0),MATCH($A12,'付费榜排名变化'!$A$1:$AT$1,0)),NA()) | C12: =IFERROR(INDEX('活跃榜排名变化'!$A$1:$AT$352,MATCH($B$1,'活跃榜排名变化'!$A$1:$A$352,0),MATCH($A12,'活跃榜排名变化'!$A$1:$AT$1,0)),NA()) | D12: =IFERROR(INDEX('人气变化'!$A$1:$AT$482,MATCH($B$1,'人气变化'!$A$1:$A$482,0),MATCH($A12,'人气变化'!$A$1:$AT$1,0)),NA()) | E12: =IFERROR(INDEX('收藏变化'!$A$1:$AT$482,MATCH($B$1,'收藏变化'!$A$1:$A$482,0),MATCH($A12,'收藏变化'!$A$1:$AT$1,0)),NA()) | F12: =IFERROR(INDEX('点赞变化'!$A$1:$AT$482,MATCH($B$1,'点赞变化'!$A$1:$A$482,0),MATCH($A12,'点赞变化'!$A$1:$AT$1,0)),NA())
A13: 2026-10-21 04:45 | B13: =IFERROR(INDEX('付费榜排名变化'!$A$1:$AT$404,MATCH($B$1,'付费榜排名变化'!$A$1:$A$404,0),MATCH($A13,'付费榜排名变化'!$A$1:$AT$1,0)),NA()) | C13: =IFERROR(INDEX('活跃榜排名变化'!$A$1:$AT$352,MATCH($B$1,'活跃榜排名变化'!$A$1:$A$352,0),MATCH($A13,'活跃榜排名变化'!$A$1:$AT$1,0)),NA()) | D13: =IFERROR(INDEX('人气变化'!$A$1:$AT$482,MATCH($B$1,'人气变化'!$A$1:$A$482,0),MATCH($A13,'人气变化'!$A$1:$AT$1,0)),NA()) | E13: =IFERROR(INDEX('收藏变化'!$A$1:$AT$482,MATCH($B$1,'收藏变化'!$A$1:$A$482,0),MATCH($A13,'收藏变化'!$A$1:$AT$1,0)),NA()) | F13: =IFERROR(INDEX('点赞变化'!$A$1:$AT$482,MATCH($B$1,'点赞变化'!$A$1:$A$482,0),MATCH($A13,'点赞变化'!$A$1:$AT$1,0)),NA())
A14: 2026-10-21 05:15 | B14: =IFERROR(INDEX('付费榜排名变化'!$A$1:$AT$404,MATCH($B$1,'付费榜排名变化'!$A$1:$A$404,0),MATCH($A14,'付费榜排名变化'!$A$1:$AT$1,0)),NA()) | C14: =IFERROR(INDEX('活跃榜排名变化'!$A$1:$AT$352,MATCH($B$1,'活跃榜排名变化'!$A$1:$A$352,0),MATCH($A14,'活跃榜排名变化'!$A$1:$AT$1,0)),NA()) | D14: =IFERROR(INDEX('人气变化'!$A$1:$AT$482,MATCH($B$1,'人气变化'!$A$1:$A$482,0),MATCH($A14,'人气变化'!$A$1:$AT$1,0)),NA()) | E14: =IFERROR(INDEX('收藏变化'!$A$1:$AT$482,MATCH($B$1,'收藏变化'!$A$1:$A$482,0),MATCH($A14,'收藏变化'!$A$1:$AT$1,0)),NA()) | F14: =IFERROR(INDEX('点赞变化'!$A$1:$AT$482,MATCH($B$1,'点赞变化'!$A$1:$A$482,0),MATCH($A14,'点赞变化'!$A$1:$AT$1,0)),NA())
A15: 2026-10-21 05:45 | B15: =IFERROR(INDEX('付费榜排名变化'!$A$1:$AT$404,MATCH($B$1,'付费榜排名变化'!$A$1:$A$404,0),MATCH($A15,'付费榜排名变化'!$A$1:$AT$1,0)),NA()) | C15: =IFERROR(INDEX('活跃榜排名变化'!$A$1:$AT$352,MATCH($B$1,'活跃榜排名变化'!$A$1:$A$352,0),MATCH($A15,'活跃榜排名变化'!$A$1:$AT$1,0)),NA()) | D15: =IFERROR(INDEX('人气变化'!$A$1:$AT$482,MATCH($B$1,'人气变化'!$A$1:$A$482,0),MATCH($A15,'人气变化'!$A$1:$AT$1,0)),NA()) | E15: =IFERROR(INDEX('收藏变化'!$A$1:$AT$482,MATCH($B$1,'收藏变化'!$A$1:$A$482,0),MATCH($A15,'收藏变化'!$A$1:$AT$1,0)),NA()) | F15: =IFERROR(INDEX('点赞变化'!$A$1:$AT$482,MATCH($B$1,'点赞变化'!$A$1:$A$482,0),MATCH($A15,'点赞变化'!$A$1:$AT$1,0)),NA())
A16: 2026-10-21 06:15 | B16: =IFERROR(INDEX('付费榜排名变化'!$A$1:$AT$404,MATCH($B$1,'付费榜排名变化'!$A$1:$A$404,0),MATCH($A16,'付费榜排名变化'!$A$1:$AT$1,0)),NA()) | C16: =IFERROR(INDEX('活跃榜排名变化'!$A$1:$AT$352,MATCH($B$1,'活跃榜排名变化'!$A$1:$A$352,0),MATCH($A16,'活跃榜排名变化'!$A$1:$AT$1,0)),NA()) | D16: =IFERROR(INDEX('人气变化'!$A$1:$AT$482,MATCH($B$1,'人气变化'!$A$1:$A$482,0),MATCH($A16,'人气变化'!$A$1:$AT$1,0)),NA()) | E16: =IFERROR(INDEX('收藏变化'!$A$1:$AT$482,MATCH($B$1,'收藏变化'!$A$1:$A$482,0),MATCH($A16,'收藏变化'!$A$1:$AT$1,0)),NA()) | F16: =IFERROR(INDEX('点赞变化'!$A$1:$AT$482,MATCH($B$1,'点赞变化'!$A$1:$A$482,0),MATCH($A16,'点赞变化'!$A$1:$AT$1,0)),NA())
... A49: 2026-10-22 00:00 | B49: =IFERROR(INDEX('付费榜排名变化'!$A$1:$AT$404,MATCH($B$1,'付费榜排名变化'!$A$1:$A$404,0),MATCH($A49,'付费榜排名变化'!$A$1:$AT$1,0)),NA()) | C49: =IFERROR(INDEX('活跃榜排名变化'!$A$1:$AT$352,MATCH($B$1,'活跃榜排名变化'!$A$1:$A$352,0),MATCH($A49,'活跃榜排名变化'!$A$1:$AT$1,0)),NA()) | D49: =IFERROR(INDEX('人气变化'!$A$1:$AT$482,MATCH($B$1,'人气变化'!$A$1:$A$482,0),MATCH($A49,'人气变化'!$A$1:$AT$1,0)),NA()) | E49: =IFERROR(INDEX('收藏变化'!$A$1:$AT$482,MATCH($B$1,'收藏变化'!$A$1:$A$482,0),MATCH($A49,'收藏变化'!$A$1:$AT$1,0)),NA()) | F49: =IFERROR(INDEX('点赞变化'!$A$1:$AT$482,MATCH($B$1,'点赞变化'!$A$1:$A$482,0),MATCH($A49,'点赞变化'!$A$1:$AT$1,0)),NA())

Sheet 付费榜排名变化
A1: 作品名 | B1: 2026-10-21 00:30 | C1: 2026-10-21 01:00 | D1: 2026-10-21 01:30 | E1: 2026-10-21 02:00 | F1: 2026-10-21 02:30 | G1: 2026-10-21 03:15 | H1: 2026-10-21 03:45 | I1: 2026-10-21 04:15 | J1: 2026-10-21 04:45 | K1: 2026-10-21 05:15 | L1: 2026-10-21 05:45 | M1: 2026-10-21 06:15 | N1: 2026-10-21 06:45 | O1: 2026-10-21 07:15 | P1: 2026-10-21 07:30 | Q1: 2026-10-21 08:00 | R1: 2026-10-21 08:15 | S1: 2026-10-21 09:00 | T1: 2026-10-21 09:30 | U1: 2026-10-21 10:00 | V1: 2026-10-21 10:30 | W1: 2026-10-21 11:00 | X1: 2026-10-21 11:30 | Y1: 2026-10-21 12:00 | Z1: 2026-10-21 12:30 | AA1: 2026-10-21 13:00 | AB1: 2026-10-21 13:30 | AC1: 2026-10-21 14:00 | AD1: 2026-10-21 14:30 | AE1: 2026-10-21 15:30 | AF1: 2026-10-21 16:00 | AG1: 2026-10-21 16:45 | AH1: 2026-10-21 17:15 | AI1: 2026-10-21 17:45 | AJ1: 2026-10-21 18:30 | AK1: 2026-10-21 19:00 | AL1: 2026-10-21 19:30 | AM1: 2026-10-21 20:00 | AN1: 2026-10-21 20:30 | AO1: 2026-10-21 21:15 | AP1: 2026-10-21 22:00 | AQ1: 2026-10-21 22:30 | AR1: 2026-10-21 23:00 | AS1: 2026-10-21 23:30 | AT1: 2026-10-22 00:00
A2: 师途 | B2: 7 | C2: 5 | D2: 4 | E2: 2 | F2: 2 | G2: 3 | H2: 1 | I2: 1 | J2: 1 | K2: 3 | L2: 3 | M2: 3 | N2: 2 | O2: 2 | P2: 3 | Q2: 3 | R2: 2 | S2: 1 | T2: 2 | U2: 1 | V2: 1 | W2: 1 | X2: 1 | Y2: 1 | Z2: 1 | AA2: 1 | AB2: 1 | AC2: 1 | AD2: 1 | AE2: 1 | AF2: 1 | AG2: 1 | AH2: 1 | AI2: 1 | AJ2: 1 | AK2: 1 | AL2: 1 | AM2: 1 | AN2: 1 | AO2: 1 | AP2: 1 | AQ2: 1 | AR2: 1 | AS2: 1 | AT2: 1
A3: 江山千秋万代 | B3: 1 | C3: 2 | D3: 3 | E3: 4 | F3: 3 | G3: 1 | H3: 3 | I3: 3 | J3: 4 | K3: 1 | L3: 2 | M3: 2 | N3: 3 | O3: 3 | P3: 2 | Q3: 1 | R3: 1 | S3: 2 | T3: 3 | U3: 3 | V3: 3 | W3: 3 | X3: 3 | Y3: 3 | Z3: 3 | AA3: 4 | AB3: 2 | AC3: 2 | AD3: 2 | AE3: 2 | AF3: 2 | AG3: 2 | AH3: 2 | AI3: 2 | AJ3: 2 | AK3: 2 | AL3: 2 | AM3: 2 | AN3: 2 | AO3: 2 | AP3: 2 | AQ3: 2 | AR3: 2 | AS3: 2 | AT3: 2
A4: 临帝阙 | B4: 8 | C4: 7 | D4: 6 | E4: 6 | F4: 5 | G4: 6 | H4: 5 | I4: 4 | J4: 2 | K4: 4 | L4: 4 | M4: 4 | N4: 4 | O4: 4 | P4: 4 | Q4: 4 | R4: 5 | S4: 5 | T4: 5 | U4: 5 | V4: 5 | W4: 4 | X4: 4 | Y4: 4 | Z4: 4 | AA4: 2 | AB4: 3 | AC4: 3 | AD4: 3 | AE4: 3 | AF4: 4 | AG4: 5 | AH4: 5 | AI4: 4 | AJ4: 4 | AK4: 4 | AL4: 4 | AM4: 3 | AN4: 3 | AO4: 3 | AP4: 3 | AQ4: 3 | AR4: 3 | AS4: 3 | AT4: 3
A5: 宫妃 | B5: 4 | C5: 1 | D5: 2 | E5: 3 | F5: 4 | G5: 2 | H5: 2 | I5: 2 | J5: 3 | K5: 5 | L5: 5 | M5: 5 | N5: 6 | O5: 6 | P5: 6 | Q5: 5 | R5: 4 | S5: 3 | T5: 1 | U5: 2 | V5: 2 | W5: 2 | X5: 2 | Y5: 2 | Z5: 2 | AA5: 3 | AB5: 4 | AC5: 4 | AD5: 4 | AE5: 4 | AF5: 3 | AG5: 4 | AH5: 4 | AI5: 5 | AJ5: 5 | AK5: 5 | AL5: 5 | AM5: 4 | AN5: 4 | AO5: 4 | AP5: 4 | AQ5: 4 | AR5: 5 | AS5: 4 | AT5: 4
A6: 仙路漫漫 | B6: 12 | C6: 4 | D6: 5 | E6: 5 | F6: 8 | G6: 8 | H6: 8 | I6: 8 | J6: 5 | K6: 2 | L6: 1 | M6: 1 | N6: 1 | O6: 1 | P6: 1 | Q6: 2 | R6: 3 | S6: 4 | T6: 4 | U6: 4 | V6: 4 | W6: 5 | X6: 6 | Y6: 5 | Z6: 5 | AA6: 5 | AB6: 5 | AC6: 5 | AD6: 6 | AE6: 6 | AF6: 5 | AG6: 3 | AH6: 3 | AI6: 3 | AJ6: 3 | AK6: 3 | AL6: 3 | AM6: 5 | AN6: 5 | AO6: 5 | AP6: 5 | AQ6: 5 | AR6: 4 | AS6: 5 | AT6: 5
A7: 怪我过分美丽 | B7: 28 | C7: 16 | D7: 9 | E7: 7 | F7: 7 | G7: 7 | H7: 7 | I7: 6 | J7: 7 | K7: 6 | L7: 6 | M7: 6 | N7: 5 | O7: 5 | P7: 5 | Q7: 6 | R7: 6 | S7: 6 | T7: 6 | U7: 6 | V7: 6 | W7: 6 | X7: 5 | Y7: 6 | Z7: 6 | AA7: 6 | AB7: 6 | AC7: 6 | AD7: 5 | AE7: 5 | AF7: 6 | AG7: 6 | AH7: 6 | AI7: 6 | AJ7: 6 | AK7: 6 | AL7: 6 | AM7: 6 | AN7: 6 | AO7: 6 | AP7: 6 | AQ7: 6 | AR7: 6 | AS7: 6 | AT7: 6
A8: 风华临安 | B8: 6 | C8: 8 | D8: 7 | E8: 8 | F8: 6 | G8: 5 | H8: 4 | I8: 5 | J8: 6 | K8: 7 | L8: 7 | M8: 7 | N8: 7 | O8: 7 | P8: 7 | Q8: 7 | R8: 7 | S8: 7 | T8: 7 | U8: 7 | V8: 7 | W8: 7 | X8: 7 | Y8: 7 | Z8: 8 | AA8: 8 | AB8: 8 | AC8: 8 | AD8: 8 | AE8: 8 | AF8: 8 | AG8: 8 | AH8: 8 | AI8: 8 | AJ8: 8 | AK8: 8 | AL8: 8 | AM8: 8 | AN8: 7 | AO8: 7 | AP8: 7 | AQ8: 7 | AR8: 7 | AS8: 7 | AT8: 7
A9: 星期天不上头条 | B9: 16 | C9: 15 | D9: 14 | E9: 12 | F9: 12 | G9: 10 | H9: 9 | I9: 9 | J9: 9 | K9: 9 | L9: 9 | M9: 8 | N9: 8 | O9: 8 | P9: 8 | Q9: 8 | R9: 8 | S9: 8 | T9: 8 | U9: 8 | V9: 8 | W9: 8 | X9: 8 | Y9: 8 | Z9: 7 | AA9: 7 | AB9: 7 | AC9: 7 | AD9: 7 | AE9: 7 | AF9: 7 | AG9: 7 | AH9: 7 | AI9: 7 | AJ9: 7 | AK9: 7 | AL9: 7 | AM9: 7 | AN9: 8 | AO9: 8 | AP9: 8 | AQ9: 8 | AR9: 8 | AS9: 8 | AT9: 8
A10: 三界衔 | B10: 11 | C10: 13 | D10: 11 | E10: 11 | F10: 9 | G10: 11 | H10: 10 | I10: 11 | J10: 12 | K10: 12 | L10: 11 | M10: 11 | N10: 11 | O10: 11 | P10: 10 | Q10: 10 | R10: 11 | S10: 9 | T10: 9 | U10: 9 | V10: 9 | W10: 9 | X10: 9 | Y10: 9 | Z10: 9 | AA10: 9 | AB10: 9 | AC10: 9 | AD10: 9 | AE10: 9 | AF10: 9 | AG10: 9 | AH10: 9 | AI10: 9 | AJ10: 9 | AK10: 9 | AL10: 9 | AM10: 9 | AN10: 9 | AO10: 9 | AP10: 9 | AQ10: 9 | AR10: 9 | AS10: 9 | AT10: 9
A11: 恶女模拟器 | B11: 21 | C11: 21 | D11: 10 | E11: 10 | F11: 10 | G11: 9 | H11: 11 | I11: 10 | J11: 11 | K11: 10 | L11: 10 | M11: 10 | N11: 10 | O11: 10 | P11: 11 | Q11: 11 | R11: 10 | S11: 10 | T11: 10 | U11: 10 | V11: 11 | W11: 12 | X11: 12 | Y11: 12 | Z11: 12 | AA11: 12 | AB11: 12 | AC11: 11 | AD11: 11 | AE11: 10 | AF11: 10 | AG11: 10 | AH11: 10 | AI11: 10 | AJ11: 10 | AK11: 10 | AL11: 10 | AM11: 10 | AN11: 10 | AO11: 11 | AP11: 10 | AQ11: 10 | AR11: 10 | AS11: 11 | AT11: 10
A12: AMNESIA 失忆症 | B12: 9 | C12: 6 | D12: 8 | E12: 9 | F12: 11 | G12: 12 | H12: 12 | I12: 12 | J12: 10 | K12: 11 | L12: 12 | M12: 12 | N12: 12 | O12: 12 | P12: 12 | Q12: 12 | R12: 12 | S12: 12 | T12: 12 | U12: 13 | V12: 10 | W12: 11 | X12: 10 | Y12: 10 | Z12: 10 | AA12: 10 | AB12: 10 | AC12: 10 | AD12: 10 | AE12: 11 | AF12: 11 | AG12: 11 | AH12: 11 | AI12: 11 | AJ12: 11 | AK12: 11 | AL12: 11 | AM12: 11 | AN12: 11 | AO12: 10 | AP12: 11 | AQ12: 11 | AR12: 11 | AS12: 10 | AT12: 11
A13: 我竟然是个女魔头 | B13: 29 | C13: 29 | D13: 30 | E13: 24 | F13: 26 | G13: 23 | H13: 26 | I13: 28 | J13: 25 | K13: 23 | L13: 22 | M13: 22 | N13: 23 | O13: 23 | P13: 23 | Q13: 22 | R13: 22 | S13: 22 | T13: 22 | U13: 21 | V13: 21 | W13: 23 | X13: 21 | Y13: 20 | Z13: 17 | AA13: 17 | AB13: 17 | AC13: 16 | AD13: 16 | AE13: 16 | AF13: 16 | AG13: 17 | AH13: 17 | AI13: 17 | AJ13: 15 | AK13: 15 | AL13: 16 | AM13: 16 | AN13: 15 | AO13: 16 | AP13: 16 | AQ13: 16 | AR13: 14 | AS13: 14 | AT13: 12
... A17: 仙门逸事 | B17: 128 | C17: 75 | D17: 98 | E17: 103 | F17: 113 | G17: 101 | H17: 100 | I17: 84 | J17: 89 | K17: 92 | L17: 98 | M17: 100 | N17: 101 | O17: 103 | P17: 104 | Q17: 105 | R17: 108 | S17: 116 | T17: 81 | U17: 81 | V17: 58 | W17: 61 | X17: 57 | Y17: 58 | Z17: 50 | AA17: 40 | AB17: 33 | AC17: 34 | AD17: 33 | AE17: 34 | AF17: 33 | AG17: 26 | AH17: 21 | AI17: 18 | AJ17: 18 | AK17: 16 | AL17: 17 | AM17: 19 | AN17: 20 | AO17: 17 | AP17: 17 | AQ17: 17 | AR17: 17 | AS17: 17 | AT17: 16
A18: 昭昭宫廷 | F18: 146 | G18: 90 | H18: 76 | I18: 79 | J18: 83 | K18: 84 | L18: 85 | M18: 89 | N18: 90 | O18: 93 | P18: 94 | Q18: 95 | R18: 82 | S18: 80 | T18: 79 | U18: 76 | V18: 64 | W18: 64 | X18: 63 | Y18: 64 | Z18: 61 | AA18: 63 | AB18: 43 | AC18: 36 | AD18: 31 | AE18: 27 | AF18: 25 | AG18: 22 | AH18: 25 | AI18: 22 | AJ18: 20 | AK18: 17 | AL18: 15 | AM18: 15 | AN18: 16 | AO18: 15 | AP18: 15 | AQ18: 14 | AR18: 15 | AS18: 15 | AT18: 17
A19: 娱乐圈|热搜预定 | C19: 42 | D19: 37 | E19: 35 | F19: 36 | G19: 33 | H19: 28 | I19: 27 | J19: 28 | K19: 29 | L19: 28 | M19: 29 | N19: 28 | O19: 28 | P19: 27 | Q19: 27 | R19: 27 | S19: 24 | T19: 24 | U19: 22 | V19: 23 | W19: 22 | X19: 23 | Y19: 22 | Z19: 23 | AA19: 21 | AB19: 19 | AC19: 23 | AD19: 18 | AE19: 20 | AF19: 18 | AG19: 20 | AH19: 19 | AI19: 20 | AJ19: 21 | AK19: 22 | AL19: 22 | AM19: 23 | AN19: 23 | AO19: 23 | AP19: 23 | AQ19: 19 | AR19: 18 | AS19: 18 | AT19: 18
A20: 我在古代当首富￥ | B20: 50 | C20: 25 | D20: 26 | E20: 30 | F20: 32 | G20: 32 | H20: 34 | I20: 36 | J20: 39 | K20: 44 | L20: 44 | M20: 45 | N20: 43 | O20: 43 | P20: 43 | Q20: 44 | R20: 44 | S20: 43 | T20: 45 | U20: 46 | V20: 53 | W20: 51 | X20: 51 | Y20: 35 | Z20: 32 | AA20: 31 | AB20: 23 | AC20: 20 | AD20: 20 | AE20: 19 | AF20: 19 | AG20: 18 | AH20: 20 | AI20: 21 | AJ20: 22 | AK20: 20 | AL20: 20 | AM20: 21 | AN20: 22 | AO20: 22 | AP20: 18 | AQ20: 18 | AR20: 19 | AS20: 19 | AT20: 19
A21: 青宫赋 | B21: 44 | C21: 36 | D21: 32 | E21: 26 | F21: 19 | G21: 18 | H21: 17 | I21: 18 | J21: 18 | K21: 18 | L21: 19 | M21: 20 | N21: 21 | O21: 21 | P21: 20 | Q21: 21 | R21: 21 | S21: 21 | T21: 20 | U21: 19 | V21: 20 | W21: 20 | X21: 22 | Y21: 23 | Z21: 21 | AA21: 22 | AB21: 22 | AC21: 21 | AD21: 23 | AE21: 24 | AF21: 23 | AG21: 23 | AH21: 22 | AI21: 25 | AJ21: 24 | AK21: 25 | AL21: 23 | AM21: 26 | AN21: 27 | AO21: 24 | AP21: 24 | AQ21: 23 | AR21: 22 | AS21: 21 | AT21: 20
A22: 替兄嫁了公主后 | B22: 37 | C22: 27 | D22: 16 | E22: 14 | F22: 13 | G22: 13 | H22: 13 | I22: 13 | J22: 13 | K22: 13 | L22: 13 | M22: 13 | N22: 14 | O22: 14 | P22: 14 | Q22: 14 | R22: 14 | S22: 14 | T22: 14 | U22: 14 | V22: 14 | W22: 14 | X22: 13 | Y22: 13 | Z22: 14 | AA22: 14 | AB22: 14 | AC22: 14 | AD22: 14 | AE22: 14 | AF22: 15 | AG22: 16 | AH22: 16 | AI22: 16 | AJ22: 17 | AK22: 18 | AL22: 19 | AM22: 20 | AN22: 19 | AO22: 18 | AP22: 19 | AQ22: 20 | AR22: 20 | AS22: 20 | AT22: 21
A23: 古代主母风华录 | B23: 5 | C23: 17 | D23: 17 | E23: 17 | F23: 17 | G23: 19 | H23: 19 | I23: 17 | J23: 17 | K23: 16 | L23: 15 | M23: 15 | N23: 15 | O23: 15 | P23: 15 | Q23: 15 | R23: 15 | S23: 15 | T23: 15 | U23: 15 | V23: 15 | W23: 15 | X23: 15 | Y23: 15 | Z23: 15 | AA23: 15 | AB23: 16 | AC23: 17 | AD23: 17 | AE23: 17 | AF23: 17 | AG23: 19 | AH23: 18 | AI23: 19 | AJ23: 19 | AK23: 19 | AL23: 18 | AM23: 22 | AN23: 21 | AO23: 21 | AP23: 21 | AQ23: 22 | AR23: 24 | AS23: 25 | AT23: 22
A24: 后宫升职手札 | B24: 72 | C24: 48 | D24: 65 | E24: 63 | F24: 56 | G24: 41 | H24: 41 | I24: 38 | J24: 41 | K24: 35 | L24: 29 | M24: 31 | N24: 33 | O24: 33 | P24: 34 | Q24: 36 | R24: 37 | S24: 37 | T24: 34 | U24: 33 | V24: 28 | W24: 30 | X24: 29 | Y24: 29 | Z24: 25 | AA24: 25 | AB24: 21 | AC24: 24 | AD24: 24 | AE24: 21 | AF24: 21 | AG24: 21 | AH24: 23 | AI24: 26 | AJ24: 23 | AK24: 23 | AL24: 24 | AM24: 27 | AN24: 25 | AO24: 25 | AP24: 26 | AQ24: 25 | AR24: 25 | AS24: 26 | AT24: 23
A25: 凭什么我是反派 | B25: 13 | C25: 19 | D25: 27 | E25: 32 | F25: 34 | G25: 34 | H25: 29 | I25: 26 | J25: 27 | K25: 27 | L25: 31 | M25: 33 | N25: 35 | O25: 35 | P25: 35 | Q25: 33 | R25: 33 | S25: 28 | T25: 30 | U25: 34 | V25: 35 | W25: 28 | X25: 32 | Y25: 33 | Z25: 36 | AA25: 39 | AB25: 32 | AC25: 27 | AD25: 26 | AE25: 29 | AF25: 29 | AG25: 33 | AH25: 27 | AI25: 24 | AJ25: 26 | AK25: 26 | AL25: 26 | AM25: 17 | AN25: 17 | AO25: 19 | AP25: 20 | AQ25: 21 | AR25: 23 | AS25: 23 | AT25: 24
A26: 虔诚之花的晚钟 | B26: 66 | C26: 23 | D26: 24 | E26: 25 | F26: 27 | G26: 25 | H26: 25 | I26: 25 | J26: 26 | K26: 26 | L26: 27 | M26: 23 | N26: 26 | O26: 26 | P26: 28 | Q26: 28 | R26: 28 | S26: 27 | T26: 25 | U26: 26 | V26: 27 | W26: 27 | X26: 27 | Y26: 28 | Z26: 28 | AA26: 28 | AB26: 25 | AC26: 25 | AD26: 25 | AE26: 25 | AF26: 27 | AG26: 30 | AH26: 30 | AI26: 29 | AJ26: 29 | AK26: 29 | AL26: 25 | AM26: 24 | AN26: 24 | AO26: 26 | AP26: 25 | AQ26: 27 | AR26: 27 | AS26: 27 | AT26: 25
A27: 废土之王Ⅰ：起源 | C27: 3 | D27: 1 | E27: 1 | F27: 1 | G27: 4 | H27: 6 | I27: 7 | J27: 8 | K27: 8 | L27: 8 | M27: 9 | N27: 9 | O27: 9 | P27: 9 | Q27: 9 | R27: 9 | S27: 11 | T27: 11 | U27: 12 | V27: 13 | W27: 13 | X27: 14 | Y27: 14 | Z27: 13 | AA27: 13 | AB27: 13 | AC27: 13 | AD27: 13 | AE27: 13 | AF27: 14 | AG27: 15 | AH27: 15 | AI27: 15 | AJ27: 16 | AK27: 21 | AL27: 21 | AM27: 18 | AN27: 18 | AO27: 20 | AP27: 22 | AQ27: 24 | AR27: 21 | AS27: 22 | AT27: 26
A28: 朕被迫上位 | B28: 93 | C28: 41 | D28: 41 | E28: 40 | F28: 47 | G28: 37 | H28: 39 | I28: 42 | J28: 42 | K28: 39 | L28: 39 | M28: 42 | N28: 44 | O28: 44 | P28: 42 | Q28: 43 | R28: 43 | S28: 44 | T28: 46 | U28: 48 | V28: 46 | W28: 42 | X28: 38 | Y28: 38 | Z28: 40 | AA28: 35 | AB28: 39 | AC28: 32 | AD28: 32 | AE28: 35 | AF28: 34 | AG28: 29 | AH28: 31 | AI28: 31 | AJ28: 30 | AK28: 27 | AL28: 29 | AM28: 29 | AN28: 29 | AO28: 31 | AP28: 31 | AQ28: 26 | AR28: 26 | AS28: 24 | AT28: 27
A29: 天纵 | B29: 10 | C29: 14 | D29: 20 | E29: 18 | F29: 21 | G29: 17 | H29: 18 | I29: 19 | J29: 19 | K29: 19 | L29: 18 | M29: 18 | N29: 20 | O29: 20 | P29: 21 | Q29: 16 | R29: 16 | S29: 16 | T29: 16 | U29: 16 | V29: 17 | W29: 17 | X29: 18 | Y29: 17 | Z29: 18 | AA29: 18 | AB29: 20 | AC29: 22 | AD29: 22 | AE29: 22 | AF29: 22 | AG29: 25 | AH29: 26 | AI29: 27 | AJ29: 27 | AK29: 28 | AL29: 28 | AM29: 28 | AN29: 28 | AO29: 30 | AP29: 29 | AQ29: 30 | AR29: 29 | AS29: 29 | AT29: 28
A30: 我在京城上头条 | D30: 79 | E30: 61 | F30: 57 | G30: 66 | H30: 64 | I30: 65 | J30: 60 | K30: 63 | L30: 65 | M30: 68 | N30: 70 | O30: 71 | P30: 71 | Q30: 71 | R30: 71 | S30: 56 | T30: 58 | U30: 49 | V30: 39 | W30: 38 | X30: 39 | Y30: 42 | Z30: 37 | AA30: 36 | AB30: 34 | AC30: 39 | AD30: 35 | AE30: 36 | AF30: 36 | AG30: 24 | AH30: 24 | AI30: 23 | AJ30: 25 | AK30: 24 | AL30: 27 | AM30: 25 | AN30: 26 | AO30: 27 | AP30: 27 | AQ30: 28 | AR30: 28 | AS30: 28 | AT30: 29
A31: 无情笺 | B31: 143 | C31: 57 | D31: 46 | E31: 31 | F31: 29 | G31: 36 | H31: 36 | I31: 32 | J31: 37 | K31: 36 | L31: 34 | M31: 30 | N31: 31 | O31: 32 | P31: 33 | Q31: 34 | R31: 34 | S31: 34 | T31: 35 | U31: 23 | V31: 19 | W31: 19 | X31: 20 | Y31: 21 | Z31: 22 | AA31: 24 | AB31: 27 | AC31: 29 | AD31: 30 | AE31: 32 | AF31: 30 | AG31: 31 | AH31: 32 | AI31: 34 | AJ31: 34 | AK31: 31 | AL31: 32 | AM31: 33 | AN31: 33 | AO31: 28 | AP31: 28 | AQ31: 29 | AR31: 30 | AS31: 30 | AT31: 30
A32: 国际女团出道战 | B32: 17 | C32: 30 | D32: 25 | E32: 28 | F32: 28 | G32: 30 | H32: 33 | I32: 34 | J32: 34 | K32: 33 | L32: 32 | M32: 32 | N32: 32 | O32: 31 | P32: 31 | Q32: 31 | R32: 31 | S32: 30 | T32: 31 | U32: 35 | V32: 34 | W32: 34 | X32: 30 | Y32: 30 | Z32: 31 | AA32: 34 | AB32: 36 | AC32: 37 | AD32: 39 | AE32: 31 | AF32: 31 | AG32: 34 | AH32: 35 | AI32: 35 | AJ32: 35 | AK32: 36 | AL32: 30 | AM32: 30 | AN32: 30 | AO32: 29 | AP32: 30 | AQ32: 31 | AR32: 31 | AS32: 31 | AT32: 31
A33: 成为团播TOP之后 | B33: 160 | C33: 58 | D33: 48 | E33: 43 | F33: 38 | G33: 38 | H33: 38 | I33: 41 | J33: 31 | K33: 32 | L33: 36 | M33: 38 | N33: 34 | O33: 34 | P33: 30 | Q33: 30 | R33: 32 | S33: 31 | T33: 29 | U33: 32 | V33: 33 | W33: 29 | X33: 31 | Y33: 31 | Z33: 29 | AA33: 30 | AB33: 31 | AC33: 28 | AD33: 28 | AE33: 26 | AF33: 26 | AG33: 27 | AH33: 28 | AI33: 28 | AJ33: 28 | AK33: 30 | AL33: 33 | AM33: 35 | AN33: 34 | AO33: 32 | AP33: 33 | AQ33: 32 | AR33: 32 | AS33: 33 | AT33: 32
A34: 从寒门开始 | B34: 23 | C34: 50 | D34: 58 | E34: 65 | F34: 76 | G34: 70 | H34: 72 | I34: 75 | J34: 65 | K34: 66 | L34: 64 | M34: 66 | N34: 63 | O34: 65 | P34: 60 | Q34: 60 | R34: 62 | S34: 54 | T34: 55 | U34: 51 | V34: 37 | W34: 33 | X34: 34 | Y34: 32 | Z34: 34 | AA34: 37 | AB34: 40 | AC34: 41 | AD34: 38 | AE34: 30 | AF34: 32 | AG34: 35 | AH34: 34 | AI34: 32 | AJ34: 33 | AK34: 34 | AL34: 31 | AM34: 31 | AN34: 31 | AO34: 34 | AP34: 32 | AQ34: 33 | AR34: 33 | AS34: 34 | AT34: 33
A35: 帝宴千秋 | B35: 116 | C35: 170 | D35: 103 | E35: 54 | F35: 39 | G35: 47 | H35: 40 | I35: 39 | J35: 30 | K35: 31 | L35: 30 | M35: 28 | N35: 30 | O35: 30 | P35: 32 | Q35: 32 | R35: 29 | S35: 32 | T35: 33 | U35: 36 | V35: 36 | W35: 36 | X35: 36 | Y35: 36 | Z35: 35 | AA35: 38 | AB35: 35 | AC35: 40 | AD35: 41 | AE35: 39 | AF35: 37 | AG35: 37 | AH35: 37 | AI35: 37 | AJ35: 37 | AK35: 37 | AL35: 36 | AM35: 32 | AN35: 32 | AO35: 33 | AP35: 34 | AQ35: 34 | AR35: 34 | AS35: 32 | AT35: 34
A36: 山河长憾 | C36: 90 | D36: 125 | E36: 69 | F36: 65 | G36: 75 | H36: 81 | I36: 74 | J36: 80 | K36: 81 | L36: 81 | M36: 77 | N36: 74 | O36: 74 | P36: 74 | Q36: 74 | R36: 74 | S36: 74 | T36: 76 | U36: 72 | V36: 75 | W36: 76 | X36: 77 | Y36: 72 | Z36: 67 | AA36: 68 | AB36: 67 | AC36: 65 | AD36: 63 | AE36: 59 | AF36: 59 | AG36: 57 | AH36: 55 | AI36: 56 | AJ36: 53 | AK36: 56 | AL36: 53 | AM36: 47 | AN36: 47 | AO36: 47 | AP36: 49 | AQ36: 38 | AR36: 39 | AS36: 36 | AT36: 35
A37: 无限求生：房车囤货组队 | B37: 76 | C37: 71 | D37: 55 | E37: 44 | F37: 48 | G37: 44 | H37: 47 | I37: 49 | J37: 50 | K37: 47 | L37: 47 | M37: 49 | N37: 16 | O37: 16 | P37: 17 | Q37: 19 | R37: 19 | S37: 19 | T37: 19 | U37: 20 | V37: 22 | W37: 24 | X37: 25 | Y37: 26 | Z37: 27 | AA37: 26 | AB37: 28 | AC37: 30 | AD37: 29 | AE37: 33 | AF37: 35 | AG37: 36 | AH37: 36 | AI37: 36 | AJ37: 36 | AK37: 35 | AL37: 37 | AM37: 38 | AN37: 37 | AO37: 37 | AP37: 37 | AQ37: 35 | AR37: 35 | AS37: 35 | AT37: 36
A38: 世家主母日常 | B38: 196 | C38: 103 | D38: 89 | E38: 77 | F38: 82 | G38: 71 | H38: 77 | I38: 80 | J38: 82 | K38: 72 | L38: 73 | M38: 73 | N38: 69 | O38: 68 | P38: 69 | Q38: 69 | R38: 69 | S38: 73 | T38: 75 | U38: 74 | V38: 77 | W38: 78 | X38: 85 | Y38: 79 | Z38: 70 | AA38: 71 | AB38: 68 | AC38: 57 | AD38: 57 | AE38: 48 | AF38: 46 | AG38: 38 | AH38: 38 | AI38: 38 | AJ38: 38 | AK38: 38 | AL38: 39 | AM38: 41 | AN38: 41 | AO38: 39 | AP38: 39 | AQ38: 39 | AR38: 38 | AS38: 37 | AT38: 37
A39: 你的私有玩物们 | B39: 41 | C39: 20 | D39: 23 | E39: 27 | F39: 22 | G39: 21 | H39: 20 | I39: 20 | J39: 20 | K39: 21 | L39: 21 | M39: 21 | N39: 22 | O39: 22 | P39: 22 | Q39: 23 | R39: 23 | S39: 23 | T39: 23 | U39: 25 | V39: 26 | W39: 25 | X39: 24 | Y39: 24 | Z39: 24 | AA39: 23 | AB39: 26 | AC39: 26 | AD39: 27 | AE39: 28 | AF39: 28 | AG39: 32 | AH39: 33 | AI39: 33 | AJ39: 32 | AK39: 32 | AL39: 34 | AM39: 34 | AN39: 36 | AO39: 35 | AP39: 35 | AQ39: 37 | AR39: 37 | AS39: 38 | AT39: 38
A40: 赴韶光 | B40: 3 | C40: 9 | D40: 13 | E40: 16 | F40: 16 | G40: 15 | H40: 15 | I40: 15 | J40: 15 | K40: 15 | L40: 16 | M40: 16 | N40: 17 | O40: 17 | P40: 18 | Q40: 18 | R40: 18 | S40: 17 | T40: 18 | U40: 18 | V40: 18 | W40: 18 | X40: 17 | Y40: 18 | Z40: 19 | AA40: 20 | AB40: 24 | AC40: 19 | AD40: 21 | AE40: 23 | AF40: 24 | AG40: 28 | AH40: 29 | AI40: 30 | AJ40: 31 | AK40: 33 | AL40: 35 | AM40: 36 | AN40: 35 | AO40: 36 | AP40: 36 | AQ40: 36 | AR40: 36 | AS40: 39 | AT40: 39
A41: 并不是一般穿游 | C41: 34 | D41: 49 | E41: 41 | F41: 40 | G41: 51 | H41: 44 | I41: 47 | J41: 48 | K41: 51 | L41: 51 | M41: 48 | N41: 49 | O41: 49 | P41: 48 | Q41: 48 | R41: 47 | S41: 47 | T41: 47 | U41: 39 | V41: 42 | W41: 40 | X41: 42 | Y41: 41 | Z41: 41 | AA41: 42 | AB41: 41 | AC41: 43 | AD41: 43 | AE41: 43 | AF41: 40 | AG41: 40 | AH41: 41 | AI41: 41 | AJ41: 40 | AK41: 40 | AL41: 40 | AM41: 40 | AN41: 39 | AO41: 41 | AP41: 41 | AQ41: 42 | AR41: 45 | AS41: 42 | AT41: 40
A42: 古代女子生存实录 | C42: 109 | D42: 72 | E42: 90 | F42: 105 | G42: 83 | H42: 70 | I42: 72 | J42: 78 | K42: 79 | L42: 80 | M42: 83 | N42: 83 | O42: 84 | P42: 87 | Q42: 88 | R42: 91 | S42: 76 | T42: 78 | U42: 80 | V42: 86 | W42: 91 | X42: 92 | Y42: 80 | Z42: 72 | AA42: 32 | AB42: 38 | AC42: 38 | AD42: 37 | AE42: 37 | AF42: 38 | AG42: 39 | AH42: 39 | AI42: 39 | AJ42: 41 | AK42: 41 | AL42: 41 | AM42: 37 | AN42: 38 | AO42: 38 | AP42: 38 | AQ42: 40 | AR42: 41 | AS42: 40 | AT42: 41
A43: 黑月光师尊拿命洗白 | B43: 79 | C43: 31 | D43: 33 | E43: 37 | F43: 35 | G43: 35 | H43: 37 | I43: 40 | J43: 33 | K43: 34 | L43: 37 | M43: 39 | N43: 41 | O43: 41 | P43: 38 | Q43: 42 | R43: 42 | S43: 39 | T43: 36 | U43: 31 | V43: 32 | W43: 32 | X43: 28 | Y43: 27 | Z43: 30 | AA43: 29 | AB43: 30 | AC43: 35 | AD43: 40 | AE43: 40 | AF43: 41 | AG43: 41 | AH43: 40 | AI43: 40 | AJ43: 39 | AK43: 39 | AL43: 38 | AM43: 39 | AN43: 40 | AO43: 40 | AP43: 40 | AQ43: 44 | AR43: 44 | AS43: 41 | AT43: 42
...

Sheet 活跃榜排名变化
A1: 作品名 | B1: 2026-10-21 00:30 | C1: 2026-10-21 01:00 | D1: 2026-10-21 01:30 | E1: 2026-10-21 02:00 | F1: 2026-10-21 02:30 | G1: 2026-10-21 03:15 | H1: 2026-10-21 03:45 | I1: 2026-10-21 04:15 | J1: 2026-10-21 04:45 | K1: 2026-10-21 05:15 | L1: 2026-10-21 05:45 | M1: 2026-10-21 06:15 | N1: 2026-10-21 06:45 | O1: 2026-10-21 07:15 | P1: 2026-10-21 07:30 | Q1: 2026-10-21 08:00 | R1: 2026-10-21 08:15 | S1: 2026-10-21 09:00 | T1: 2026-10-21 09:30 | U1: 2026-10-21 10:00 | V1: 2026-10-21 10:30 | W1: 2026-10-21 11:00 | X1: 2026-10-21 11:30 | Y1: 2026-10-21 12:00 | Z1: 2026-10-21 12:30 | AA1: 2026-10-21 13:00 | AB1: 2026-10-21 13:30 | AC1: 2026-10-21 14:00 | AD1: 2026-10-21 14:30 | AE1: 2026-10-21 15:30 | AF1: 2026-10-21 16:00 | AG1: 2026-10-21 16:45 | AH1: 2026-10-21 17:15 | AI1: 2026-10-21 17:45 | AJ1: 2026-10-21 18:30 | AK1: 2026-10-21 19:00 | AL1: 2026-10-21 19:30 | AM1: 2026-10-21 20:00 | AN1: 2026-10-21 20:30 | AO1: 2026-10-21 21:15 | AP1: 2026-10-21 22:00 | AQ1: 2026-10-21 22:30 | AR1: 2026-10-21 23:00 | AS1: 2026-10-21 23:30 | AT1: 2026-10-22 00:00
A2: 临帝阙 | B2: 1 | C2: 1 | D2: 1 | E2: 1 | F2: 1 | G2: 1 | H2: 1 | I2: 1 | J2: 1 | K2: 1 | L2: 1 | M2: 1 | N2: 1 | O2: 1 | P2: 1 | Q2: 1 | R2: 1 | S2: 1 | T2: 1 | U2: 1 | V2: 1 | W2: 1 | X2: 1 | Y2: 1 | Z2: 1 | AA2: 1 | AB2: 1 | AC2: 1 | AD2: 1 | AE2: 1 | AF2: 1 | AG2: 1 | AH2: 1 | AI2: 1 | AJ2: 1 | AK2: 1 | AL2: 1 | AM2: 1 | AN2: 1 | AO2: 1 | AP2: 1 | AQ2: 1 | AR2: 1 | AS2: 1 | AT2: 1
A3: 风华临安 | B3: 2 | C3: 2 | D3: 2 | E3: 2 | F3: 2 | G3: 2 | H3: 2 | I3: 2 | J3: 2 | K3: 2 | L3: 2 | M3: 2 | N3: 2 | O3: 2 | P3: 3 | Q3: 2 | R3: 3 | S3: 3 | T3: 3 | U3: 3 | V3: 3 | W3: 3 | X3: 3 | Y3: 3 | Z3: 2 | AA3: 2 | AB3: 3 | AC3: 3 | AD3: 3 | AE3: 3 | AF3: 3 | AG3: 3 | AH3: 3 | AI3: 3 | AJ3: 3 | AK3: 3 | AL3: 3 | AM3: 6 | AN3: 6 | AO3: 5 | AP3: 6 | AQ3: 6 | AR3: 6 | AS3: 6 | AT3: 2
A4: 师途 | B4: 4 | C4: 4 | D4: 4 | E4: 4 | F4: 4 | G4: 4 | H4: 3 | I4: 3 | J4: 4 | K4: 5 | L4: 7 | M4: 6 | N4: 5 | O4: 6 | P4: 7 | Q4: 10 | R4: 6 | S4: 2 | T4: 2 | U4: 4 | V4: 4 | W4: 4 | X4: 4 | Y4: 4 | Z4: 4 | AA4: 4 | AB4: 4 | AC4: 4 | AD4: 4 | AE4: 4 | AF4: 5 | AG4: 4 | AH4: 4 | AI4: 5 | AJ4: 5 | AK4: 5 | AL4: 4 | AM4: 5 | AN4: 2 | AO4: 3 | AP4: 4 | AQ4: 4 | AR4: 3 | AS4: 3 | AT4: 3
A5: 江山千秋万代 | B5: 3 | C5: 3 | D5: 3 | E5: 3 | F5: 3 | G5: 3 | H5: 4 | I5: 4 | J5: 3 | K5: 3 | L5: 3 | M5: 3 | N5: 3 | O5: 3 | P5: 2 | Q5: 3 | R5: 2 | S5: 4 | T5: 4 | U5: 2 | V5: 2 | W5: 2 | X5: 2 | Y5: 2 | Z5: 3 | AA5: 3 | AB5: 2 | AC5: 2 | AD5: 2 | AE5: 2 | AF5: 2 | AG5: 2 | AH5: 2 | AI5: 2 | AJ5: 2 | AK5: 2 | AL5: 2 | AM5: 2 | AN5: 4 | AO5: 4 | AP5: 2 | AQ5: 3 | AR5: 4 | AS5: 4 | AT5: 4
A6: 情欲道 | AN6: 32 | AO6: 7 | AP6: 5 | AQ6: 5 | AR6: 5 | AS6: 5 | AT6: 5
A7: 捉鬼师后日谈 | B7: 6 | C7: 6 | D7: 6 | E7: 5 | F7: 5 | G7: 9 | H7: 6 | I7: 7 | J7: 10 | K7: 10 | L7: 10 | M7: 10 | N7: 6 | O7: 12 | P7: 8 | Q7: 7 | R7: 12 | S7: 12 | T7: 11 | U7: 8 | V7: 5 | W7: 5 | X7: 10 | Y7: 11 | Z7: 6 | AA7: 5 | AB7: 7 | AC7: 5 | AD7: 6 | AE7: 5 | AF7: 4 | AG7: 5 | AH7: 5 | AI7: 4 | AJ7: 6 | AK7: 4 | AL7: 5 | AM7: 7 | AN7: 3 | AO7: 2 | AP7: 3 | AQ7: 2 | AR7: 2 | AS7: 2 | AT7: 6
A8: 怪我过分美丽 | B8: 8 | C8: 9 | D8: 9 | E8: 9 | F8: 9 | G8: 8 | H8: 9 | I8: 10 | J8: 9 | K8: 4 | L8: 5 | M8: 8 | N8: 10 | O8: 10 | P8: 9 | Q8: 8 | R8: 9 | S8: 8 | T8: 9 | U8: 9 | V8: 8 | W8: 9 | X8: 8 | Y8: 7 | Z8: 7 | AA8: 9 | AB8: 8 | AC8: 8 | AD8: 10 | AE8: 12 | AF8: 14 | AG8: 14 | AH8: 13 | AI8: 14 | AJ8: 12 | AK8: 12 | AL8: 11 | AM8: 11 | AN8: 10 | AO8: 11 | AP8: 10 | AQ8: 12 | AR8: 7 | AS8: 7 | AT8: 7
A9: 后宫升职手札 | B9: 13 | C9: 13 | D9: 13 | E9: 14 | F9: 14 | G9: 19 | H9: 12 | I9: 18 | J9: 18 | K9: 18 | L9: 12 | M9: 12 | N9: 12 | O9: 14 | P9: 14 | Q9: 13 | R9: 15 | S9: 13 | T9: 13 | U9: 12 | V9: 10 | W9: 10 | X9: 9 | Y9: 8 | Z9: 11 | AA9: 10 | AB9: 12 | AC9: 12 | AD9: 12 | AE9: 7 | AF9: 8 | AG9: 9 | AH9: 9 | AI9: 9 | AJ9: 9 | AK9: 8 | AL9: 23 | AM9: 19 | AN9: 17 | AO9: 8 | AP9: 8 | AQ9: 8 | AR9: 9 | AS9: 8 | AT9: 8
A10: AMNESIA 失忆症 | B10: 10 | C10: 11 | D10: 11 | E10: 12 | F10: 13 | G10: 11 | H10: 11 | I10: 11 | J10: 15 | K10: 14 | L10: 13 | M10: 13 | N10: 14 | O10: 11 | P10: 11 | Q10: 9 | R10: 7 | S10: 6 | T10: 6 | U10: 5 | V10: 7 | W10: 7 | X10: 6 | Y10: 10 | Z10: 9 | AA10: 8 | AB10: 5 | AC10: 9 | AD10: 11 | AE10: 10 | AF10: 13 | AG10: 13 | AH10: 8 | AI10: 15 | AJ10: 15 | AK10: 15 | AL10: 13 | AM10: 13 | AN10: 12 | AO10: 15 | AP10: 14 | AQ10: 14 | AR10: 14 | AS10: 9 | AT10: 9
A11: 恶女模拟器 | B11: 9 | C11: 7 | D11: 7 | E11: 7 | F11: 7 | G11: 6 | H11: 8 | I11: 8 | J11: 7 | K11: 7 | L11: 6 | M11: 5 | N11: 9 | O11: 8 | P11: 10 | Q11: 11 | R11: 11 | S11: 11 | T11: 10 | U11: 11 | V11: 12 | W11: 11 | X11: 11 | Y11: 9 | Z11: 12 | AA11: 12 | AB11: 10 | AC11: 10 | AD11: 9 | AE11: 9 | AF11: 10 | AG11: 11 | AH11: 10 | AI11: 10 | AJ11: 11 | AK11: 13 | AL11: 12 | AM11: 12 | AN11: 11 | AO11: 13 | AP11: 13 | AQ11: 11 | AR11: 12 | AS11: 11 | AT11: 10
A12: 三界衔 | B12: 5 | C12: 5 | D12: 5 | E12: 6 | F12: 6 | G12: 5 | H12: 5 | I12: 6 | J12: 5 | K12: 6 | L12: 8 | M12: 7 | N12: 8 | O12: 5 | P12: 5 | Q12: 5 | R12: 5 | S12: 7 | T12: 7 | U12: 7 | V12: 9 | W12: 8 | X12: 7 | Y12: 5 | Z12: 8 | AA12: 6 | AB12: 6 | AC12: 6 | AD12: 5 | AE12: 6 | AF12: 9 | AG12: 10 | AH12: 11 | AI12: 13 | AJ12: 13 | AK12: 14 | AL12: 10 | AM12: 10 | AN12: 9 | AO12: 10 | AP12: 11 | AQ12: 13 | AR12: 10 | AS12: 10 | AT12: 11
A13: 宫妃 | B13: 7 | C13: 8 | D13: 8 | E13: 8 | F13: 8 | G13: 7 | H13: 7 | I13: 5 | J13: 8 | K13: 8 | L13: 9 | M13: 9 | N13: 11 | O13: 13 | P13: 13 | Q13: 12 | R13: 10 | S13: 5 | T13: 5 | U13: 6 | V13: 6 | W13: 6 | X13: 5 | Y13: 6 | Z13: 5 | AA13: 11 | AB13: 11 | AC13: 7 | AD13: 8 | AE13: 11 | AF13: 6 | AG13: 6 | AH13: 6 | AI13: 8 | AJ13: 8 | AK13: 9 | AL13: 8 | AM13: 8 | AN13: 7 | AO13: 9 | AP13: 9 | AQ13: 9 | AR13: 13 | AS13: 12 | AT13: 12
A14: 星期天不上头条 | B14: 11 | C14: 10 | D14: 10 | E14: 10 | F14: 10 | G14: 12 | H14: 13 | I14: 13 | J14: 11 | K14: 13 | L14: 14 | M14: 14 | N14: 13 | O14: 9 | P14: 12 | Q14: 6 | R14: 8 | S14: 10 | T14: 8 | U14: 10 | V14: 11 | W14: 12 | X14: 12 | Y14: 12 | Z14: 10 | AA14: 7 | AB14: 9 | AC14: 11 | AD14: 7 | AE14: 8 | AF14: 12 | AG14: 12 | AH14: 12 | AI14: 11 | AJ14: 14 | AK14: 16 | AL14: 14 | AM14: 14 | AN14: 13 | AO14: 12 | AP14: 12 | AQ14: 10 | AR14: 11 | AS14: 13 | AT14: 13
A15: 蕉下鹿 | AF15: 181 | AG15: 52 | AH15: 22 | AI15: 12 | AJ15: 7 | AK15: 7 | AL15: 6 | AM15: 3 | AN15: 5 | AO15: 6 | AP15: 7 | AQ15: 7 | AR15: 8 | AS15: 14 | AT15: 14
A16: 京中叙 | B16: 17 | C16: 17 | D16: 15 | E16: 13 | F16: 12 | G16: 10 | H16: 10 | I16: 9 | J16: 13 | K16: 9 | L16: 11 | M16: 11 | N16: 7 | O16: 7 | P16: 6 | Q16: 14 | R16: 14 | S16: 18 | T16: 17 | U16: 16 | V16: 16 | W16: 15 | X16: 16 | Y16: 17 | Z16: 20 | AA16: 17 | AB16: 18 | AC16: 20 | AD16: 20 | AE16: 14 | AF16: 17 | AG16: 20 | AH16: 20 | AI16: 22 | AJ16: 20 | AK16: 21 | AL16: 19 | AM16: 20 | AN16: 21 | AO16: 20 | AP16: 20 | AQ16: 19 | AR16: 17 | AS16: 15 | AT16: 15
A17: 灰日告白 | B17: 12 | C17: 12 | D17: 12 | E17: 11 | F17: 11 | G17: 13 | H17: 14 | I17: 12 | J17: 12 | K17: 12 | L17: 15 | M17: 16 | N17: 19 | O17: 16 | P17: 17 | Q17: 17 | R17: 13 | S17: 17 | T17: 12 | U17: 15 | V17: 15 | W17: 14 | X17: 14 | Y17: 14 | Z17: 14 | AA17: 14 | AB17: 15 | AC17: 14 | AD17: 15 | AE17: 19 | AF17: 19 | AG17: 21 | AH17: 27 | AI17: 28 | AJ17: 21 | AK17: 25 | AL17: 20 | AM17: 16 | AN17: 16 | AO17: 17 | AP17: 17 | AQ17: 15 | AR17: 15 | AS17: 16 | AT17: 16
A18: 娱乐圈|热搜预定 | B18: 14 | C18: 14 | D18: 17 | E18: 16 | F18: 16 | G18: 15 | H18: 16 | I18: 15 | J18: 17 | K18: 16 | L18: 17 | M18: 17 | N18: 17 | O18: 18 | P18: 21 | Q18: 21 | R18: 18 | S18: 16 | T18: 15 | U18: 14 | V18: 13 | W18: 13 | X18: 13 | Y18: 13 | Z18: 13 | AA18: 13 | AB18: 14 | AC18: 15 | AD18: 13 | AE18: 15 | AF18: 16 | AG18: 16 | AH18: 15 | AI18: 16 | AJ18: 17 | AK18: 17 | AL18: 15 | AM18: 15 | AN18: 15 | AO18: 18 | AP18: 18 | AQ18: 18 | AR18: 18 | AS18: 17 | AT18: 17
A19: 仙路漫漫 | B19: 16 | C19: 15 | D19: 16 | E19: 15 | F19: 15 | G19: 14 | H19: 15 | I19: 16 | J19: 14 | K19: 11 | L19: 4 | M19: 4 | N19: 4 | O19: 4 | P19: 4 | Q19: 4 | R19: 4 | S19: 9 | T19: 14 | U19: 13 | V19: 14 | W19: 17 | X19: 15 | Y19: 15 | Z19: 15 | AA19: 15 | AB19: 13 | AC19: 13 | AD19: 14 | AE19: 17 | AF19: 7 | AG19: 7 | AH19: 7 | AI19: 6 | AJ19: 4 | AK19: 6 | AL19: 7 | AM19: 4 | AN19: 14 | AO19: 16 | AP19: 16 | AQ19: 16 | AR19: 16 | AS19: 18 | AT19: 18
A20: 我竟然是个女魔头 | B20: 32 | C20: 32 | D20: 33 | E20: 36 | F20: 34 | G20: 33 | H20: 29 | I20: 51 | J20: 56 | K20: 42 | L20: 52 | M20: 54 | N20: 54 | O20: 42 | P20: 39 | Q20: 28 | R20: 29 | S20: 45 | T20: 49 | U20: 45 | V20: 50 | W20: 55 | X20: 56 | Y20: 54 | Z20: 40 | AA20: 31 | AB20: 27 | AC20: 22 | AD20: 29 | AE20: 26 | AF20: 26 | AG20: 29 | AH20: 39 | AI20: 35 | AJ20: 39 | AK20: 40 | AL20: 36 | AM20: 41 | AN20: 36 | AO20: 31 | AP20: 29 | AQ20: 29 | AR20: 26 | AS20: 24 | AT20: 19
A21: 昭昭宫廷 | B21: 60 | C21: 58 | D21: 63 | E21: 56 | F21: 57 | G21: 58 | H21: 58 | I21: 64 | J21: 63 | K21: 52 | L21: 56 | M21: 58 | N21: 66 | O21: 57 | P21: 50 | Q21: 69 | R21: 53 | S21: 48 | T21: 50 | U21: 47 | V21: 49 | W21: 51 | X21: 47 | Y21: 42 | Z21: 46 | AA21: 50 | AB21: 22 | AC21: 18 | AD21: 16 | AE21: 13 | AF21: 11 | AG21: 8 | AH21: 14 | AI21: 7 | AJ21: 10 | AK21: 10 | AL21: 9 | AM21: 9 | AN21: 8 | AO21: 14 | AP21: 15 | AQ21: 17 | AR21: 19 | AS21: 19 | AT21: 20
A22: 勿扰修仙中 | B22: 18 | C22: 18 | D22: 18 | E22: 17 | F22: 17 | G22: 16 | H22: 17 | I22: 22 | J22: 21 | K22: 17 | L22: 18 | M22: 21 | N22: 22 | O22: 21 | P22: 20 | Q22: 22 | R22: 22 | S22: 21 | T22: 19 | U22: 17 | V22: 17 | W22: 16 | X22: 17 | Y22: 16 | Z22: 16 | AA22: 16 | AB22: 17 | AC22: 17 | AD22: 17 | AE22: 16 | AF22: 15 | AG22: 19 | AH22: 17 | AI22: 19 | AJ22: 18 | AK22: 19 | AL22: 17 | AM22: 17 | AN22: 18 | AO22: 19 | AP22: 21 | AQ22: 23 | AR22: 22 | AS22: 21 | AT22: 21
A23: 青宫赋 | B23: 20 | C23: 21 | D23: 20 | E23: 19 | F23: 18 | G23: 18 | H23: 21 | I23: 20 | J23: 19 | K23: 19 | L23: 19 | M23: 24 | N23: 28 | O23: 33 | P23: 41 | Q23: 41 | R23: 42 | S23: 35 | T23: 36 | U23: 29 | V23: 29 | W23: 27 | X23: 32 | Y23: 33 | Z23: 30 | AA23: 33 | AB23: 33 | AC23: 30 | AD23: 33 | AE23: 30 | AF23: 33 | AG23: 34 | AH23: 35 | AI23: 39 | AJ23: 36 | AK23: 37 | AL23: 34 | AM23: 31 | AN23: 29 | AO23: 25 | AP23: 23 | AQ23: 22 | AR23: 20 | AS23: 20 | AT23: 22
A24: 我在古代当首富￥ | B24: 26 | C24: 27 | D24: 27 | E24: 30 | F24: 32 | G24: 29 | H24: 28 | I24: 30 | J24: 33 | K24: 31 | L24: 32 | M24: 39 | N24: 38 | O24: 41 | P24: 38 | Q24: 39 | R24: 39 | S24: 23 | T24: 21 | U24: 19 | V24: 18 | W24: 18 | X24: 19 | Y24: 18 | Z24: 19 | AA24: 19 | AB24: 16 | AC24: 16 | AD24: 18 | AE24: 18 | AF24: 18 | AG24: 17 | AH24: 19 | AI24: 20 | AJ24: 19 | AK24: 20 | AL24: 18 | AM24: 18 | AN24: 19 | AO24: 21 | AP24: 19 | AQ24: 20 | AR24: 23 | AS24: 22 | AT24: 23
A25: 后妃成长录 | B25: 25 | C25: 25 | D25: 26 | E25: 25 | F25: 28 | G25: 30 | H25: 24 | I25: 24 | J25: 25 | K25: 23 | L25: 24 | M25: 23 | N25: 23 | O25: 24 | P25: 30 | Q25: 32 | R25: 38 | S25: 67 | T25: 61 | U25: 57 | V25: 26 | W25: 24 | X25: 24 | Y25: 48 | Z25: 44 | AA25: 46 | AB25: 49 | AC25: 47 | AD25: 48 | AE25: 20 | AF25: 22 | AG25: 28 | AH25: 28 | AI25: 26 | AJ25: 25 | AK25: 27 | AL25: 29 | AM25: 25 | AN25: 26 | AO25: 22 | AP25: 22 | AQ25: 21 | AR25: 21 | AS25: 23 | AT25: 24
A26: 古代主母风华录 | B26: 21 | C26: 22 | D26: 22 | E26: 23 | F26: 23 | G26: 21 | H26: 37 | I26: 19 | J26: 24 | K26: 22 | L26: 23 | M26: 31 | N26: 30 | O26: 27 | P26: 24 | Q26: 29 | R26: 26 | S26: 25 | T26: 28 | U26: 33 | V26: 35 | W26: 30 | X26: 18 | Y26: 26 | Z26: 31 | AA26: 21 | AB26: 21 | AC26: 38 | AD26: 21 | AE26: 22 | AF26: 21 | AG26: 23 | AH26: 24 | AI26: 25 | AJ26: 23 | AK26: 24 | AL26: 25 | AM26: 24 | AN26: 22 | AO26: 23 | AP26: 24 | AQ26: 24 | AR26: 24 | AS26: 25 | AT26: 25
A27: 世系长歌 | B27: 57 | C27: 50 | D27: 54 | E27: 52 | F27: 55 | G27: 43 | H27: 40 | I27: 28 | J27: 16 | K27: 15 | L27: 16 | M27: 15 | N27: 15 | O27: 15 | P27: 15 | Q27: 16 | R27: 24 | S27: 31 | T27: 33 | U27: 46 | V27: 44 | W27: 38 | X27: 43 | Y27: 45 | Z27: 33 | AA27: 18 | AB27: 19 | AC27: 19 | AD27: 19 | AE27: 21 | AF27: 20 | AG27: 22 | AH27: 23 | AI27: 27 | AJ27: 26 | AK27: 29 | AL27: 30 | AM27: 30 | AN27: 54 | AO27: 54 | AP27: 53 | AQ27: 52 | AR27: 28 | AS27: 27 | AT27: 26
... A60: 我在京城上头条 | B60: 40 | C60: 46 | D60: 44 | E60: 45 | F60: 45 | G60: 50 | H60: 48 | I60: 66 | J60: 65 | K60: 76 | L60: 80 | M60: 96 | N60: 79 | O60: 74 | P60: 66 | Q60: 86 | R60: 94 | S60: 72 | T60: 67 | U60: 43 | V60: 38 | W60: 37 | X60: 34 | Y60: 41 | Z60: 39 | AA60: 39 | AB60: 40 | AC60: 51 | AD60: 57 | AE60: 50 | AF60: 43 | AG60: 40 | AH60: 40 | AI60: 38 | AJ60: 34 | AK60: 35 | AL60: 32 | AM60: 33 | AN60: 43 | AO60: 53 | AP60: 55 | AQ60: 59 | AR60: 58 | AS60: 58 | AT60: 59
A61: 风过千山雪 | AN61: 41 | AO61: 37 | AP61: 38 | AQ61: 39 | AR61: 48 | AS61: 56 | AT61: 60
A62: 这宫斗没法继续了 | B62: 87 | C62: 98 | D62: 98 | E62: 97 | F62: 94 | G62: 94 | H62: 90 | I62: 85 | J62: 75 | K62: 81 | L62: 75 | M62: 67 | N62: 80 | O62: 76 | P62: 86 | Q62: 83 | R62: 61 | S62: 64 | T62: 72 | U62: 85 | V62: 75 | W62: 82 | X62: 87 | Y62: 93 | Z62: 112 | AA62: 117 | AB62: 125 | AC62: 113 | AD62: 136 | AE62: 141 | AF62: 143 | AG62: 131 | AH62: 124 | AI62: 122 | AJ62: 114 | AK62: 111 | AL62: 106 | AM62: 85 | AN62: 73 | AO62: 80 | AP62: 71 | AQ62: 62 | AR62: 38 | AS62: 46 | AT62: 61
A63: 入罗帷 | B63: 84 | C63: 75 | D63: 70 | E63: 70 | F63: 71 | G63: 67 | H63: 71 | I63: 73 | J63: 46 | K63: 110 | L63: 106 | M63: 98 | N63: 108 | O63: 100 | P63: 88 | Q63: 76 | R63: 86 | S63: 81 | T63: 75 | U63: 72 | V63: 77 | W63: 81 | X63: 81 | Y63: 80 | Z63: 78 | AA63: 84 | AB63: 69 | AC63: 79 | AD63: 74 | AE63: 79 | AF63: 44 | AG63: 50 | AH63: 53 | AI63: 56 | AJ63: 52 | AK63: 60 | AL63: 62 | AM63: 106 | AN63: 120 | AO63: 112 | AP63: 135 | AQ63: 114 | AR63: 107 | AS63: 63 | AT63: 62
A64: 后宫乱芳时 | B64: 83 | C64: 78 | D64: 74 | E64: 76 | F64: 73 | G64: 69 | H64: 69 | I64: 78 | J64: 74 | K64: 70 | L64: 72 | M64: 71 | N64: 73 | O64: 90 | P64: 87 | Q64: 89 | R64: 141 | S64: 92 | T64: 97 | U64: 76 | V64: 67 | W64: 64 | X64: 61 | Y64: 63 | Z64: 68 | AA64: 68 | AB64: 77 | AC64: 74 | AD64: 82 | AE64: 85 | AF64: 83 | AG64: 81 | AH64: 84 | AI64: 80 | AJ64: 82 | AK64: 80 | AL64: 78 | AM64: 83 | AN64: 70 | AO64: 72 | AP64: 60 | AQ64: 64 | AR64: 64 | AS64: 69 | AT64: 63
A65: 聚光灯后 | B65: 88 | C65: 99 | D65: 97 | E65: 98 | F65: 96 | G65: 93 | H65: 95 | I65: 101 | J65: 93 | K65: 109 | L65: 104 | M65: 117 | N65: 115 | O65: 73 | P65: 73 | Q65: 82 | R65: 81 | S65: 100 | T65: 94 | U65: 81 | V65: 85 | W65: 97 | X65: 85 | Y65: 76 | Z65: 71 | AA65: 62 | AB65: 68 | AC65: 78 | AD65: 77 | AE65: 73 | AF65: 31 | AG65: 31 | AH65: 33 | AI65: 32 | AJ65: 37 | AK65: 41 | AL65: 37 | AM65: 36 | AN65: 34 | AO65: 32 | AP65: 57 | AQ65: 60 | AR65: 33 | AS65: 33 | AT65: 64
A66: 内区观测录 | B66: 19 | C66: 19 | D66: 19 | E66: 24 | F66: 37 | G66: 37 | H66: 45 | I66: 68 | J66: 68 | K66: 121 | L66: 167 | Q66: 108 | R66: 79 | S66: 44 | T66: 38 | U66: 32 | V66: 40 | W66: 39 | X66: 37 | Y66: 44 | Z66: 41 | AA66: 49 | AB66: 62 | AC66: 60 | AD66: 63 | AE66: 63 | AF66: 68 | AG66: 92 | AH66: 95 | AI66: 90 | AJ66: 73 | AK66: 74 | AL66: 77 | AM66: 84 | AN66: 77 | AO66: 75 | AP66: 81 | AQ66: 81 | AR66: 77 | AS66: 74 | AT66: 65
A67: 第六视角 | B67: 51 | C67: 49 | D67: 48 | E67: 46 | F67: 46 | G67: 51 | H67: 53 | I67: 55 | J67: 85 | K67: 63 | L67: 45 | M67: 44 | N67: 51 | O67: 43 | P67: 46 | Q67: 35 | R67: 37 | S67: 27 | T67: 47 | U67: 39 | V67: 52 | W67: 47 | X67: 45 | Y67: 52 | Z67: 53 | AA67: 55 | AB67: 52 | AC67: 54 | AD67: 54 | AE67: 56 | AF67: 66 | AG67: 69 | AH67: 82 | AI67: 84 | AJ67: 94 | AK67: 97 | AL67: 102 | AM67: 93 | AN67: 93 | AO67: 89 | AP67: 92 | AQ67: 77 | AR67: 68 | AS67: 70 | AT67: 66
A68: 吾凰·在上 | B68: 54 | C68: 52 | D68: 55 | E68: 55 | F68: 50 | G68: 45 | H68: 43 | I68: 46 | J68: 64 | K68: 67 | L68: 58 | M68: 74 | N68: 86 | O68: 91 | P68: 78 | Q68: 61 | R68: 69 | S68: 58 | T68: 76 | U68: 80 | V68: 79 | W68: 59 | X68: 71 | Y68: 75 | Z68: 60 | AA68: 66 | AB68: 64 | AC68: 72 | AD68: 72 | AE68: 49 | AF68: 57 | AG68: 63 | AH68: 61 | AI68: 57 | AJ68: 56 | AK68: 69 | AL68: 89 | AM68: 78 | AN68: 76 | AO68: 87 | AP68: 80 | AQ68: 80 | AR68: 76 | AS68: 75 | AT68: 67
A69: 千秋百代：帝王一小时 | B69: 58 | C69: 55 | D69: 57 | E69: 63 | F69: 64 | G69: 66 | H69: 65 | I69: 70 | J69: 71 | K69: 66 | L69: 57 | M69: 52 | N69: 52 | O69: 68 | P69: 69 | Q69: 84 | R69: 80 | S69: 104 | T69: 103 | U69: 87 | V69: 80 | W69: 73 | X69: 77 | Y69: 68 | Z69: 74 | AA69: 63 | AB69: 65 | AC69: 61 | AD69: 56 | AE69: 58 | AF69: 59 | AG69: 58 | AH69: 54 | AI69: 58 | AJ69: 63 | AK69: 62 | AL69: 59 | AM69: 61 | AN69: 55 | AO69: 60 | AP69: 59 | AQ69: 61 | AR69: 65 | AS69: 68 | AT69: 68
A70: 模拟豪门人生 | B70: 61 | C70: 59 | D70: 66 | E70: 66 | F70: 65 | G70: 62 | H70: 64 | I70: 89 | J70: 82 | K70: 74 | L70: 69 | M70: 77 | N70: 77 | O70: 80 | P70: 77 | Q70: 71 | R70: 76 | S70: 63 | T70: 58 | U70: 58 | V70: 76 | W70: 84 | X70: 74 | Y70: 82 | Z70: 65 | AA70: 67 | AB70: 70 | AC70: 77 | AD70: 70 | AE70: 71 | AF70: 73 | AG70: 68 | AH70: 72 | AI70: 75 | AJ70: 89 | AK70: 87 | AL70: 93 | AM70: 91 | AN70: 98 | AO70: 93 | AP70: 73 | AQ70: 68 | AR70: 63 | AS70: 67 | AT70: 69
A71: 金珠遗梦 | B71: 64 | C71: 51 | D71: 51 | E71: 50 | F71: 52 | G71: 47 | H71: 47 | I71: 48 | J71: 51 | K71: 53 | L71: 53 | M71: 45 | N71: 53 | O71: 59 | P71: 51 | Q71: 53 | R71: 48 | S71: 51 | T71: 65 | U71: 54 | V71: 57 | W71: 49 | X71: 58 | Y71: 55 | Z71: 50 | AA71: 53 | AB71: 54 | AC71: 67 | AD71: 65 | AE71: 65 | AF71: 75 | AG71: 76 | AH71: 73 | AI71: 65 | AJ71: 66 | AK71: 86 | AL71: 85 | AM71: 80 | AN71: 78 | AO71: 65 | AP71: 65 | AQ71: 73 | AR71: 72 | AS71: 77 | AT71: 70
A72: 赴韶光 | B72: 53 | C72: 63 | D72: 60 | E72: 61 | F72: 58 | G72: 60 | H72: 62 | I72: 36 | J72: 59 | K72: 56 | L72: 49 | M72: 81 | N72: 63 | O72: 55 | P72: 45 | Q72: 34 | R72: 32 | S72: 38 | T72: 32 | U72: 30 | V72: 33 | W72: 61 | X72: 55 | Y72: 51 | Z72: 61 | AA72: 75 | AB72: 82 | AC72: 68 | AD72: 69 | AE72: 52 | AF72: 60 | AG72: 65 | AH72: 65 | AI72: 61 | AJ72: 68 | AK72: 68 | AL72: 72 | AM72: 67 | AN72: 64 | AO72: 63 | AP72: 68 | AQ72: 74 | AR72: 74 | AS72: 73 | AT72: 71
...

Sheet 人气变化
A1: 作品名 | B1: 2026-10-21 00:30 | C1: 2026-10-21 01:00 | D1: 2026-10-21 01:30 | E1: 2026-10-21 02:00 | F1: 2026-10-21 02:30 | G1: 2026-10-21 03:15 | H1: 2026-10-21 03:45 | I1: 2026-10-21 04:15 | J1: 2026-10-21 04:45 | K1: 2026-10-21 05:15 | L1: 2026-10-21 05:45 | M1: 2026-10-21 06:15 | N1: 2026-10-21 06:45 | O1: 2026-10-21 07:15 | P1: 2026-10-21 07:30 | Q1: 2026-10-21 08:00 | R1: 2026-10-21 08:15 | S1: 2026-10-21 09:00 | T1: 2026-10-21 09:30 | U1: 2026-10-21 10:00 | V1: 2026-10-21 10:30 | W1: 2026-10-21 11:00 | X1: 2026-10-21 11:30 | Y1: 2026-10-21 12:00 | Z1: 2026-10-21 12:30 | AA1: 2026-10-21 13:00 | AB1: 2026-10-21 13:30 | AC1: 2026-10-21 14:00 | AD1: 2026-10-21 14:30 | AE1: 2026-10-21 15:30 | AF1: 2026-10-21 16:00 | AG1: 2026-10-21 16:45 | AH1: 2026-10-21 17:15 | AI1: 2026-10-21 17:45 | AJ1: 2026-10-21 18:30 | AK1: 2026-10-21 19:00 | AL1: 2026-10-21 19:30 | AM1: 2026-10-21 20:00 | AN1: 2026-10-21 20:30 | AO1: 2026-10-21 21:15 | AP1: 2026-10-21 22:00 | AQ1: 2026-10-21 22:30 | AR1: 2026-10-21 23:00 | AS1: 2026-10-21 23:30 | AT1: 2026-10-22 00:00
A2: 师途 | B2: 159259914 | C2: 159259914 | D2: 159264438 | E2: 159264438 | F2: 159264438 | G2: 159264438 | H2: 159266166 | I2: 159266166 | J2: 159266593 | K2: 159266593 | L2: 159266593 | M2: 159266593 | N2: 159267116 | O2: 159267116 | P2: 159267508 | Q2: 159267508 | R2: 159267508 | S2: 159267508 | T2: 159268666 | U2: 159268666 | V2: 159269518 | W2: 159269518 | X2: 159269518 | Y2: 159269518 | Z2: 159271469 | AA2: 159271469 | AB2: 159272807 | AC2: 159272807 | AD2: 159274209 | AE2: 159274209 | AF2: 159274209 | AG2: 159276713 | AH2: 159277941 | AI2: 159277941 | AJ2: 159279176 | AK2: 159279176 | AL2: 159280549 | AM2: 159280549 | AN2: 159282122 | AO2: 159283918 | AP2: 159283918 | AQ2: 159285984 | AR2: 159285984 | AS2: 159285984 | AT2: 159285984
A3: 临帝阙 | B3: 141478309 | C3: 141478309 | D3: 141485274 | E3: 141485274 | F3: 141485274 | G3: 141485274 | H3: 141487882 | I3: 141487882 | J3: 141488513 | K3: 141488513 | L3: 141488513 | M3: 141488513 | N3: 141489286 | O3: 141489286 | P3: 141489770 | Q3: 141489770 | R3: 141489770 | S3: 141489770 | T3: 141491110 | U3: 141491110 | V3: 141492408 | W3: 141492408 | X3: 141492408 | Y3: 141492408 | Z3: 141495365 | AA3: 141495365 | AB3: 141497564 | AC3: 141497564 | AD3: 141500008 | AE3: 141500008 | AF3: 141500008 | AG3: 141504440 | AH3: 141504440 | AI3: 141504440 | AJ3: 141504440 | AK3: 141508845 | AL3: 141508845 | AM3: 141511058 | AN3: 141511058 | AO3: 141513778 | AP3: 141516835 | AQ3: 141520384 | AR3: 141520384 | AS3: 141520384 | AT3: 141520384
A4: 仙路漫漫 | B4: 93146529 | C4: 93146529 | D4: 93148357 | E4: 93148357 | F4: 93148357 | G4: 93148357 | H4: 93149003 | I4: 93149003 | J4: 93149133 | K4: 93149133 | L4: 93149133 | M4: 93149133 | N4: 93149384 | O4: 93149384 | P4: 93149654 | Q4: 93149654 | R4: 93149654 | S4: 93149654 | T4: 93150096 | U4: 93150096 | V4: 93150445 | W4: 93150445 | X4: 93150445 | Y4: 93150445 | Z4: 93151195 | AA4: 93151195 | AB4: 93151684 | AC4: 93151684 | AD4: 93152150 | AE4: 93152150 | AF4: 93152150 | AG4: 93153080 | AH4: 93153577 | AI4: 93153577 | AJ4: 93154029 | AK4: 93154029 | AL4: 93154555 | AM4: 93154555 | AN4: 93155127 | AO4: 93155794 | AP4: 93155794 | AQ4: 93156528 | AR4: 93156528 | AS4: 93156528 | AT4: 93156528
A5: 宫斗这件小事新版 | B5: 83879240 | C5: 83879240 | D5: 83879765 | E5: 83879765 | F5: 83879765 | G5: 83879765 | H5: 83879971 | I5: 83879971 | J5: 83880017 | K5: 83880017 | L5: 83880017 | M5: 83880017 | N5: 83880116 | O5: 83880116 | P5: 83880163 | Q5: 83880163 | R5: 83880163 | S5: 83880163 | T5: 83880266 | U5: 83880266 | V5: 83880350 | W5: 83880350 | X5: 83880350 | Y5: 83880350 | Z5: 83880557 | AA5: 83880557 | AB5: 83880728 | AC5: 83880728 | AD5: 83880888 | AE5: 83880888 | AF5: 83880888 | AG5: 83881321 | AH5: 83881483 | AI5: 83881483 | AJ5: 83881652 | AK5: 83881652 | AL5: 83881857 | AM5: 83881857 | AN5: 83882038 | AO5: 83882274 | AP5: 83882274 | AQ5: 83882545 | AR5: 83882545 | AS5: 83882545 | AT5: 83882545
A6: 怪我过分美丽 | B6: 62796856 | C6: 62796856 | D6: 62800552 | E6: 62800552 | F6: 62800552 | G6: 62800552 | H6: 62801765 | I6: 62801765 | J6: 62802059 | K6: 62802059 | L6: 62802059 | M6: 62802059 | N6: 62802429 | O6: 62802429 | P6: 62802739 | Q6: 62802739 | R6: 62802739 | S6: 62802739 | T6: 62803655 | U6: 62803655 | V6: 62804414 | W6: 62804414 | X6: 62804414 | Y6: 62804414 | Z6: 62806128 | AA6: 62806128 | AB6: 62807199 | AC6: 62807199 | AD6: 62808338 | AE6: 62808338 | AF6: 62808338 | AG6: 62810555 | AH6: 62810555 | AI6: 62810555 | AJ6: 62812599 | AK6: 62812599 | AL6: 62813636 | AM6: 62813636 | AN6: 62814853 | AO6: 62814853 | AP6: 62816168 | AQ6: 62817657 | AR6: 62817657 | AS6: 62817657 | AT6: 62817657
A7: 幼主本纪 | B7: 47002305 | C7: 47002305 | D7: 47002563 | E7: 47002563 | F7: 47002563 | G7: 47002563 | H7: 47002659 | I7: 47002659 | J7: 47002697 | K7: 47002697 | L7: 47002697 | M7: 47002697 | N7: 47002721 | O7: 47002721 | X7: 47002855 | Y7: 47002855 | Z7: 47002951 | AA7: 47002951 | AB7: 47003029 | AC7: 47003029 | AD7: 47003098 | AE7: 47003098 | AF7: 47003098 | AG7: 47003244 | AH7: 47003244 | AI7: 47003244 | AJ7: 47003372 | AK7: 47003372 | AL7: 47003456 | AM7: 47003456 | AN7: 47003549 | AO7: 47003549 | AP7: 47003655 | AQ7: 47003778 | AR7: 47003778 | AS7: 47003778 | AT7: 47003778
A8: 神也梦春秋 | B8: 42241956 | C8: 42241956 | D8: 42241956 | E8: 42244910 | F8: 42244910 | G8: 42244910 | H8: 42245961 | I8: 42245961 | J8: 42246222 | K8: 42246222 | L8: 42246222 | M8: 42246222 | N8: 42246479 | O8: 42246479 | P8: 42246479 | Q8: 42246713 | R8: 42246713 | S8: 42246713 | T8: 42246713 | U8: 42247388 | V8: 42247388 | W8: 42247884 | X8: 42247884 | Y8: 42247884 | Z8: 42247884 | AA8: 42247884 | AB8: 42247884 | AC8: 42249653 | AD8: 42249653 | AE8: 42250310 | AF8: 42250310 | AG8: 42251409 | AH8: 42251409 | AI8: 42251409 | AJ8: 42251409 | AK8: 42252599 | AL8: 42252599 | AM8: 42253335 | AN8: 42253335 | AO8: 42254022 | AP8: 42254862 | AQ8: 42254862 | AR8: 42255882 | AS8: 42255882 | AT8: 42255882
A9: 宫妃 | B9: 38359612 | C9: 38359612 | D9: 38360778 | E9: 38360778 | F9: 38360778 | G9: 38360778 | H9: 38361222 | I9: 38361222 | J9: 38361336 | K9: 38361336 | L9: 38361336 | M9: 38361336 | N9: 38361499 | O9: 38361499 | P9: 38361570 | Q9: 38361570 | R9: 38361570 | S9: 38361570 | T9: 38361769 | U9: 38361769 | V9: 38361977 | W9: 38361977 | X9: 38361977 | Y9: 38361977 | Z9: 38362549 | AA9: 38362549 | AB9: 38362957 | AC9: 38362957 | AD9: 38363298 | AE9: 38363298 | AF9: 38363298 | AG9: 38364078 | AH9: 38364456 | AI9: 38364456 | AJ9: 38364809 | AK9: 38364809 | AL9: 38365148 | AM9: 38365148 | AN9: 38365540 | AO9: 38366026 | AP9: 38366026 | AQ9: 38366496 | AR9: 38366496 | AS9: 38366496 | AT9: 38366496
A10: 江山千秋万代 | B10: 37557038 | C10: 37557038 | D10: 37557038 | E10: 37564202 | F10: 37564202 | G10: 37564202 | H10: 37567169 | I10: 37567169 | J10: 37567852 | K10: 37567852 | L10: 37567852 | M10: 37567852 | N10: 37568637 | O10: 37568637 | P10: 37568637 | Q10: 37569226 | R10: 37569226 | S10: 37569226 | T10: 37569226 | U10: 37571503 | V10: 37571503 | W10: 37573422 | X10: 37573422 | Y10: 37573422 | Z10: 37573422 | AA10: 37573422 | AB10: 37573422 | AC10: 37580736 | AD10: 37580736 | AE10: 37583598 | AF10: 37583598 | AG10: 37588705 | AH10: 37588705 | AI10: 37588705 | AJ10: 37588705 | AK10: 37593213 | AL10: 37593213 | AM10: 37595625 | AN10: 37595625 | AO10: 37598367 | AP10: 37601513 | AQ10: 37601513 | AR10: 37605180 | AS10: 37605180 | AT10: 37605180
A11: 皇后是只狐狸精 | B11: 35222168 | C11: 35222168 | D11: 35222575 | E11: 35222575 | F11: 35222575 | G11: 35222575 | H11: 35222747 | I11: 35222747 | J11: 35222785 | K11: 35222785 | L11: 35222785 | M11: 35222785 | N11: 35222851 | O11: 35222851 | P11: 35222882 | Q11: 35222882 | R11: 35222882 | S11: 35222882 | T11: 35222966 | U11: 35222966 | V11: 35223047 | W11: 35223047 | X11: 35223047 | Y11: 35223047 | Z11: 35223193 | AA11: 35223193 | AB11: 35223324 | AC11: 35223324 | AD11: 35223465 | AE11: 35223465 | AF11: 35223465 | AG11: 35223730 | AH11: 35223730 | AI11: 35223730 | AJ11: 35223943 | AK11: 35223943 | AL11: 35224144 | AM11: 35224144 | AN11: 35224338 | AO11: 35224338 | AP11: 35224564 | AQ11: 35224828 | AR11: 35224828 | AS11: 35224828 | AT11: 35224828
A12: 后宫乱芳时 | B12: 34255882 | C12: 34255882 | D12: 34256296 | E12: 34256296 | F12: 34256296 | G12: 34256296 | H12: 34256448 | I12: 34256448 | J12: 34256485 | K12: 34256485 | L12: 34256485 | M12: 34256485 | N12: 34256545 | O12: 34256545 | P12: 34256575 | Q12: 34256575 | R12: 34256575 | S12: 34256575 | T12: 34256658 | U12: 34256658 | V12: 34256717 | W12: 34256717 | X12: 34256717 | Y12: 34256717 | Z12: 34256884 | AA12: 34256884 | AB12: 34256986 | AC12: 34256986 | AD12: 34257091 | AE12: 34257091 | AF12: 34257091 | AG12: 34257322 | AH12: 34257322 | AI12: 34257322 | AJ12: 34257322 | AK12: 34257570 | AL12: 34257570 | AM12: 34257697 | AN12: 34257697 | AO12: 34257829 | AP12: 34258032 | AQ12: 34258248 | AR12: 34258248 | AS12: 34258248 | AT12: 34258248
A13: 都想攻略女魔头 | B13: 33458077 | C13: 33458077 | D13: 33458870 | E13: 33458870 | F13: 33458870 | G13: 33458870 | H13: 33459140 | I13: 33459140 | J13: 33459212 | K13: 33459212 | L13: 33459212 | M13: 33459212 | N13: 33459329 | O13: 33459329 | P13: 33459403 | Q13: 33459403 | R13: 33459403 | S13: 33459403 | T13: 33459579 | U13: 33459579 | V13: 33459708 | W13: 33459708 | X13: 33459708 | Y13: 33459708 | Z13: 33459978 | AA13: 33459978 | AB13: 33460168 | AC13: 33460168 | AD13: 33460361 | AE13: 33460361 | AF13: 33460361 | AG13: 33460623 | AH13: 33460623 | AI13: 33460623 | AJ13: 33460878 | AK13: 33460878 | AL13: 33461067 | AM13: 33461067 | AN13: 33461280 | AO13: 33461280 | AP13: 33461819 | AQ13: 33462335 | AR13: 33462335 | AS13: 33462335 | AT13: 33462335
A14: 逢尊 | B14: 33249813 | C14: 33249813 | D14: 33250192 | E14: 33250192 | F14: 33250192 | G14: 33250192 | H14: 33250357 | I14: 33250357 | J14: 33250401 | K14: 33250401 | L14: 33250401 | M14: 33250401 | N14: 33250465 | O14: 33250465 | P14: 33250479 | Q14: 33250479 | R14: 33250479 | S14: 33250479 | T14: 33250542 | W14: 33250604 | X14: 33250604 | Y14: 33250604 | Z14: 33250729 | AA14: 33250729 | AB14: 33250827 | AC14: 33250827 | AD14: 33250935 | AE14: 33250935 | AF14: 33250935 | AG14: 33251167 | AH14: 33251167 | AI14: 33251167 | AJ14: 33251400 | AK14: 33251400 | AL14: 33251539 | AM14: 33251539 | AN14: 33251699 | AO14: 33251699 | AP14: 33251854 | AQ14: 33252003 | AR14: 33252003 | AS14: 33252003 | AT14: 33252003
A15: 古代人生模拟器 | B15: 30117068 | C15: 30117068 | D15: 30117341 | E15: 30117341 | F15: 30117341 | G15: 30117341 | H15: 30117474 | I15: 30117474 | J15: 30117513 | K15: 30117513 | L15: 30117513 | M15: 30117513 | N15: 30117543 | O15: 30117543 | P15: 30117567 | Q15: 30117567 | R15: 30117567 | S15: 30117567 | T15: 30117602 | U15: 30117602 | V15: 30117655 | W15: 30117655 | X15: 30117655 | Y15: 30117655 | Z15: 30117758 | AA15: 30117758 | AB15: 30117853 | AC15: 30117853 | AD15: 30117932 | AE15: 30117932 | AF15: 30117932 | AG15: 30118101 | AH15: 30118101 | AI15: 30118101 | AJ15: 30118264 | AK15: 30118264 | AL15: 30118349 | AM15: 30118349 | AN15: 30118458 | AO15: 30118458 | AP15: 30118575 | AQ15: 30118666 | AR15: 30118666 | AS15: 30118666 | AT15: 30118666
