Workbook

Sheet 付费榜当日最终
A1: 2026-10-09 付费榜最终排名（当天最后一次抓取，榜单时间 2026-10-10 00:00）
A3: 排名 | B3: 作品名 | C3: 作品ID | D3: 人气 | E3: 收藏 | F3: 点赞
A4: 1 | B4: 师途 | C4: 32351 | D4: 158843139 | E4: 1696375 | F4: 441233
A5: 2 | B5: 临帝阙 | C5: 178176 | D5: 140763457 | E5: 1634309 | F5: 330454
A6: 3 | B6: 三界衔 | C6: 1561773 | D6: 2324902 | E6: 361713 | F6: 18869
A7: 4 | B7: 江山千秋万代 | C7: 368816 | D7: 37047549 | E7: 462519 | F7: 61038
A8: 5 | B8: 星期天不上头条 | C8: 468214 | D8: 8109575 | E8: 188942 | F8: 16370
A9: 6 | B9: 勿扰修仙中 | C9: 397723 | D9: 15112167 | E9: 322706 | F9: 44702
A10: 7 | B10: 怪我过分美丽 | C10: 103593 | D10: 62418635 | E10: 714323 | F10: 123201
A11: 8 | B11: 成为团播TOP之后 | C11: 1991368 | D11: 124247 | E11: 76457 | F11: 805
A12: 9 | B12: 风华临安 | C12: 1644173 | D12: 5512477 | E12: 210810 | F12: 30799
A13: 10 | B13: 宫妃 | C13: 8075 | D13: 38255265 | E13: 494283 | F13: 105998
A14: 11 | B14: 仙路漫漫 | C14: 35066 | D14: 92984686 | E14: 908761 | F14: 220058
A15: 12 | B15: AMNESIA 失忆症 | C15: 3862 | D15: 9208211 | E15: 497996 | F15: 105956
... A203: 200 | B203: 殿下在上 | C203: 1080703 | D203: 2453681 | E203: 144908 | F203: 14934

Sheet 当日增长
A1: 2026-10-09 人气/收藏/点赞增长 = 今天最后一次抓取 − 昨天最后一次抓取；只统计当天上过付费榜或活跃榜的作品
A3: 作品名 | B3: 作品ID | C3: 人气 | D3: 人气增长 | E3: 收藏 | F3: 收藏增长 | G3: 点赞 | H3: 点赞增长
A4: 临帝阙 | B4: 178176 | C4: 140763457 | D4: 71285 | E4: 1634309 | F4: 362 | G4: 330454 | H4: 96
A5: 江山千秋万代 | B5: 368816 | C5: 37047549 | D5: 49756 | E5: 462519 | F5: 363 | G5: 61038 | H5: 49
A6: 师途 | B6: 32351 | C6: 158843139 | D6: 39073 | E6: 1696375 | F6: 270 | G6: 441233 | H6: 69
A7: 怪我过分美丽 | B7: 103593 | C7: 62418635 | D7: 35435 | E7: 714323 | F7: 133 | G7: 123201 | H7: 28
A8: 三界衔 | B8: 1561773 | C8: 2324902 | D8: 34405 | E8: 361713 | F8: 281 | G8: 18869 | H8: 88
A9: 星期天不上头条 | B9: 468214 | C9: 8109575 | D9: 32313 | E9: 188942 | F9: 223 | G9: 16370 | H9: 34
A10: 娱乐圈|热搜预定 | B10: 802492 | C10: 15587948 | D10: 28633 | E10: 312921 | F10: 176 | G10: 40603 | H10: 40
A11: 风华临安 | B11: 1644173 | C11: 5512477 | D11: 27532 | E11: 210810 | F11: 471 | G11: 30799 | H11: 105
A12: 勿扰修仙中 | B12: 397723 | C12: 15112167 | D12: 22460 | E12: 322706 | F12: 272 | G12: 44702 | H12: 49
A13: 京中叙 | B13: 1544579 | C13: 5977671 | D13: 21147 | E13: 336581 | F13: 348 | G13: 29183 | H13: 67
A14: 捉鬼师后日谈 | B14: 436436 | C14: 29742354 | D14: 19426 | E14: 855142 | F14: 417 | G14: 244679 | H14: 155
A15: 神也梦春秋 | B15: 325672 | C15: 42004890 | D15: 19255 | E15: 481381 | F15: 108 | G15: 86846 | H15: 35
... A336: 天命不奈何 | B336: 1967410 | C336: 725593 | D336: 0 | E336: 113683 | F336: 1 | G336: 4452 | H336: 0
A337: 御妖名单 | B337: 19681 | C337: 1296924 | E337: 62654 | G337: 10087
A338: 京城第一经纪人 | B338: 33125 | C338: 11340945 | E338: 193632 | G338: 35660
A339: 结缘吧道友 | B339: 34670 | C339: 1186153 | E339: 22681 | G339: 4142
A340: 恶役大小姐养成计划 | B340: 40929 | C340: 4710921 | E340: 124706 | G340: 26168
A341: 乱世沉浮录 | B341: 43440 | C341: 13953261 | E341: 225741 | G341: 41741
A342: 震惊！主上有病？ | B342: 47142 | C342: 6948451 | E342: 179721 | G342: 34674
A343: 继母准则 | B343: 127772 | C343: 6473930 | E343: 175175 | G343: 24185
A344: 公主请登基 | B344: 167799 | C344: 7723163 | E344: 206611 | G344: 31223
A345: 反派鬼王在线重生 | B345: 168073 | C345: 4503193 | E345: 149003 | G345: 24963
A346: 无限奇迹人生 | B346: 183630 | C346: 8942729 | E346: 186944 | G346: 30167
A347: 炉鼎自救指南 | B347: 195234 | C347: 8287452 | E347: 326740 | G347: 58385
A348: 斩月 | B348: 206067 | C348: 2057399 | E348: 136255 | G348: 13059
... A440: 疯批的诱惑 | B440: 2389941 | C440: 14605 | E440: 8748 | G440: 156

Sheet 趋势查询
A1: 作品名称： | B1: 师途
A2: 在黄色格子里输入作品名，或点右侧小箭头从列表里选；空白表示当时没有数据（未上榜）
A4: 榜单时间 | B4: 付费榜 | C4: 活跃榜 | D4: 人气 | E4: 收藏 | F4: 点赞
A5: 2026-10-09 00:15 | B5: =IFERROR(INDEX('付费榜排名变化'!$A$1:$CF$367,MATCH($B$1,'付费榜排名变化'!$A$1:$A$367,0),MATCH($A5,'付费榜排名变化'!$A$1:$CF$1,0)),NA()) | C5: =IFERROR(INDEX('活跃榜排名变化'!$A$1:$CF$343,MATCH($B$1,'活跃榜排名变化'!$A$1:$A$343,0),MATCH($A5,'活跃榜排名变化'!$A$1:$CF$1,0)),NA()) | D5: =IFERROR(INDEX('人气变化'!$A$1:$CF$438,MATCH($B$1,'人气变化'!$A$1:$A$438,0),MATCH($A5,'人气变化'!$A$1:$CF$1,0)),NA()) | E5: =IFERROR(INDEX('收藏变化'!$A$1:$CF$438,MATCH($B$1,'收藏变化'!$A$1:$A$438,0),MATCH($A5,'收藏变化'!$A$1:$CF$1,0)),NA()) | F5: =IFERROR(INDEX('点赞变化'!$A$1:$CF$438,MATCH($B$1,'点赞变化'!$A$1:$A$438,0),MATCH($A5,'点赞变化'!$A$1:$CF$1,0)),NA())
A6: 2026-10-09 00:45 | B6: =IFERROR(INDEX('付费榜排名变化'!$A$1:$CF$367,MATCH($B$1,'付费榜排名变化'!$A$1:$A$367,0),MATCH($A6,'付费榜排名变化'!$A$1:$CF$1,0)),NA()) | C6: =IFERROR(INDEX('活跃榜排名变化'!$A$1:$CF$343,MATCH($B$1,'活跃榜排名变化'!$A$1:$A$343,0),MATCH($A6,'活跃榜排名变化'!$A$1:$CF$1,0)),NA()) | D6: =IFERROR(INDEX('人气变化'!$A$1:$CF$438,MATCH($B$1,'人气变化'!$A$1:$A$438,0),MATCH($A6,'人气变化'!$A$1:$CF$1,0)),NA()) | E6: =IFERROR(INDEX('收藏变化'!$A$1:$CF$438,MATCH($B$1,'收藏变化'!$A$1:$A$438,0),MATCH($A6,'收藏变化'!$A$1:$CF$1,0)),NA()) | F6: =IFERROR(INDEX('点赞变化'!$A$1:$CF$438,MATCH($B$1,'点赞变化'!$A$1:$A$438,0),MATCH($A6,'点赞变化'!$A$1:$CF$1,0)),NA())
A7: 2026-10-09 01:00 | B7: =IFERROR(INDEX('付费榜排名变化'!$A$1:$CF$367,MATCH($B$1,'付费榜排名变化'!$A$1:$A$367,0),MATCH($A7,'付费榜排名变化'!$A$1:$CF$1,0)),NA()) | C7: =IFERROR(INDEX('活跃榜排名变化'!$A$1:$CF$343,MATCH($B$1,'活跃榜排名变化'!$A$1:$A$343,0),MATCH($A7,'活跃榜排名变化'!$A$1:$CF$1,0)),NA()) | D7: =IFERROR(INDEX('人气变化'!$A$1:$CF$438,MATCH($B$1,'人气变化'!$A$1:$A$438,0),MATCH($A7,'人气变化'!$A$1:$CF$1,0)),NA()) | E7: =IFERROR(INDEX('收藏变化'!$A$1:$CF$438,MATCH($B$1,'收藏变化'!$A$1:$A$438,0),MATCH($A7,'收藏变化'!$A$1:$CF$1,0)),NA()) | F7: =IFERROR(INDEX('点赞变化'!$A$1:$CF$438,MATCH($B$1,'点赞变化'!$A$1:$A$438,0),MATCH($A7,'点赞变化'!$A$1:$CF$1,0)),NA())
A8: 2026-10-09 01:15 | B8: =IFERROR(INDEX('付费榜排名变化'!$A$1:$CF$367,MATCH($B$1,'付费榜排名变化'!$A$1:$A$367,0),MATCH($A8,'付费榜排名变化'!$A$1:$CF$1,0)),NA()) | C8: =IFERROR(INDEX('活跃榜排名变化'!$A$1:$CF$343,MATCH($B$1,'活跃榜排名变化'!$A$1:$A$343,0),MATCH($A8,'活跃榜排名变化'!$A$1:$CF$1,0)),NA()) | D8: =IFERROR(INDEX('人气变化'!$A$1:$CF$438,MATCH($B$1,'人气变化'!$A$1:$A$438,0),MATCH($A8,'人气变化'!$A$1:$CF$1,0)),NA()) | E8: =IFERROR(INDEX('收藏变化'!$A$1:$CF$438,MATCH($B$1,'收藏变化'!$A$1:$A$438,0),MATCH($A8,'收藏变化'!$A$1:$CF$1,0)),NA()) | F8: =IFERROR(INDEX('点赞变化'!$A$1:$CF$438,MATCH($B$1,'点赞变化'!$A$1:$A$438,0),MATCH($A8,'点赞变化'!$A$1:$CF$1,0)),NA())
A9: 2026-10-09 01:30 | B9: =IFERROR(INDEX('付费榜排名变化'!$A$1:$CF$367,MATCH($B$1,'付费榜排名变化'!$A$1:$A$367,0),MATCH($A9,'付费榜排名变化'!$A$1:$CF$1,0)),NA()) | C9: =IFERROR(INDEX('活跃榜排名变化'!$A$1:$CF$343,MATCH($B$1,'活跃榜排名变化'!$A$1:$A$343,0),MATCH($A9,'活跃榜排名变化'!$A$1:$CF$1,0)),NA()) | D9: =IFERROR(INDEX('人气变化'!$A$1:$CF$438,MATCH($B$1,'人气变化'!$A$1:$A$438,0),MATCH($A9,'人气变化'!$A$1:$CF$1,0)),NA()) | E9: =IFERROR(INDEX('收藏变化'!$A$1:$CF$438,MATCH($B$1,'收藏变化'!$A$1:$A$438,0),MATCH($A9,'收藏变化'!$A$1:$CF$1,0)),NA()) | F9: =IFERROR(INDEX('点赞变化'!$A$1:$CF$438,MATCH($B$1,'点赞变化'!$A$1:$A$438,0),MATCH($A9,'点赞变化'!$A$1:$CF$1,0)),NA())
A10: 2026-10-09 01:45 | B10: =IFERROR(INDEX('付费榜排名变化'!$A$1:$CF$367,MATCH($B$1,'付费榜排名变化'!$A$1:$A$367,0),MATCH($A10,'付费榜排名变化'!$A$1:$CF$1,0)),NA()) | C10: =IFERROR(INDEX('活跃榜排名变化'!$A$1:$CF$343,MATCH($B$1,'活跃榜排名变化'!$A$1:$A$343,0),MATCH($A10,'活跃榜排名变化'!$A$1:$CF$1,0)),NA()) | D10: =IFERROR(INDEX('人气变化'!$A$1:$CF$438,MATCH($B$1,'人气变化'!$A$1:$A$438,0),MATCH($A10,'人气变化'!$A$1:$CF$1,0)),NA()) | E10: =IFERROR(INDEX('收藏变化'!$A$1:$CF$438,MATCH($B$1,'收藏变化'!$A$1:$A$438,0),MATCH($A10,'收藏变化'!$A$1:$CF$1,0)),NA()) | F10: =IFERROR(INDEX('点赞变化'!$A$1:$CF$438,MATCH($B$1,'点赞变化'!$A$1:$A$438,0),MATCH($A10,'点赞变化'!$A$1:$CF$1,0)),NA())
A11: 2026-10-09 02:00 | B11: =IFERROR(INDEX('付费榜排名变化'!$A$1:$CF$367,MATCH($B$1,'付费榜排名变化'!$A$1:$A$367,0),MATCH($A11,'付费榜排名变化'!$A$1:$CF$1,0)),NA()) | C11: =IFERROR(INDEX('活跃榜排名变化'!$A$1:$CF$343,MATCH($B$1,'活跃榜排名变化'!$A$1:$A$343,0),MATCH($A11,'活跃榜排名变化'!$A$1:$CF$1,0)),NA()) | D11: =IFERROR(INDEX('人气变化'!$A$1:$CF$438,MATCH($B$1,'人气变化'!$A$1:$A$438,0),MATCH($A11,'人气变化'!$A$1:$CF$1,0)),NA()) | E11: =IFERROR(INDEX('收藏变化'!$A$1:$CF$438,MATCH($B$1,'收藏变化'!$A$1:$A$438,0),MATCH($A11,'收藏变化'!$A$1:$CF$1,0)),NA()) | F11: =IFERROR(INDEX('点赞变化'!$A$1:$CF$438,MATCH($B$1,'点赞变化'!$A$1:$A$438,0),MATCH($A11,'点赞变化'!$A$1:$CF$1,0)),NA())
A12: 2026-10-09 02:15 | B12: =IFERROR(INDEX('付费榜排名变化'!$A$1:$CF$367,MATCH($B$1,'付费榜排名变化'!$A$1:$A$367,0),MATCH($A12,'付费榜排名变化'!$A$1:$CF$1,0)),NA()) | C12: =IFERROR(INDEX('活跃榜排名变化'!$A$1:$CF$343,MATCH($B$1,'活跃榜排名变化'!$A$1:$A$343,0),MATCH($A12,'活跃榜排名变化'!$A$1:$CF$1,0)),NA()) | D12: =IFERROR(INDEX('人气变化'!$A$1:$CF$438,MATCH($B$1,'人气变化'!$A$1:$A$438,0),MATCH($A12,'人气变化'!$A$1:$CF$1,0)),NA()) | E12: =IFERROR(INDEX('收藏变化'!$A$1:$CF$438,MATCH($B$1,'收藏变化'!$A$1:$A$438,0),MATCH($A12,'收藏变化'!$A$1:$CF$1,0)),NA()) | F12: =IFERROR(INDEX('点赞变化'!$A$1:$CF$438,MATCH($B$1,'点赞变化'!$A$1:$A$438,0),MATCH($A12,'点赞变化'!$A$1:$CF$1,0)),NA())
A13: 2026-10-09 02:45 | B13: =IFERROR(INDEX('付费榜排名变化'!$A$1:$CF$367,MATCH($B$1,'付费榜排名变化'!$A$1:$A$367,0),MATCH($A13,'付费榜排名变化'!$A$1:$CF$1,0)),NA()) | C13: =IFERROR(INDEX('活跃榜排名变化'!$A$1:$CF$343,MATCH($B$1,'活跃榜排名变化'!$A$1:$A$343,0),MATCH($A13,'活跃榜排名变化'!$A$1:$CF$1,0)),NA()) | D13: =IFERROR(INDEX('人气变化'!$A$1:$CF$438,MATCH($B$1,'人气变化'!$A$1:$A$438,0),MATCH($A13,'人气变化'!$A$1:$CF$1,0)),NA()) | E13: =IFERROR(INDEX('收藏变化'!$A$1:$CF$438,MATCH($B$1,'收藏变化'!$A$1:$A$438,0),MATCH($A13,'收藏变化'!$A$1:$CF$1,0)),NA()) | F13: =IFERROR(INDEX('点赞变化'!$A$1:$CF$438,MATCH($B$1,'点赞变化'!$A$1:$A$438,0),MATCH($A13,'点赞变化'!$A$1:$CF$1,0)),NA())
A14: 2026-10-09 03:00 | B14: =IFERROR(INDEX('付费榜排名变化'!$A$1:$CF$367,MATCH($B$1,'付费榜排名变化'!$A$1:$A$367,0),MATCH($A14,'付费榜排名变化'!$A$1:$CF$1,0)),NA()) | C14: =IFERROR(INDEX('活跃榜排名变化'!$A$1:$CF$343,MATCH($B$1,'活跃榜排名变化'!$A$1:$A$343,0),MATCH($A14,'活跃榜排名变化'!$A$1:$CF$1,0)),NA()) | D14: =IFERROR(INDEX('人气变化'!$A$1:$CF$438,MATCH($B$1,'人气变化'!$A$1:$A$438,0),MATCH($A14,'人气变化'!$A$1:$CF$1,0)),NA()) | E14: =IFERROR(INDEX('收藏变化'!$A$1:$CF$438,MATCH($B$1,'收藏变化'!$A$1:$A$438,0),MATCH($A14,'收藏变化'!$A$1:$CF$1,0)),NA()) | F14: =IFERROR(INDEX('点赞变化'!$A$1:$CF$438,MATCH($B$1,'点赞变化'!$A$1:$A$438,0),MATCH($A14,'点赞变化'!$A$1:$CF$1,0)),NA())
A15: 2026-10-09 03:15 | B15: =IFERROR(INDEX('付费榜排名变化'!$A$1:$CF$367,MATCH($B$1,'付费榜排名变化'!$A$1:$A$367,0),MATCH($A15,'付费榜排名变化'!$A$1:$CF$1,0)),NA()) | C15: =IFERROR(INDEX('活跃榜排名变化'!$A$1:$CF$343,MATCH($B$1,'活跃榜排名变化'!$A$1:$A$343,0),MATCH($A15,'活跃榜排名变化'!$A$1:$CF$1,0)),NA()) | D15: =IFERROR(INDEX('人气变化'!$A$1:$CF$438,MATCH($B$1,'人气变化'!$A$1:$A$438,0),MATCH($A15,'人气变化'!$A$1:$CF$1,0)),NA()) | E15: =IFERROR(INDEX('收藏变化'!$A$1:$CF$438,MATCH($B$1,'收藏变化'!$A$1:$A$438,0),MATCH($A15,'收藏变化'!$A$1:$CF$1,0)),NA()) | F15: =IFERROR(INDEX('点赞变化'!$A$1:$CF$438,MATCH($B$1,'点赞变化'!$A$1:$A$438,0),MATCH($A15,'点赞变化'!$A$1:$CF$1,0)),NA())
A16: 2026-10-09 03:30 | B16: =IFERROR(INDEX('付费榜排名变化'!$A$1:$CF$367,MATCH($B$1,'付费榜排名变化'!$A$1:$A$367,0),MATCH($A16,'付费榜排名变化'!$A$1:$CF$1,0)),NA()) | C16: =IFERROR(INDEX('活跃榜排名变化'!$A$1:$CF$343,MATCH($B$1,'活跃榜排名变化'!$A$1:$A$343,0),MATCH($A16,'活跃榜排名变化'!$A$1:$CF$1,0)),NA()) | D16: =IFERROR(INDEX('人气变化'!$A$1:$CF$438,MATCH($B$1,'人气变化'!$A$1:$A$438,0),MATCH($A16,'人气变化'!$A$1:$CF$1,0)),NA()) | E16: =IFERROR(INDEX('收藏变化'!$A$1:$CF$438,MATCH($B$1,'收藏变化'!$A$1:$A$438,0),MATCH($A16,'收藏变化'!$A$1:$CF$1,0)),NA()) | F16: =IFERROR(INDEX('点赞变化'!$A$1:$CF$438,MATCH($B$1,'点赞变化'!$A$1:$A$438,0),MATCH($A16,'点赞变化'!$A$1:$CF$1,0)),NA())
... A87: 2026-10-10 00:00 | B87: =IFERROR(INDEX('付费榜排名变化'!$A$1:$CF$367,MATCH($B$1,'付费榜排名变化'!$A$1:$A$367,0),MATCH($A87,'付费榜排名变化'!$A$1:$CF$1,0)),NA()) | C87: =IFERROR(INDEX('活跃榜排名变化'!$A$1:$CF$343,MATCH($B$1,'活跃榜排名变化'!$A$1:$A$343,0),MATCH($A87,'活跃榜排名变化'!$A$1:$CF$1,0)),NA()) | D87: =IFERROR(INDEX('人气变化'!$A$1:$CF$438,MATCH($B$1,'人气变化'!$A$1:$A$438,0),MATCH($A87,'人气变化'!$A$1:$CF$1,0)),NA()) | E87: =IFERROR(INDEX('收藏变化'!$A$1:$CF$438,MATCH($B$1,'收藏变化'!$A$1:$A$438,0),MATCH($A87,'收藏变化'!$A$1:$CF$1,0)),NA()) | F87: =IFERROR(INDEX('点赞变化'!$A$1:$CF$438,MATCH($B$1,'点赞变化'!$A$1:$A$438,0),MATCH($A87,'点赞变化'!$A$1:$CF$1,0)),NA())

Sheet 付费榜排名变化
A1: 作品名 | B1: 2026-10-09 00:15 | C1: 2026-10-09 00:45 | D1: 2026-10-09 01:00 | E1: 2026-10-09 01:15 | F1: 2026-10-09 01:30 | G1: 2026-10-09 01:45 | H1: 2026-10-09 02:00 | I1: 2026-10-09 02:15 | J1: 2026-10-09 02:45 | K1: 2026-10-09 03:00 | L1: 2026-10-09 03:15 | M1: 2026-10-09 03:30 | N1: 2026-10-09 03:45 | O1: 2026-10-09 04:00 | P1: 2026-10-09 04:15 | Q1: 2026-10-09 04:45 | R1: 2026-10-09 05:00 | S1: 2026-10-09 05:15 | T1: 2026-10-09 05:30 | U1: 2026-10-09 05:45 | V1: 2026-10-09 06:00 | W1: 2026-10-09 06:15 | X1: 2026-10-09 06:30 | Y1: 2026-10-09 06:45 | Z1: 2026-10-09 07:00 | AA1: 2026-10-09 07:15 | AB1: 2026-10-09 07:30 | AC1: 2026-10-09 07:45 | AD1: 2026-10-09 08:00 | AE1: 2026-10-09 08:15 | AF1: 2026-10-09 08:45 | AG1: 2026-10-09 09:15 | AH1: 2026-10-09 09:30 | AI1: 2026-10-09 09:45 | AJ1: 2026-10-09 10:00 | AK1: 2026-10-09 10:15 | AL1: 2026-10-09 10:30 | AM1: 2026-10-09 10:45 | AN1: 2026-10-09 11:00 | AO1: 2026-10-09 11:15 | AP1: 2026-10-09 11:30 | AQ1: 2026-10-09 11:45 | AR1: 2026-10-09 12:00 | AS1: 2026-10-09 12:30 | AT1: 2026-10-09 12:45 | AU1: 2026-10-09 13:00 | AV1: 2026-10-09 13:15 | AW1: 2026-10-09 13:30 | AX1: 2026-10-09 13:45 | AY1: 2026-10-09 14:00 | AZ1: 2026-10-09 14:30 | BA1: 2026-10-09 14:45 | BB1: 2026-10-09 15:15 | BC1: 2026-10-09 15:30 | BD1: 2026-10-09 15:45 | BE1: 2026-10-09 16:00 | BF1: 2026-10-09 16:15 | BG1: 2026-10-09 16:45 | BH1: 2026-10-09 17:00 | BI1: 2026-10-09 17:15 | BJ1: 2026-10-09 17:30 | BK1: 2026-10-09 17:45 | BL1: 2026-10-09 18:00 | BM1: 2026-10-09 18:15 | BN1: 2026-10-09 18:45 | BO1: 2026-10-09 19:00 | BP1: 2026-10-09 19:15 | BQ1: 2026-10-09 19:30 | BR1: 2026-10-09 19:45 | BS1: 2026-10-09 20:00 | BT1: 2026-10-09 20:15 | BU1: 2026-10-09 20:30 | BV1: 2026-10-09 21:00 | BW1: 2026-10-09 21:15 | BX1: 2026-10-09 21:30 | BY1: 2026-10-09 22:00 | BZ1: 2026-10-09 22:15 | CA1: 2026-10-09 22:30 | CB1: 2026-10-09 22:45 | CC1: 2026-10-09 23:15 | CD1: 2026-10-09 23:30 | CE1: 2026-10-09 23:45 | CF1: 2026-10-10 00:00
A2: 师途 | B2: 1 | C2: 1 | D2: 1 | E2: 1 | F2: 1 | G2: 1 | H2: 1 | I2: 1 | J2: 1 | K2: 1 | L2: 1 | M2: 1 | N2: 1 | O2: 1 | P2: 1 | Q2: 1 | R2: 1 | S2: 1 | T2: 1 | U2: 1 | V2: 1 | W2: 1 | X2: 1 | Y2: 1 | Z2: 1 | AA2: 1 | AB2: 1 | AC2: 1 | AD2: 1 | AE2: 1 | AF2: 1 | AG2: 1 | AH2: 1 | AI2: 1 | AJ2: 1 | AK2: 1 | AL2: 1 | AM2: 1 | AN2: 1 | AO2: 1 | AP2: 1 | AQ2: 1 | AR2: 1 | AS2: 1 | AT2: 1 | AU2: 1 | AV2: 1 | AW2: 1 | AX2: 1 | AY2: 1 | AZ2: 1 | BA2: 1 | BB2: 1 | BC2: 1 | BD2: 1 | BE2: 1 | BF2: 1 | BG2: 1 | BH2: 1 | BI2: 1 | BJ2: 1 | BK2: 1 | BL2: 1 | BM2: 1 | BN2: 1 | BO2: 1 | BP2: 1 | BQ2: 1 | BR2: 1 | BS2: 1 | BT2: 1 | BU2: 1 | BV2: 1 | BW2: 1 | BX2: 1 | BY2: 1 | BZ2: 1 | CA2: 1 | CB2: 1 | CC2: 1 | CD2: 1 | CE2: 1 | CF2: 1
A3: 临帝阙 | B3: 5 | C3: 11 | D3: 12 | E3: 8 | F3: 7 | G3: 8 | H3: 6 | I3: 4 | J3: 3 | K3: 4 | L3: 2 | M3: 3 | N3: 2 | O3: 2 | P3: 3 | Q3: 3 | R3: 2 | S3: 3 | T3: 3 | U3: 3 | V3: 3 | W3: 2 | X3: 2 | Y3: 3 | Z3: 3 | AA3: 3 | AB3: 3 | AC3: 3 | AD3: 3 | AE3: 3 | AF3: 4 | AG3: 3 | AH3: 3 | AI3: 3 | AJ3: 3 | AK3: 3 | AL3: 3 | AM3: 3 | AN3: 3 | AO3: 3 | AP3: 3 | AQ3: 3 | AR3: 2 | AS3: 2 | AT3: 2 | AU3: 2 | AV3: 2 | AW3: 2 | AX3: 2 | AY3: 2 | AZ3: 2 | BA3: 3 | BB3: 3 | BC3: 3 | BD3: 3 | BE3: 4 | BF3: 3 | BG3: 3 | BH3: 2 | BI3: 2 | BJ3: 2 | BK3: 3 | BL3: 3 | BM3: 3 | BN3: 3 | BO3: 3 | BP3: 3 | BQ3: 3 | BR3: 2 | BS3: 2 | BT3: 2 | BU3: 2 | BV3: 2 | BW3: 2 | BX3: 2 | BY3: 2 | BZ3: 2 | CA3: 2 | CB3: 2 | CC3: 2 | CD3: 2 | CE3: 2 | CF3: 2
A4: 三界衔 | B4: 4 | C4: 3 | D4: 3 | E4: 3 | F4: 3 | G4: 3 | H4: 2 | I4: 2 | J4: 4 | K4: 2 | L4: 3 | M4: 2 | N4: 3 | O4: 3 | P4: 2 | Q4: 2 | R4: 3 | S4: 2 | T4: 2 | U4: 2 | V4: 2 | W4: 3 | X4: 3 | Y4: 2 | Z4: 2 | AA4: 2 | AB4: 2 | AC4: 2 | AD4: 2 | AE4: 2 | AF4: 2 | AG4: 2 | AH4: 2 | AI4: 2 | AJ4: 2 | AK4: 2 | AL4: 2 | AM4: 2 | AN4: 2 | AO4: 2 | AP4: 2 | AQ4: 2 | AR4: 3 | AS4: 3 | AT4: 3 | AU4: 3 | AV4: 3 | AW4: 3 | AX4: 3 | AY4: 3 | AZ4: 4 | BA4: 5 | BB4: 4 | BC4: 4 | BD4: 4 | BE4: 3 | BF4: 4 | BG4: 4 | BH4: 4 | BI4: 4 | BJ4: 4 | BK4: 4 | BL4: 4 | BM4: 4 | BN4: 4 | BO4: 4 | BP4: 4 | BQ4: 4 | BR4: 4 | BS4: 4 | BT4: 4 | BU4: 4 | BV4: 4 | BW4: 4 | BX4: 4 | BY4: 4 | BZ4: 3 | CA4: 3 | CB4: 3 | CC4: 3 | CD4: 3 | CE4: 3 | CF4: 3
A5: 江山千秋万代 | B5: 3 | C5: 14 | D5: 10 | E5: 10 | F5: 5 | G5: 7 | H5: 8 | I5: 9 | J5: 8 | K5: 9 | L5: 9 | M5: 9 | N5: 10 | O5: 10 | P5: 10 | Q5: 9 | R5: 9 | S5: 9 | T5: 9 | U5: 9 | V5: 9 | W5: 9 | X5: 9 | Y5: 9 | Z5: 9 | AA5: 9 | AB5: 9 | AC5: 9 | AD5: 9 | AE5: 9 | AF5: 9 | AG5: 9 | AH5: 8 | AI5: 8 | AJ5: 8 | AK5: 8 | AL5: 8 | AM5: 8 | AN5: 8 | AO5: 8 | AP5: 8 | AQ5: 8 | AR5: 8 | AS5: 5 | AT5: 4 | AU5: 4 | AV5: 5 | AW5: 4 | AX5: 4 | AY5: 4 | AZ5: 3 | BA5: 2 | BB5: 2 | BC5: 2 | BD5: 2 | BE5: 2 | BF5: 2 | BG5: 2 | BH5: 3 | BI5: 3 | BJ5: 3 | BK5: 2 | BL5: 2 | BM5: 2 | BN5: 2 | BO5: 2 | BP5: 2 | BQ5: 2 | BR5: 3 | BS5: 3 | BT5: 3 | BU5: 3 | BV5: 3 | BW5: 3 | BX5: 3 | BY5: 3 | BZ5: 4 | CA5: 4 | CB5: 4 | CC5: 4 | CD5: 4 | CE5: 4 | CF5: 4
A6: 星期天不上头条 | B6: 11 | C6: 12 | D6: 5 | E6: 9 | F6: 9 | G6: 10 | H6: 10 | I6: 10 | J6: 7 | K6: 7 | L6: 8 | M6: 8 | N6: 8 | O6: 8 | P6: 8 | Q6: 8 | R6: 8 | S6: 8 | T6: 8 | U6: 8 | V6: 7 | W6: 7 | X6: 7 | Y6: 7 | Z6: 7 | AA6: 5 | AB6: 4 | AC6: 5 | AD6: 4 | AE6: 4 | AF6: 3 | AG6: 4 | AH6: 4 | AI6: 4 | AJ6: 4 | AK6: 4 | AL6: 4 | AM6: 5 | AN6: 5 | AO6: 5 | AP6: 4 | AQ6: 4 | AR6: 4 | AS6: 4 | AT6: 5 | AU6: 5 | AV6: 4 | AW6: 5 | AX6: 5 | AY6: 5 | AZ6: 5 | BA6: 4 | BB6: 5 | BC6: 5 | BD6: 5 | BE6: 5 | BF6: 5 | BG6: 5 | BH6: 5 | BI6: 5 | BJ6: 5 | BK6: 5 | BL6: 5 | BM6: 5 | BN6: 5 | BO6: 5 | BP6: 5 | BQ6: 5 | BR6: 5 | BS6: 5 | BT6: 5 | BU6: 5 | BV6: 5 | BW6: 5 | BX6: 5 | BY6: 5 | BZ6: 5 | CA6: 5 | CB6: 5 | CC6: 5 | CD6: 5 | CE6: 5 | CF6: 5
A7: 勿扰修仙中 | B7: 10 | C7: 4 | D7: 4 | E7: 6 | F7: 8 | G7: 4 | H7: 4 | I7: 6 | J7: 5 | K7: 5 | L7: 5 | M7: 5 | N7: 5 | O7: 6 | P7: 5 | Q7: 6 | R7: 6 | S7: 6 | T7: 6 | U7: 7 | V7: 8 | W7: 8 | X7: 8 | Y7: 8 | Z7: 8 | AA7: 8 | AB7: 7 | AC7: 7 | AD7: 7 | AE7: 8 | AF7: 7 | AG7: 8 | AH7: 9 | AI7: 9 | AJ7: 9 | AK7: 9 | AL7: 9 | AM7: 9 | AN7: 9 | AO7: 9 | AP7: 9 | AQ7: 9 | AR7: 9 | AS7: 9 | AT7: 9 | AU7: 9 | AV7: 9 | AW7: 9 | AX7: 9 | AY7: 9 | AZ7: 9 | BA7: 9 | BB7: 8 | BC7: 8 | BD7: 8 | BE7: 8 | BF7: 7 | BG7: 7 | BH7: 7 | BI7: 7 | BJ7: 7 | BK7: 7 | BL7: 7 | BM7: 7 | BN7: 7 | BO7: 7 | BP7: 7 | BQ7: 7 | BR7: 7 | BS7: 7 | BT7: 6 | BU7: 6 | BV7: 6 | BW7: 6 | BX7: 6 | BY7: 6 | BZ7: 6 | CA7: 6 | CB7: 6 | CC7: 6 | CD7: 6 | CE7: 6 | CF7: 6
A8: 怪我过分美丽 | B8: 8 | C8: 5 | D8: 7 | E8: 5 | F8: 6 | G8: 5 | H8: 7 | I8: 7 | J8: 6 | K8: 6 | L8: 6 | M8: 6 | N8: 6 | O8: 5 | P8: 6 | Q8: 7 | R8: 7 | S8: 7 | T8: 7 | U8: 6 | V8: 6 | W8: 6 | X8: 6 | Y8: 6 | Z8: 6 | AA8: 7 | AB8: 8 | AC8: 8 | AD8: 8 | AE8: 7 | AF8: 8 | AG8: 6 | AH8: 5 | AI8: 6 | AJ8: 6 | AK8: 6 | AL8: 6 | AM8: 4 | AN8: 6 | AO8: 6 | AP8: 6 | AQ8: 7 | AR8: 7 | AS8: 7 | AT8: 7 | AU8: 7 | AV8: 6 | AW8: 6 | AX8: 7 | AY8: 7 | AZ8: 7 | BA8: 7 | BB8: 7 | BC8: 6 | BD8: 6 | BE8: 6 | BF8: 6 | BG8: 6 | BH8: 6 | BI8: 6 | BJ8: 6 | BK8: 6 | BL8: 6 | BM8: 6 | BN8: 6 | BO8: 6 | BP8: 6 | BQ8: 6 | BR8: 6 | BS8: 6 | BT8: 7 | BU8: 7 | BV8: 7 | BW8: 7 | BX8: 7 | BY8: 7 | BZ8: 7 | CA8: 7 | CB8: 7 | CC8: 7 | CD8: 7 | CE8: 7 | CF8: 7
A9: 成为团播TOP之后 | B9: 7 | C9: 7 | D9: 8 | E9: 7 | F9: 10 | G9: 9 | H9: 9 | I9: 8 | J9: 10 | K9: 10 | L9: 10 | M9: 10 | N9: 9 | O9: 9 | P9: 9 | Q9: 10 | R9: 10 | S9: 10 | T9: 10 | U9: 10 | V9: 10 | W9: 10 | X9: 10 | Y9: 10 | Z9: 10 | AA9: 10 | AB9: 10 | AC9: 10 | AD9: 10 | AE9: 10 | AF9: 11 | AG9: 10 | AH9: 10 | AI9: 10 | AJ9: 10 | AK9: 10 | AL9: 10 | AM9: 10 | AN9: 10 | AO9: 10 | AP9: 10 | AQ9: 10 | AR9: 10 | AS9: 10 | AT9: 10 | AU9: 10 | AV9: 10 | AW9: 10 | AX9: 10 | AY9: 10 | AZ9: 10 | BA9: 10 | BB9: 10 | BC9: 10 | BD9: 10 | BE9: 10 | BF9: 10 | BG9: 10 | BH9: 10 | BI9: 10 | BJ9: 10 | BK9: 10 | BL9: 10 | BM9: 9 | BN9: 9 | BO9: 9 | BP9: 9 | BQ9: 9 | BR9: 9 | BS9: 9 | BT9: 9 | BU9: 9 | BV9: 9 | BW9: 9 | BX9: 9 | BY9: 8 | BZ9: 8 | CA9: 8 | CB9: 8 | CC9: 8 | CD9: 8 | CE9: 8 | CF9: 8
A10: 风华临安 | B10: 2 | C10: 2 | D10: 2 | E10: 4 | F10: 2 | G10: 2 | H10: 3 | I10: 3 | J10: 2 | K10: 3 | L10: 4 | M10: 4 | N10: 4 | O10: 4 | P10: 4 | Q10: 5 | R10: 5 | S10: 5 | T10: 5 | U10: 5 | V10: 5 | W10: 5 | X10: 5 | Y10: 5 | Z10: 5 | AA10: 6 | AB10: 6 | AC10: 6 | AD10: 6 | AE10: 6 | AF10: 5 | AG10: 7 | AH10: 7 | AI10: 7 | AJ10: 7 | AK10: 7 | AL10: 7 | AM10: 7 | AN10: 4 | AO10: 4 | AP10: 5 | AQ10: 5 | AR10: 5 | AS10: 6 | AT10: 6 | AU10: 6 | AV10: 7 | AW10: 7 | AX10: 6 | AY10: 6 | AZ10: 6 | BA10: 6 | BB10: 6 | BC10: 7 | BD10: 7 | BE10: 7 | BF10: 8 | BG10: 8 | BH10: 8 | BI10: 8 | BJ10: 8 | BK10: 8 | BL10: 8 | BM10: 8 | BN10: 8 | BO10: 8 | BP10: 8 | BQ10: 8 | BR10: 8 | BS10: 8 | BT10: 8 | BU10: 8 | BV10: 8 | BW10: 8 | BX10: 8 | BY10: 9 | BZ10: 9 | CA10: 9 | CB10: 9 | CC10: 9 | CD10: 9 | CE10: 9 | CF10: 9
A11: 宫妃 | B11: 9 | C11: 9 | D11: 9 | E11: 12 | F11: 12 | G11: 13 | H11: 13 | I11: 12 | J11: 12 | K11: 12 | L11: 11 | M11: 11 | N11: 11 | O11: 11 | P11: 11 | Q11: 11 | R11: 11 | S11: 11 | T11: 11 | U11: 11 | V11: 11 | W11: 11 | X11: 11 | Y11: 11 | Z11: 11 | AA11: 11 | AB11: 11 | AC11: 11 | AD11: 11 | AE11: 11 | AF11: 12 | AG11: 12 | AH11: 12 | AI11: 12 | AJ11: 11 | AK11: 11 | AL11: 11 | AM11: 11 | AN11: 11 | AO11: 11 | AP11: 11 | AQ11: 11 | AR11: 11 | AS11: 11 | AT11: 11 | AU11: 11 | AV11: 11 | AW11: 11 | AX11: 11 | AY11: 11 | AZ11: 11 | BA11: 11 | BB11: 11 | BC11: 11 | BD11: 11 | BE11: 11 | BF11: 11 | BG11: 11 | BH11: 11 | BI11: 11 | BJ11: 11 | BK11: 11 | BL11: 11 | BM11: 11 | BN11: 11 | BO11: 11 | BP11: 11 | BQ11: 11 | BR11: 11 | BS11: 11 | BT11: 11 | BU11: 11 | BV11: 11 | BW11: 11 | BX11: 10 | BY11: 10 | BZ11: 10 | CA11: 10 | CB11: 10 | CC11: 10 | CD11: 10 | CE11: 10 | CF11: 10
A12: 仙路漫漫 | B12: 6 | C12: 6 | D12: 6 | E12: 2 | F12: 4 | G12: 6 | H12: 5 | I12: 5 | J12: 9 | K12: 8 | L12: 7 | M12: 7 | N12: 7 | O12: 7 | P12: 7 | Q12: 4 | R12: 4 | S12: 4 | T12: 4 | U12: 4 | V12: 4 | W12: 4 | X12: 4 | Y12: 4 | Z12: 4 | AA12: 4 | AB12: 5 | AC12: 4 | AD12: 5 | AE12: 5 | AF12: 6 | AG12: 5 | AH12: 6 | AI12: 5 | AJ12: 5 | AK12: 5 | AL12: 5 | AM12: 6 | AN12: 7 | AO12: 7 | AP12: 7 | AQ12: 6 | AR12: 6 | AS12: 8 | AT12: 8 | AU12: 8 | AV12: 8 | AW12: 8 | AX12: 8 | AY12: 8 | AZ12: 8 | BA12: 8 | BB12: 9 | BC12: 9 | BD12: 9 | BE12: 9 | BF12: 9 | BG12: 9 | BH12: 9 | BI12: 9 | BJ12: 9 | BK12: 9 | BL12: 9 | BM12: 10 | BN12: 10 | BO12: 10 | BP12: 10 | BQ12: 10 | BR12: 10 | BS12: 10 | BT12: 10 | BU12: 10 | BV12: 10 | BW12: 10 | BX12: 11 | BY12: 11 | BZ12: 11 | CA12: 11 | CB12: 11 | CC12: 11 | CD12: 11 | CE12: 11 | CF12: 11
A13: AMNESIA 失忆症 | B13: 14 | C13: 8 | D13: 11 | E13: 11 | F13: 11 | G13: 11 | H13: 11 | I13: 11 | J13: 11 | K13: 11 | L13: 12 | M13: 12 | N13: 12 | O13: 12 | P13: 12 | Q13: 12 | R13: 12 | S13: 12 | T13: 12 | U13: 12 | V13: 12 | W13: 12 | X13: 13 | Y13: 12 | Z13: 12 | AA13: 12 | AB13: 12 | AC13: 12 | AD13: 13 | AE13: 13 | AF13: 13 | AG13: 13 | AH13: 13 | AI13: 14 | AJ13: 14 | AK13: 14 | AL13: 14 | AM13: 14 | AN13: 14 | AO13: 14 | AP13: 13 | AQ13: 13 | AR13: 13 | AS13: 13 | AT13: 12 | AU13: 12 | AV13: 12 | AW13: 12 | AX13: 12 | AY13: 13 | AZ13: 12 | BA13: 12 | BB13: 12 | BC13: 12 | BD13: 12 | BE13: 12 | BF13: 12 | BG13: 12 | BH13: 12 | BI13: 12 | BJ13: 12 | BK13: 12 | BL13: 12 | BM13: 12 | BN13: 12 | BO13: 12 | BP13: 12 | BQ13: 12 | BR13: 12 | BS13: 12 | BT13: 12 | BU13: 12 | BV13: 12 | BW13: 12 | BX13: 12 | BY13: 12 | BZ13: 12 | CA13: 12 | CB13: 12 | CC13: 12 | CD13: 12 | CE13: 12 | CF13: 12
... A32: 并不是一般穿游 | B32: 22 | C32: 15 | D32: 18 | E32: 21 | F32: 22 | G32: 16 | H32: 16 | I32: 17 | J32: 19 | K32: 19 | L32: 19 | M32: 18 | N32: 18 | O32: 18 | P32: 18 | Q32: 19 | R32: 19 | S32: 19 | T32: 19 | U32: 20 | V32: 20 | W32: 21 | X32: 21 | Y32: 21 | Z32: 22 | AA32: 23 | AB32: 23 | AC32: 23 | AD32: 23 | AE32: 23 | AF32: 21 | AG32: 21 | AH32: 22 | AI32: 23 | AJ32: 23 | AK32: 23 | AL32: 23 | AM32: 24 | AN32: 24 | AO32: 24 | AP32: 25 | AQ32: 26 | AR32: 26 | AS32: 26 | AT32: 26 | AU32: 27 | AV32: 28 | AW32: 28 | AX32: 26 | AY32: 26 | AZ32: 25 | BA32: 25 | BB32: 28 | BC32: 29 | BD32: 29 | BE32: 31 | BF32: 30 | BG32: 30 | BH32: 31 | BI32: 32 | BJ32: 33 | BK32: 32 | BL32: 32 | BM32: 32 | BN32: 32 | BO32: 32 | BP32: 33 | BQ32: 32 | BR32: 33 | BS32: 30 | BT32: 30 | BU32: 30 | BV32: 30 | BW32: 31 | BX32: 31 | BY32: 32 | BZ32: 32 | CA32: 32 | CB32: 31 | CC32: 31 | CD32: 33 | CE32: 33 | CF32: 31
A33: 末日之基地建设 | B33: 25 | D33: 41 | E33: 39 | F33: 37 | G33: 40 | H33: 48 | I33: 44 | J33: 51 | K33: 48 | L33: 49 | M33: 49 | N33: 53 | O33: 55 | P33: 56 | Q33: 59 | R33: 62 | S33: 62 | T33: 62 | U33: 62 | V33: 63 | W33: 63 | X33: 63 | Y33: 66 | Z33: 67 | AA33: 67 | AB33: 68 | AC33: 68 | AD33: 66 | AE33: 68 | AF33: 68 | AG33: 70 | AH33: 71 | AI33: 74 | AJ33: 74 | AK33: 76 | AL33: 76 | AM33: 78 | AN33: 81 | AO33: 81 | AP33: 82 | AQ33: 84 | AR33: 88 | AS33: 89 | AT33: 92 | AU33: 95 | AV33: 98 | AW33: 99 | AX33: 101 | AY33: 108 | AZ33: 120 | BA33: 122 | BB33: 126 | BC33: 131 | BD33: 134 | BE33: 121 | BF33: 115 | BG33: 121 | BH33: 123 | BI33: 61 | BJ33: 62 | BK33: 62 | BL33: 63 | BM33: 64 | BN33: 62 | BO33: 62 | BP33: 62 | BQ33: 63 | BR33: 64 | BS33: 65 | BT33: 66 | BU33: 66 | BV33: 64 | BW33: 66 | BX33: 62 | BY33: 28 | BZ33: 28 | CA33: 28 | CB33: 28 | CC33: 30 | CD33: 30 | CE33: 31 | CF33: 32
A34: 妄情债 | B34: 18 | C34: 32 | D34: 30 | E34: 27 | F34: 26 | G34: 23 | H34: 19 | I34: 22 | J34: 23 | K34: 21 | L34: 21 | M34: 21 | N34: 21 | O34: 23 | P34: 21 | Q34: 23 | R34: 25 | S34: 28 | T34: 28 | U34: 28 | V34: 27 | W34: 28 | X34: 28 | Y34: 29 | Z34: 29 | AA34: 29 | AB34: 29 | AC34: 30 | AD34: 30 | AE34: 30 | AF34: 30 | AG34: 31 | AH34: 30 | AI34: 30 | AJ34: 27 | AK34: 28 | AL34: 29 | AM34: 28 | AN34: 28 | AO34: 28 | AP34: 27 | AQ34: 28 | AR34: 28 | AS34: 29 | AT34: 29 | AU34: 28 | AV34: 29 | AW34: 29 | AX34: 29 | AY34: 28 | AZ34: 28 | BA34: 26 | BB34: 26 | BC34: 30 | BD34: 28 | BE34: 28 | BF34: 29 | BG34: 31 | BH34: 30 | BI34: 28 | BJ34: 28 | BK34: 26 | BL34: 26 | BM34: 27 | BN34: 28 | BO34: 28 | BP34: 28 | BQ34: 28 | BR34: 28 | BS34: 28 | BT34: 28 | BU34: 28 | BV34: 29 | BW34: 30 | BX34: 30 | BY34: 31 | BZ34: 31 | CA34: 31 | CB34: 32 | CC34: 33 | CD34: 31 | CE34: 32 | CF34: 33
A35: 替兄嫁了公主后 | B35: 35 | C35: 28 | D35: 17 | E35: 17 | F35: 17 | G35: 18 | H35: 17 | I35: 19 | J35: 21 | K35: 22 | L35: 22 | M35: 24 | N35: 25 | O35: 26 | P35: 22 | Q35: 22 | R35: 22 | S35: 24 | T35: 25 | U35: 26 | V35: 28 | W35: 29 | X35: 29 | Y35: 30 | Z35: 30 | AA35: 30 | AB35: 30 | AC35: 28 | AD35: 27 | AE35: 27 | AF35: 27 | AG35: 27 | AH35: 28 | AI35: 27 | AJ35: 28 | AK35: 30 | AL35: 30 | AM35: 30 | AN35: 31 | AO35: 30 | AP35: 29 | AQ35: 30 | AR35: 30 | AS35: 30 | AT35: 30 | AU35: 31 | AV35: 31 | AW35: 33 | AX35: 32 | AY35: 31 | AZ35: 32 | BA35: 36 | BB35: 39 | BC35: 41 | BD35: 42 | BE35: 39 | BF35: 39 | BG35: 37 | BH35: 39 | BI35: 41 | BJ35: 42 | BK35: 45 | BL35: 42 | BM35: 43 | BN35: 44 | BO35: 45 | BP35: 44 | BQ35: 44 | BR35: 40 | BS35: 42 | BT35: 42 | BU35: 40 | BV35: 37 | BW35: 36 | BX35: 35 | BY35: 36 | BZ35: 36 | CA35: 36 | CB35: 36 | CC35: 34 | CD35: 34 | CE35: 34 | CF35: 34
A36: 表小姐成长计划 | B36: 132 | C36: 73 | D36: 57 | E36: 52 | F36: 43 | G36: 34 | H36: 34 | I36: 35 | J36: 42 | K36: 39 | L36: 43 | M36: 42 | N36: 45 | O36: 46 | P36: 41 | Q36: 37 | R36: 26 | S36: 20 | T36: 20 | U36: 21 | V36: 22 | W36: 23 | X36: 23 | Y36: 23 | Z36: 25 | AA36: 24 | AB36: 24 | AC36: 24 | AD36: 24 | AE36: 24 | AF36: 25 | AG36: 25 | AH36: 26 | AI36: 25 | AJ36: 25 | AK36: 25 | AL36: 26 | AM36: 27 | AN36: 29 | AO36: 29 | AP36: 30 | AQ36: 31 | AR36: 31 | AS36: 33 | AT36: 35 | AU36: 35 | AV36: 36 | AW36: 38 | AX36: 40 | AY36: 40 | AZ36: 36 | BA36: 35 | BB36: 36 | BC36: 37 | BD36: 36 | BE36: 37 | BF36: 36 | BG36: 36 | BH36: 36 | BI36: 38 | BJ36: 38 | BK36: 42 | BL36: 45 | BM36: 46 | BN36: 47 | BO36: 44 | BP36: 42 | BQ36: 42 | BR36: 43 | BS36: 40 | BT36: 40 | BU36: 42 | BV36: 41 | BW36: 40 | BX36: 39 | BY36: 41 | BZ36: 40 | CA36: 40 | CB36: 37 | CC36: 37 | CD36: 36 | CE36: 35 | CF36: 35
A37: 明月照千山 | B37: 33 | C37: 35 | D37: 35 | E37: 41 | F37: 44 | G37: 48 | H37: 54 | I37: 59 | J37: 64 | K37: 63 | L37: 61 | M37: 55 | N37: 58 | O37: 58 | P37: 59 | Q37: 55 | R37: 52 | S37: 52 | T37: 54 | U37: 54 | V37: 52 | W37: 53 | X37: 52 | Y37: 52 | Z37: 52 | AA37: 53 | AB37: 53 | AC37: 51 | AD37: 51 | AE37: 51 | AF37: 50 | AG37: 49 | AH37: 48 | AI37: 49 | AJ37: 50 | AK37: 50 | AL37: 49 | AM37: 48 | AN37: 43 | AO37: 40 | AP37: 35 | AQ37: 37 | AR37: 39 | AS37: 35 | AT37: 33 | AU37: 32 | AV37: 34 | AW37: 34 | AX37: 34 | AY37: 35 | AZ37: 35 | BA37: 41 | BB37: 41 | BC37: 43 | BD37: 41 | BE37: 42 | BF37: 42 | BG37: 43 | BH37: 43 | BI37: 44 | BJ37: 45 | BK37: 47 | BL37: 46 | BM37: 47 | BN37: 46 | BO37: 47 | BP37: 46 | BQ37: 46 | BR37: 46 | BS37: 47 | BT37: 47 | BU37: 48 | BV37: 45 | BW37: 45 | BX37: 45 | BY37: 46 | BZ37: 45 | CA37: 43 | CB37: 41 | CC37: 42 | CD37: 42 | CE37: 37 | CF37: 36
A38: 古代富婆模拟器 | B38: 59 | C38: 101 | D38: 40 | E38: 36 | F38: 38 | G38: 35 | H38: 40 | I38: 41 | J38: 41 | K38: 43 | L38: 40 | M38: 40 | N38: 44 | O38: 45 | P38: 48 | Q38: 44 | R38: 44 | S38: 43 | T38: 43 | U38: 41 | V38: 41 | W38: 42 | X38: 42 | Y38: 43 | Z38: 44 | AA38: 45 | AB38: 45 | AC38: 45 | AD38: 45 | AE38: 45 | AF38: 47 | AG38: 45 | AH38: 46 | AI38: 48 | AJ38: 49 | AK38: 49 | AL38: 51 | AM38: 52 | AN38: 52 | AO38: 55 | AP38: 46 | AQ38: 46 | AR38: 48 | AS38: 52 | AT38: 51 | AU38: 47 | AV38: 47 | AW38: 47 | AX38: 51 | AY38: 48 | AZ38: 52 | BA38: 51 | BB38: 52 | BC38: 53 | BD38: 53 | BE38: 54 | BF38: 55 | BG38: 54 | BH38: 55 | BI38: 56 | BJ38: 56 | BK38: 55 | BL38: 56 | BM38: 57 | BN38: 59 | BO38: 60 | BP38: 61 | BQ38: 61 | BR38: 62 | BS38: 62 | BT38: 62 | BU38: 60 | BV38: 56 | BW38: 55 | BX38: 55 | BY38: 51 | BZ38: 52 | CA38: 45 | CB38: 46 | CC38: 39 | CD38: 40 | CE38: 36 | CF38: 37
A39: 开播吧！电视台 | B39: 89 | C39: 189 | D39: 157 | E39: 186 | H39: 129 | I39: 144 | J39: 109 | K39: 88 | L39: 91 | M39: 88 | N39: 92 | O39: 95 | P39: 98 | Q39: 102 | R39: 103 | S39: 103 | T39: 103 | U39: 104 | V39: 106 | W39: 107 | X39: 110 | Y39: 111 | Z39: 111 | AA39: 111 | AB39: 111 | AC39: 112 | AD39: 113 | AE39: 115 | AF39: 122 | AG39: 122 | AH39: 124 | AI39: 124 | AJ39: 108 | AK39: 104 | AL39: 92 | AM39: 93 | AN39: 94 | AO39: 98 | AP39: 79 | AQ39: 72 | AR39: 67 | AS39: 64 | AT39: 65 | AU39: 65 | AV39: 66 | AW39: 66 | AX39: 58 | AY39: 58 | AZ39: 55 | BA39: 55 | BB39: 55 | BC39: 56 | BD39: 55 | BE39: 55 | BF39: 53 | BG39: 53 | BH39: 52 | BI39: 52 | BJ39: 50 | BK39: 51 | BL39: 51 | BM39: 52 | BN39: 51 | BO39: 51 | BP39: 51 | BQ39: 51 | BR39: 51 | BS39: 51 | BT39: 52 | BU39: 52 | BV39: 54 | BW39: 54 | BX39: 56 | BY39: 54 | BZ39: 53 | CA39: 53 | CB39: 38 | CC39: 38 | CD39: 41 | CE39: 40 | CF39: 38
A40: 山河长憾 | B40: 72 | C40: 26 | D40: 27 | E40: 31 | F40: 32 | G40: 31 | H40: 31 | I40: 33 | J40: 34 | K40: 34 | L40: 35 | M40: 35 | N40: 31 | O40: 21 | P40: 24 | Q40: 21 | R40: 21 | S40: 22 | T40: 23 | U40: 23 | V40: 23 | W40: 24 | X40: 24 | Y40: 25 | Z40: 24 | AA40: 25 | AB40: 25 | AC40: 25 | AD40: 25 | AE40: 25 | AF40: 26 | AG40: 28 | AH40: 27 | AI40: 28 | AJ40: 29 | AK40: 29 | AL40: 27 | AM40: 25 | AN40: 27 | AO40: 27 | AP40: 28 | AQ40: 27 | AR40: 27 | AS40: 28 | AT40: 28 | AU40: 29 | AV40: 30 | AW40: 31 | AX40: 31 | AY40: 33 | AZ40: 34 | BA40: 33 | BB40: 31 | BC40: 31 | BD40: 32 | BE40: 33 | BF40: 33 | BG40: 32 | BH40: 33 | BI40: 33 | BJ40: 32 | BK40: 33 | BL40: 33 | BM40: 33 | BN40: 34 | BO40: 34 | BP40: 34 | BQ40: 35 | BR40: 37 | BS40: 38 | BT40: 37 | BU40: 37 | BV40: 38 | BW40: 35 | BX40: 34 | BY40: 39 | BZ40: 39 | CA40: 38 | CB40: 42 | CC40: 36 | CD40: 35 | CE40: 38 | CF40: 39
A41: 造星梦工厂96 | B41: 57 | C41: 27 | D41: 34 | E41: 40 | F41: 50 | G41: 59 | H41: 53 | I41: 42 | J41: 47 | K41: 45 | L41: 30 | M41: 31 | N41: 32 | O41: 33 | P41: 28 | Q41: 29 | R41: 32 | S41: 33 | T41: 33 | U41: 34 | V41: 34 | W41: 35 | X41: 35 | Y41: 35 | Z41: 32 | AA41: 33 | AB41: 33 | AC41: 33 | AD41: 33 | AE41: 33 | AF41: 33 | AG41: 26 | AH41: 24 | AI41: 24 | AJ41: 24 | AK41: 24 | AL41: 24 | AM41: 23 | AN41: 25 | AO41: 26 | AP41: 24 | AQ41: 24 | AR41: 24 | AS41: 24 | AT41: 24 | AU41: 25 | AV41: 25 | AW41: 25 | AX41: 25 | AY41: 25 | AZ41: 26 | BA41: 27 | BB41: 24 | BC41: 26 | BD41: 27 | BE41: 29 | BF41: 26 | BG41: 26 | BH41: 28 | BI41: 29 | BJ41: 30 | BK41: 31 | BL41: 31 | BM41: 31 | BN41: 31 | BO41: 31 | BP41: 32 | BQ41: 33 | BR41: 32 | BS41: 33 | BT41: 34 | BU41: 36 | BV41: 36 | BW41: 37 | BX41: 38 | BY41: 38 | BZ41: 38 | CA41: 37 | CB41: 39 | CC41: 41 | CD41: 39 | CE41: 39 | CF41: 40
A42: 无情笺 | B42: 26 | D42: 104 | E42: 129 | F42: 145 | G42: 129 | H42: 138 | I42: 120 | J42: 122 | K42: 123 | L42: 128 | M42: 128 | N42: 130 | O42: 136 | P42: 142 | Q42: 140 | R42: 102 | S42: 102 | T42: 102 | U42: 103 | V42: 105 | W42: 106 | X42: 109 | Y42: 110 | Z42: 110 | AA42: 110 | AB42: 110 | AC42: 104 | AD42: 101 | AE42: 102 | AF42: 95 | AG42: 99 | AH42: 82 | AI42: 72 | AJ42: 65 | AK42: 60 | AL42: 60 | AM42: 57 | AN42: 59 | AO42: 60 | AP42: 60 | AQ42: 60 | AR42: 56 | AS42: 49 | AT42: 45 | AU42: 45 | AV42: 44 | AW42: 45 | AX42: 45 | AY42: 46 | AZ42: 47 | BA42: 47 | BB42: 47 | BC42: 46 | BD42: 46 | BE42: 46 | BF42: 48 | BG42: 49 | BH42: 49 | BI42: 49 | BJ42: 49 | BK42: 49 | BL42: 49 | BM42: 49 | BN42: 45 | BO42: 46 | BP42: 48 | BQ42: 48 | BR42: 47 | BS42: 48 | BT42: 48 | BU42: 47 | BV42: 47 | BW42: 46 | BX42: 46 | BY42: 50 | BZ42: 51 | CA42: 49 | CB42: 50 | CC42: 45 | CD42: 38 | CE42: 42 | CF42: 41
A43: 后妃成长录 | B43: 86 | C43: 53 | D43: 77 | E43: 79 | F43: 93 | G43: 82 | H43: 89 | I43: 98 | J43: 117 | K43: 119 | L43: 124 | M43: 125 | N43: 125 | O43: 130 | P43: 107 | Q43: 109 | R43: 110 | S43: 111 | T43: 113 | U43: 114 | V43: 114 | W43: 116 | X43: 122 | Y43: 122 | Z43: 122 | AA43: 124 | AB43: 126 | AC43: 130 | AD43: 131 | AE43: 116 | AF43: 120 | AG43: 79 | AH43: 79 | AI43: 80 | AJ43: 81 | AK43: 83 | AL43: 84 | AM43: 80 | AN43: 73 | AO43: 68 | AP43: 69 | AQ43: 69 | AR43: 71 | AS43: 75 | AT43: 71 | AU43: 73 | AV43: 75 | AW43: 68 | AX43: 65 | AY43: 60 | AZ43: 62 | BA43: 61 | BB43: 56 | BC43: 54 | BD43: 54 | BE43: 47 | BF43: 44 | BG43: 40 | BH43: 37 | BI43: 37 | BJ43: 37 | BK43: 40 | BL43: 39 | BM43: 38 | BN43: 36 | BO43: 39 | BP43: 36 | BQ43: 36 | BR43: 35 | BS43: 34 | BT43: 33 | BU43: 32 | BV43: 33 | BW43: 33 | BX43: 32 | BY43: 35 | BZ43: 34 | CA43: 34 | CB43: 34 | CC43: 35 | CD43: 37 | CE43: 41 | CF43: 42
A44: 无限求生：房车囤货组队 | B44: 27 | C44: 84 | D44: 110 | E44: 133 | F44: 151 | G44: 169 | H44: 112 | I44: 91 | J44: 89 | K44: 94 | L44: 97 | M44: 100 | N44: 104 | O44: 106 | P44: 109 | Q44: 111 | R44: 112 | S44: 115 | T44: 116 | U44: 117 | V44: 117 | W44: 120 | X44: 125 | Y44: 125 | Z44: 126 | AA44: 129 | AB44: 131 | AC44: 133 | AD44: 134 | AE44: 135 | AF44: 138 | AG44: 143 | AH44: 149 | AI44: 151 | AJ44: 159 | AK44: 164 | AL44: 169 | AM44: 178 | AN44: 181 | AO44: 184 | AP44: 132 | AQ44: 106 | AR44: 63 | AS44: 57 | AT44: 58 | AU44: 60 | AV44: 61 | AW44: 62 | AX44: 63 | AY44: 65 | AZ44: 49 | BA44: 43 | BB44: 42 | BC44: 40 | BD44: 39 | BE44: 40 | BF44: 41 | BG44: 44 | BH44: 40 | BI44: 43 | BJ44: 44 | BK44: 34 | BL44: 34 | BM44: 34 | BN44: 33 | BO44: 35 | BP44: 35 | BQ44: 34 | BR44: 34 | BS44: 35 | BT44: 35 | BU44: 34 | BV44: 35 | BW44: 34 | BX44: 36 | BY44: 34 | BZ44: 35 | CA44: 35 | CB44: 35 | CC44: 40 | CD44: 43 | CE44: 43 | CF44: 43
A45: 问道缥缈 | B45: 88 | C45: 45 | D45: 60 | E45: 73 | F45: 69 | G45: 76 | H45: 86 | I45: 96 | J45: 115 | K45: 86 | L45: 88 | M45: 91 | N45: 68 | O45: 71 | P45: 42 | Q45: 43 | R45: 30 | S45: 21 | T45: 21 | U45: 24 | V45: 24 | W45: 25 | X45: 25 | Y45: 26 | Z45: 27 | AA45: 27 | AB45: 27 | AC45: 27 | AD45: 28 | AE45: 28 | AF45: 28 | AG45: 30 | AH45: 31 | AI45: 31 | AJ45: 31 | AK45: 31 | AL45: 34 | AM45: 34 | AN45: 35 | AO45: 36 | AP45: 38 | AQ45: 39 | AR45: 38 | AS45: 38 | AT45: 39 | AU45: 36 | AV45: 38 | AW45: 42 | AX45: 41 | AY45: 43 | AZ45: 46 | BA45: 45 | BB45: 44 | BC45: 44 | BD45: 44 | BE45: 44 | BF45: 46 | BG45: 47 | BH45: 47 | BI45: 39 | BJ45: 39 | BK45: 43 | BL45: 41 | BM45: 40 | BN45: 40 | BO45: 36 | BP45: 41 | BQ45: 41 | BR45: 42 | BS45: 43 | BT45: 43 | BU45: 44 | BV45: 43 | BW45: 42 | BX45: 43 | BY45: 37 | BZ45: 37 | CA45: 39 | CB45: 40 | CC45: 44 | CD45: 44 | CE45: 44 | CF45: 44
A46: 在下凤三离 | B46: 30 | F46: 146 | G46: 167 | H46: 181 | I46: 112 | J46: 114 | K46: 116 | L46: 105 | M46: 108 | N46: 90 | O46: 93 | P46: 97 | Q46: 101 | R46: 101 | S46: 101 | T46: 86 | U46: 74 | V46: 74 | W46: 74 | X46: 76 | Y46: 76 | Z46: 76 | AA46: 78 | AB46: 74 | AC46: 75 | AD46: 75 | AE46: 73 | AF46: 72 | AG46: 72 | AH46: 38 | AI46: 38 | AJ46: 40 | AK46: 40 | AL46: 38 | AM46: 38 | AN46: 38 | AO46: 39 | AP46: 36 | AQ46: 34 | AR46: 34 | AS46: 34 | AT46: 36 | AU46: 37 | AV46: 37 | AW46: 39 | AX46: 38 | AY46: 39 | AZ46: 40 | BA46: 44 | BB46: 45 | BC46: 47 | BD46: 47 | BE46: 48 | BF46: 49 | BG46: 45 | BH46: 45 | BI46: 46 | BJ46: 46 | BK46: 38 | BL46: 38 | BM46: 37 | BN46: 39 | BO46: 41 | BP46: 38 | BQ46: 40 | BR46: 41 | BS46: 41 | BT46: 41 | BU46: 43 | BV46: 44 | BW46: 44 | BX46: 44 | BY46: 45 | BZ46: 46 | CA46: 47 | CB46: 47 | CC46: 43 | CD46: 45 | CE46: 45 | CF46: 45
A47: 你的私有玩物们 | B47: 65 | C47: 117 | D47: 63 | E47: 44 | F47: 45 | G47: 44 | H47: 38 | I47: 43 | J47: 31 | K47: 30 | L47: 31 | M47: 33 | N47: 36 | O47: 37 | P47: 37 | Q47: 38 | R47: 39 | S47: 41 | T47: 41 | U47: 42 | V47: 42 | W47: 44 | X47: 44 | Y47: 45 | Z47: 43 | AA47: 43 | AB47: 43 | AC47: 41 | AD47: 41 | AE47: 38 | AF47: 38 | AG47: 36 | AH47: 36 | AI47: 36 | AJ47: 37 | AK47: 37 | AL47: 37 | AM47: 37 | AN47: 39 | AO47: 38 | AP47: 40 | AQ47: 38 | AR47: 40 | AS47: 40 | AT47: 40 | AU47: 40 | AV47: 42 | AW47: 36 | AX47: 36 | AY47: 38 | AZ47: 41 | BA47: 42 | BB47: 40 | BC47: 42 | BD47: 43 | BE47: 43 | BF47: 43 | BG47: 42 | BH47: 41 | BI47: 42 | BJ47: 40 | BK47: 44 | BL47: 43 | BM47: 42 | BN47: 42 | BO47: 42 | BP47: 39 | BQ47: 39 | BR47: 36 | BS47: 36 | BT47: 38 | BU47: 38 | BV47: 39 | BW47: 39 | BX47: 40 | BY47: 42 | BZ47: 42 | CA47: 41 | CB47: 43 | CC47: 46 | CD47: 46 | CE47: 46 | CF47: 46
A48: 都想攻略女魔头 | B48: 61 | F48: 176 | G48: 137 | H48: 32 | I48: 31 | J48: 37 | K48: 35 | L48: 36 | M48: 36 | N48: 39 | O48: 39 | P48: 38 | Q48: 39 | R48: 40 | S48: 42 | T48: 42 | U48: 43 | V48: 44 | W48: 46 | X48: 46 | Y48: 39 | Z48: 39 | AA48: 40 | AB48: 36 | AC48: 36 | AD48: 37 | AE48: 37 | AF48: 37 | AG48: 40 | AH48: 42 | AI48: 42 | AJ48: 43 | AK48: 44 | AL48: 46 | AM48: 46 | AN48: 45 | AO48: 47 | AP48: 50 | AQ48: 51 | AR48: 52 | AS48: 48 | AT48: 49 | AU48: 48 | AV48: 49 | AW48: 49 | AX48: 48 | AY48: 51 | AZ48: 54 | BA48: 56 | BB48: 54 | BC48: 57 | BD48: 58 | BE48: 59 | BF48: 61 | BG48: 61 | BH48: 64 | BI48: 65 | BJ48: 65 | BK48: 65 | BL48: 65 | BM48: 50 | BN48: 37 | BO48: 38 | BP48: 40 | BQ48: 37 | BR48: 39 | BS48: 39 | BT48: 39 | BU48: 41 | BV48: 42 | BW48: 43 | BX48: 41 | BY48: 43 | BZ48: 43 | CA48: 44 | CB48: 45 | CC48: 47 | CD48: 48 | CE48: 48 | CF48: 47
A49: 国际女团出道战 | B49: 55 | C49: 57 | D49: 59 | E49: 60 | F49: 64 | G49: 70 | H49: 77 | I49: 53 | J49: 29 | K49: 32 | L49: 33 | M49: 30 | N49: 35 | O49: 36 | P49: 36 | Q49: 36 | R49: 38 | S49: 39 | T49: 39 | U49: 40 | V49: 38 | W49: 39 | X49: 39 | Y49: 40 | Z49: 41 | AA49: 41 | AB49: 41 | AC49: 42 | AD49: 42 | AE49: 43 | AF49: 44 | AG49: 48 | AH49: 51 | AI49: 51 | AJ49: 52 | AK49: 54 | AL49: 54 | AM49: 56 | AN49: 53 | AO49: 52 | AP49: 54 | AQ49: 54 | AR49: 46 | AS49: 45 | AT49: 47 | AU49: 46 | AV49: 48 | AW49: 48 | AX49: 50 | AY49: 44 | AZ49: 43 | BA49: 46 | BB49: 46 | BC49: 48 | BD49: 48 | BE49: 50 | BF49: 50 | BG49: 52 | BH49: 53 | BI49: 53 | BJ49: 54 | BK49: 54 | BL49: 55 | BM49: 58 | BN49: 58 | BO49: 59 | BP49: 59 | BQ49: 60 | BR49: 56 | BS49: 52 | BT49: 50 | BU49: 39 | BV49: 40 | BW49: 41 | BX49: 42 | BY49: 44 | BZ49: 44 | CA49: 46 | CB49: 48 | CC49: 49 | CD49: 47 | CE49: 47 | CF49: 48
A50: 朕被迫上位 | B50: 71 | C50: 30 | D50: 29 | E50: 34 | F50: 34 | G50: 39 | H50: 45 | I50: 50 | J50: 58 | K50: 61 | L50: 63 | M50: 57 | N50: 56 | O50: 50 | P50: 53 | Q50: 54 | R50: 56 | S50: 56 | T50: 56 | U50: 56 | V50: 56 | W50: 56 | X50: 56 | Y50: 56 | Z50: 58 | AA50: 59 | AB50: 54 | AC50: 54 | AD50: 55 | AE50: 54 | AF50: 40 | AG50: 42 | AH50: 44 | AI50: 45 | AJ50: 46 | AK50: 48 | AL50: 43 | AM50: 43 | AN50: 44 | AO50: 46 | AP50: 49 | AQ50: 50 | AR50: 51 | AS50: 55 | AT50: 57 | AU50: 57 | AV50: 58 | AW50: 59 | AX50: 61 | AY50: 63 | AZ50: 64 | BA50: 67 | BB50: 67 | BC50: 65 | BD50: 63 | BE50: 66 | BF50: 67 | BG50: 67 | BH50: 60 | BI50: 55 | BJ50: 55 | BK50: 58 | BL50: 58 | BM50: 60 | BN50: 54 | BO50: 55 | BP50: 56 | BQ50: 54 | BR50: 54 | BS50: 56 | BT50: 56 | BU50: 56 | BV50: 53 | BW50: 49 | BX50: 48 | BY50: 48 | BZ50: 47 | CA50: 48 | CB50: 49 | CC50: 50 | CD50: 49 | CE50: 49 | CF50: 49
A51: 溯世书⁡ | B51: 54 | C51: 22 | D51: 21 | E51: 25 | F51: 29 | G51: 26 | H51: 29 | I51: 26 | J51: 27 | K51: 31 | L51: 32 | M51: 34 | N51: 38 | O51: 38 | P51: 39 | Q51: 40 | R51: 42 | S51: 38 | T51: 38 | U51: 36 | V51: 36 | W51: 36 | X51: 36 | Y51: 36 | Z51: 37 | AA51: 38 | AB51: 39 | AC51: 39 | AD51: 39 | AE51: 41 | AF51: 43 | AG51: 35 | AH51: 37 | AI51: 37 | AJ51: 39 | AK51: 39 | AL51: 41 | AM51: 41 | AN51: 42 | AO51: 44 | AP51: 45 | AQ51: 45 | AR51: 45 | AS51: 47 | AT51: 50 | AU51: 51 | AV51: 54 | AW51: 52 | AX51: 52 | AY51: 53 | AZ51: 56 | BA51: 57 | BB51: 57 | BC51: 58 | BD51: 56 | BE51: 57 | BF51: 57 | BG51: 51 | BH51: 51 | BI51: 51 | BJ51: 53 | BK51: 53 | BL51: 53 | BM51: 56 | BN51: 56 | BO51: 54 | BP51: 55 | BQ51: 56 | BR51: 57 | BS51: 57 | BT51: 57 | BU51: 57 | BV51: 58 | BW51: 59 | BX51: 60 | BY51: 60 | BZ51: 61 | CA51: 62 | CB51: 57 | CC51: 51 | CD51: 51 | CE51: 51 | CF51: 50
A52: 千山行旅图 | B52: 154 | G52: 149 | H52: 164 | I52: 182 | BC52: 24 | BD52: 24 | BE52: 25 | BF52: 25 | BG52: 25 | BH52: 25 | BI52: 25 | BJ52: 26 | BK52: 28 | BL52: 28 | BM52: 29 | BN52: 29 | BO52: 29 | BP52: 30 | BQ52: 30 | BR52: 30 | BS52: 31 | BT52: 32 | BU52: 33 | BV52: 34 | BW52: 38 | BX52: 37 | BY52: 40 | BZ52: 41 | CA52: 42 | CB52: 44 | CC52: 48 | CD52: 50 | CE52: 50 | CF52: 51
A53: 后宫群妃录 | B53: 49 | C53: 95 | D53: 111 | E53: 122 | F53: 66 | G53: 60 | H53: 52 | I53: 56 | J53: 62 | K53: 58 | L53: 44 | M53: 43 | N53: 42 | O53: 40 | P53: 43 | Q53: 46 | R53: 45 | S53: 46 | T53: 46 | U53: 47 | V53: 43 | W53: 45 | X53: 45 | Y53: 46 | Z53: 46 | AA53: 46 | AB53: 46 | AC53: 46 | AD53: 47 | AE53: 49 | AF53: 49 | AG53: 50 | AH53: 47 | AI53: 46 | AJ53: 48 | AK53: 46 | AL53: 48 | AM53: 49 | AN53: 49 | AO53: 51 | AP53: 53 | AQ53: 47 | AR53: 49 | AS53: 51 | AT53: 54 | AU53: 54 | AV53: 52 | AW53: 55 | AX53: 55 | AY53: 57 | AZ53: 59 | BA53: 60 | BB53: 62 | BC53: 64 | BD53: 66 | BE53: 61 | BF53: 60 | BG53: 55 | BH53: 54 | BI53: 54 | BJ53: 51 | BK53: 50 | BL53: 50 | BM53: 51 | BN53: 52 | BO53: 52 | BP53: 52 | BQ53: 52 | BR53: 53 | BS53: 53 | BT53: 54 | BU53: 51 | BV53: 51 | BW53: 48 | BX53: 49 | BY53: 52 | BZ53: 54 | CA53: 54 | CB53: 54 | CC53: 52 | CD53: 53 | CE53: 52 | CF53: 52
A54: 斩情 | B54: 45 | C54: 93 | D54: 126 | E54: 152 | F54: 154 | G54: 177 | H54: 186 | AS54: 143 | AT54: 147 | AU54: 153 | AV54: 161 | AW54: 112 | AX54: 116 | AY54: 123 | AZ54: 127 | BA54: 129 | BB54: 134 | BC54: 139 | BD54: 142 | BE54: 144 | BF54: 145 | BG54: 154 | BH54: 155 | BI54: 160 | BJ54: 162 | BK54: 133 | BL54: 137 | BM54: 139 | BN54: 141 | BO54: 144 | BP54: 145 | BQ54: 150 | BR54: 151 | BS54: 150 | BT54: 152 | BU54: 153 | BV54: 160 | BW54: 164 | BX54: 168 | BY54: 64 | BZ54: 49 | CA54: 51 | CB54: 52 | CC54: 55 | CD54: 52 | CE54: 53 | CF54: 53
A55: 仙履奇谈 | B55: 24 | C55: 149 | D55: 92 | E55: 76 | F55: 33 | G55: 33 | H55: 39 | I55: 34 | J55: 32 | K55: 37 | L55: 39 | M55: 39 | N55: 30 | O55: 31 | P55: 32 | Q55: 32 | R55: 24 | S55: 26 | T55: 27 | U55: 22 | V55: 21 | W55: 22 | X55: 22 | Y55: 22 | Z55: 23 | AA55: 21 | AB55: 21 | AC55: 21 | AD55: 21 | AE55: 21 | AF55: 20 | AG55: 22 | AH55: 23 | AI55: 20 | AJ55: 21 | AK55: 22 | AL55: 22 | AM55: 22 | AN55: 22 | AO55: 23 | AP55: 23 | AQ55: 23 | AR55: 23 | AS55: 25 | AT55: 25 | AU55: 26 | AV55: 27 | AW55: 27 | AX55: 28 | AY55: 30 | AZ55: 30 | BA55: 34 | BB55: 37 | BC55: 39 | BD55: 40 | BE55: 41 | BF55: 40 | BG55: 41 | BH55: 44 | BI55: 45 | BJ55: 43 | BK55: 46 | BL55: 47 | BM55: 44 | BN55: 48 | BO55: 48 | BP55: 47 | BQ55: 47 | BR55: 49 | BS55: 46 | BT55: 46 | BU55: 49 | BV55: 49 | BW55: 47 | BX55: 47 | BY55: 49 | BZ55: 50 | CA55: 52 | CB55: 53 | CC55: 54 | CD55: 55 | CE55: 54 | CF55: 54
A56: 千秋百代：帝王一小时 | B56: 82 | C56: 39 | D56: 43 | E56: 42 | F56: 53 | G56: 50 | H56: 46 | I56: 45 | J56: 45 | K56: 49 | L56: 50 | M56: 48 | N56: 47 | O56: 44 | P56: 47 | Q56: 45 | R56: 46 | S56: 47 | T56: 48 | U56: 48 | V56: 49 | W56: 49 | X56: 50 | Y56: 50 | Z56: 50 | AA56: 49 | AB56: 49 | AC56: 49 | AD56: 46 | AE56: 48 | AF56: 46 | AG56: 46 | AH56: 49 | AI56: 47 | AJ56: 47 | AK56: 41 | AL56: 44 | AM56: 44 | AN56: 46 | AO56: 48 | AP56: 51 | AQ56: 52 | AR56: 53 | AS56: 50 | AT56: 52 | AU56: 52 | AV56: 51 | AW56: 53 | AX56: 49 | AY56: 50 | AZ56: 51 | BA56: 53 | BB56: 53 | BC56: 55 | BD56: 57 | BE56: 56 | BF56: 58 | BG56: 59 | BH56: 58 | BI56: 59 | BJ56: 57 | BK56: 56 | BL56: 54 | BM56: 53 | BN56: 53 | BO56: 53 | BP56: 53 | BQ56: 53 | BR56: 52 | BS56: 55 | BT56: 53 | BU56: 55 | BV56: 50 | BW56: 50 | BX56: 50 | BY56: 47 | BZ56: 48 | CA56: 50 | CB56: 51 | CC56: 53 | CD56: 54 | CE56: 55 | CF56: 55
A57: 仙门第一纨绔 | B57: 108 | E57: 61 | F57: 70 | G57: 45 | H57: 37 | I57: 38 | J57: 44 | K57: 47 | L57: 48 | M57: 51 | N57: 22 | O57: 25 | P57: 26 | Q57: 26 | R57: 29 | S57: 31 | T57: 31 | U57: 31 | V57: 31 | W57: 32 | X57: 32 | Y57: 33 | Z57: 34 | AA57: 34 | AB57: 34 | AC57: 34 | AD57: 34 | AE57: 34 | AF57: 35 | AG57: 38 | AH57: 40 | AI57: 40 | AJ57: 41 | AK57: 42 | AL57: 39 | AM57: 39 | AN57: 21 | AO57: 21 | AP57: 21 | AQ57: 21 | AR57: 21 | AS57: 22 | AT57: 22 | AU57: 24 | AV57: 26 | AW57: 26 | AX57: 27 | AY57: 27 | AZ57: 27 | BA57: 30 | BB57: 32 | BC57: 34 | BD57: 34 | BE57: 35 | BF57: 37 | BG57: 38 | BH57: 42 | BI57: 34 | BJ57: 34 | BK57: 35 | BL57: 36 | BM57: 39 | BN57: 41 | BO57: 43 | BP57: 45 | BQ57: 45 | BR57: 45 | BS57: 45 | BT57: 45 | BU57: 46 | BV57: 48 | BW57: 52 | BX57: 52 | BY57: 56 | BZ57: 58 | CA57: 60 | CB57: 62 | CC57: 63 | CD57: 63 | CE57: 63 | CF57: 56
A58: 暗卫他又跑 | B58: 53 | C58: 36 | D58: 46 | E58: 56 | F58: 48 | G58: 49 | H58: 43 | I58: 48 | J58: 48 | K58: 51 | L58: 52 | M58: 54 | N58: 51 | O58: 53 | P58: 52 | Q58: 52 | R58: 53 | S58: 53 | T58: 55 | U58: 55 | V58: 55 | W58: 55 | X58: 55 | Y58: 53 | Z58: 53 | AA58: 54 | AB58: 56 | AC58: 56 | AD58: 57 | AE58: 58 | AF58: 59 | AG58: 62 | AH58: 64 | AI58: 64 | AJ58: 62 | AK58: 64 | AL58: 63 | AM58: 64 | AN58: 63 | AO58: 58 | AP58: 58 | AQ58: 58 | AR58: 59 | AS58: 63 | AT58: 64 | AU58: 64 | AV58: 65 | AW58: 65 | AX58: 66 | AY58: 66 | AZ58: 66 | BA58: 63 | BB58: 64 | BC58: 66 | BD58: 64 | BE58: 65 | BF58: 65 | BG58: 66 | BH58: 65 | BI58: 68 | BJ58: 68 | BK58: 68 | BL58: 67 | BM58: 68 | BN58: 67 | BO58: 69 | BP58: 67 | BQ58: 67 | BR58: 68 | BS58: 66 | BT58: 63 | BU58: 63 | BV58: 63 | BW58: 62 | BX58: 63 | BY58: 63 | BZ58: 64 | CA58: 64 | CB58: 64 | CC58: 62 | CD58: 62 | CE58: 62 | CF58: 57
...

Sheet 活跃榜排名变化
A1: 作品名 | B1: 2026-10-09 00:15 | C1: 2026-10-09 00:45 | D1: 2026-10-09 01:00 | E1: 2026-10-09 01:15 | F1: 2026-10-09 01:30 | G1: 2026-10-09 01:45 | H1: 2026-10-09 02:00 | I1: 2026-10-09 02:15 | J1: 2026-10-09 02:45 | K1: 2026-10-09 03:00 | L1: 2026-10-09 03:15 | M1: 2026-10-09 03:30 | N1: 2026-10-09 03:45 | O1: 2026-10-09 04:00 | P1: 2026-10-09 04:15 | Q1: 2026-10-09 04:45 | R1: 2026-10-09 05:00 | S1: 2026-10-09 05:15 | T1: 2026-10-09 05:30 | U1: 2026-10-09 05:45 | V1: 2026-10-09 06:00 | W1: 2026-10-09 06:15 | X1: 2026-10-09 06:30 | Y1: 2026-10-09 06:45 | Z1: 2026-10-09 07:00 | AA1: 2026-10-09 07:15 | AB1: 2026-10-09 07:30 | AC1: 2026-10-09 07:45 | AD1: 2026-10-09 08:00 | AE1: 2026-10-09 08:15 | AF1: 2026-10-09 08:45 | AG1: 2026-10-09 09:15 | AH1: 2026-10-09 09:30 | AI1: 2026-10-09 09:45 | AJ1: 2026-10-09 10:00 | AK1: 2026-10-09 10:15 | AL1: 2026-10-09 10:30 | AM1: 2026-10-09 10:45 | AN1: 2026-10-09 11:00 | AO1: 2026-10-09 11:15 | AP1: 2026-10-09 11:30 | AQ1: 2026-10-09 11:45 | AR1: 2026-10-09 12:00 | AS1: 2026-10-09 12:30 | AT1: 2026-10-09 12:45 | AU1: 2026-10-09 13:00 | AV1: 2026-10-09 13:15 | AW1: 2026-10-09 13:30 | AX1: 2026-10-09 13:45 | AY1: 2026-10-09 14:00 | AZ1: 2026-10-09 14:30 | BA1: 2026-10-09 14:45 | BB1: 2026-10-09 15:15 | BC1: 2026-10-09 15:30 | BD1: 2026-10-09 15:45 | BE1: 2026-10-09 16:00 | BF1: 2026-10-09 16:15 | BG1: 2026-10-09 16:45 | BH1: 2026-10-09 17:00 | BI1: 2026-10-09 17:15 | BJ1: 2026-10-09 17:30 | BK1: 2026-10-09 17:45 | BL1: 2026-10-09 18:00 | BM1: 2026-10-09 18:15 | BN1: 2026-10-09 18:45 | BO1: 2026-10-09 19:00 | BP1: 2026-10-09 19:15 | BQ1: 2026-10-09 19:30 | BR1: 2026-10-09 19:45 | BS1: 2026-10-09 20:00 | BT1: 2026-10-09 20:15 | BU1: 2026-10-09 20:30 | BV1: 2026-10-09 21:00 | BW1: 2026-10-09 21:15 | BX1: 2026-10-09 21:30 | BY1: 2026-10-09 22:00 | BZ1: 2026-10-09 22:15 | CA1: 2026-10-09 22:30 | CB1: 2026-10-09 22:45 | CC1: 2026-10-09 23:15 | CD1: 2026-10-09 23:30 | CE1: 2026-10-09 23:45 | CF1: 2026-10-10 00:00
A2: 临帝阙 | B2: 1 | C2: 1 | D2: 1 | E2: 1 | F2: 1 | G2: 1 | H2: 1 | I2: 1 | J2: 1 | K2: 1 | L2: 1 | M2: 1 | N2: 1 | O2: 1 | P2: 1 | Q2: 1 | R2: 1 | S2: 1 | T2: 1 | U2: 1 | V2: 1 | W2: 1 | X2: 1 | Y2: 1 | Z2: 1 | AA2: 1 | AB2: 1 | AC2: 1 | AD2: 1 | AE2: 2 | AF2: 3 | AG2: 1 | AH2: 1 | AI2: 1 | AJ2: 1 | AK2: 1 | AL2: 1 | AM2: 1 | AN2: 1 | AO2: 1 | AP2: 1 | AQ2: 1 | AR2: 1 | AS2: 1 | AT2: 1 | AU2: 1 | AV2: 1 | AW2: 1 | AX2: 1 | AY2: 1 | AZ2: 1 | BA2: 1 | BB2: 1 | BC2: 1 | BD2: 1 | BE2: 1 | BF2: 1 | BG2: 1 | BH2: 1 | BI2: 1 | BJ2: 1 | BK2: 1 | BL2: 1 | BM2: 1 | BN2: 1 | BO2: 1 | BP2: 1 | BQ2: 1 | BR2: 1 | BS2: 1 | BT2: 1 | BU2: 1 | BV2: 1 | BW2: 1 | BX2: 1 | BY2: 1 | BZ2: 1 | CA2: 1 | CB2: 1 | CC2: 1 | CD2: 1 | CE2: 1 | CF2: 1
A3: 三界衔 | B3: 4 | C3: 3 | D3: 4 | E3: 3 | F3: 5 | G3: 4 | H3: 2 | I3: 3 | J3: 2 | K3: 3 | L3: 3 | M3: 2 | N3: 2 | O3: 2 | P3: 2 | Q3: 2 | R3: 2 | S3: 2 | T3: 2 | U3: 2 | V3: 2 | W3: 2 | X3: 3 | Y3: 3 | Z3: 2 | AA3: 2 | AB3: 2 | AC3: 2 | AD3: 2 | AE3: 1 | AF3: 1 | AG3: 2 | AH3: 2 | AI3: 2 | AJ3: 2 | AK3: 2 | AL3: 2 | AM3: 2 | AN3: 2 | AO3: 2 | AP3: 2 | AQ3: 3 | AR3: 3 | AS3: 2 | AT3: 2 | AU3: 2 | AV3: 3 | AW3: 3 | AX3: 3 | AY3: 3 | AZ3: 3 | BA3: 3 | BB3: 3 | BC3: 3 | BD3: 3 | BE3: 3 | BF3: 3 | BG3: 3 | BH3: 3 | BI3: 3 | BJ3: 3 | BK3: 3 | BL3: 3 | BM3: 3 | BN3: 3 | BO3: 3 | BP3: 3 | BQ3: 3 | BR3: 3 | BS3: 3 | BT3: 3 | BU3: 3 | BV3: 3 | BW3: 3 | BX3: 3 | BY3: 2 | BZ3: 2 | CA3: 2 | CB3: 4 | CC3: 2 | CD3: 2 | CE3: 2 | CF3: 2
A4: 江山千秋万代 | B4: 2 | C4: 2 | D4: 2 | E4: 2 | F4: 2 | G4: 2 | H4: 3 | I4: 2 | J4: 3 | K4: 2 | L4: 2 | M4: 3 | N4: 3 | O4: 3 | P4: 3 | Q4: 3 | R4: 3 | S4: 3 | T4: 3 | U4: 3 | V4: 3 | W4: 3 | X4: 2 | Y4: 2 | Z4: 3 | AA4: 3 | AB4: 3 | AC4: 3 | AD4: 3 | AE4: 3 | AF4: 2 | AG4: 3 | AH4: 3 | AI4: 4 | AJ4: 4 | AK4: 4 | AL4: 5 | AM4: 4 | AN4: 4 | AO4: 4 | AP4: 4 | AQ4: 4 | AR4: 2 | AS4: 3 | AT4: 3 | AU4: 3 | AV4: 2 | AW4: 2 | AX4: 2 | AY4: 2 | AZ4: 2 | BA4: 2 | BB4: 2 | BC4: 2 | BD4: 2 | BE4: 2 | BF4: 2 | BG4: 2 | BH4: 2 | BI4: 2 | BJ4: 2 | BK4: 2 | BL4: 2 | BM4: 2 | BN4: 2 | BO4: 2 | BP4: 2 | BQ4: 2 | BR4: 2 | BS4: 2 | BT4: 2 | BU4: 2 | BV4: 2 | BW4: 2 | BX4: 2 | BY4: 3 | BZ4: 3 | CA4: 3 | CB4: 2 | CC4: 3 | CD4: 3 | CE4: 3 | CF4: 3
A5: 师途 | B5: 3 | C5: 4 | D5: 3 | E5: 4 | F5: 4 | G5: 3 | H5: 4 | I5: 4 | J5: 4 | K5: 4 | L5: 4 | M5: 4 | N5: 4 | O5: 4 | P5: 4 | Q5: 4 | R5: 4 | S5: 4 | T5: 4 | U5: 4 | V5: 4 | W5: 4 | X5: 4 | Y5: 4 | Z5: 4 | AA5: 4 | AB5: 4 | AC5: 4 | AD5: 4 | AE5: 4 | AF5: 5 | AG5: 4 | AH5: 4 | AI5: 3 | AJ5: 3 | AK5: 3 | AL5: 3 | AM5: 3 | AN5: 3 | AO5: 3 | AP5: 3 | AQ5: 2 | AR5: 4 | AS5: 4 | AT5: 4 | AU5: 4 | AV5: 4 | AW5: 4 | AX5: 4 | AY5: 4 | AZ5: 4 | BA5: 4 | BB5: 4 | BC5: 4 | BD5: 4 | BE5: 4 | BF5: 4 | BG5: 4 | BH5: 4 | BI5: 4 | BJ5: 4 | BK5: 4 | BL5: 4 | BM5: 4 | BN5: 4 | BO5: 4 | BP5: 4 | BQ5: 4 | BR5: 4 | BS5: 4 | BT5: 4 | BU5: 4 | BV5: 4 | BW5: 4 | BX5: 4 | BY5: 5 | BZ5: 5 | CA5: 5 | CB5: 5 | CC5: 5 | CD5: 4 | CE5: 4 | CF5: 4
A6: 成为团播TOP之后 | B6: 5 | C6: 6 | D6: 6 | E6: 5 | F6: 6 | G6: 6 | H6: 6 | I6: 6 | J6: 7 | K6: 6 | L6: 5 | M6: 5 | N6: 5 | O6: 6 | P6: 5 | Q6: 5 | R6: 5 | S6: 5 | T6: 5 | U6: 5 | V6: 5 | W6: 5 | X6: 5 | Y6: 5 | Z6: 6 | AA6: 6 | AB6: 6 | AC6: 6 | AD6: 5 | AE6: 5 | AF6: 6 | AG6: 6 | AH6: 5 | AI6: 5 | AJ6: 5 | AK6: 5 | AL6: 6 | AM6: 5 | AN6: 5 | AO6: 5 | AP6: 5 | AQ6: 5 | AR6: 5 | AS6: 5 | AT6: 6 | AU6: 5 | AV6: 5 | AW6: 5 | AX6: 5 | AY6: 5 | AZ6: 5 | BA6: 5 | BB6: 5 | BC6: 5 | BD6: 5 | BE6: 5 | BF6: 5 | BG6: 5 | BH6: 5 | BI6: 5 | BJ6: 5 | BK6: 5 | BL6: 5 | BM6: 5 | BN6: 5 | BO6: 5 | BP6: 5 | BQ6: 6 | BR6: 6 | BS6: 6 | BT6: 6 | BU6: 6 | BV6: 6 | BW6: 6 | BX6: 6 | BY6: 6 | BZ6: 6 | CA6: 6 | CB6: 6 | CC6: 6 | CD6: 5 | CE6: 5 | CF6: 5
A7: 捉鬼师后日谈 | B7: 6 | C7: 5 | D7: 5 | E7: 6 | F7: 3 | G7: 5 | H7: 5 | I7: 5 | J7: 5 | K7: 5 | L7: 6 | M7: 7 | N7: 7 | O7: 7 | P7: 6 | Q7: 6 | R7: 6 | S7: 6 | T7: 7 | U7: 6 | V7: 6 | W7: 6 | X7: 6 | Y7: 6 | Z7: 5 | AA7: 5 | AB7: 5 | AC7: 5 | AD7: 6 | AE7: 8 | AF7: 9 | AG7: 9 | AH7: 10 | AI7: 10 | AJ7: 9 | AK7: 8 | AL7: 4 | AM7: 6 | AN7: 7 | AO7: 7 | AP7: 8 | AQ7: 8 | AR7: 7 | AS7: 6 | AT7: 5 | AU7: 6 | AV7: 6 | AW7: 6 | AX7: 6 | AY7: 6 | AZ7: 6 | BA7: 6 | BB7: 7 | BC7: 6 | BD7: 6 | BE7: 6 | BF7: 6 | BG7: 6 | BH7: 6 | BI7: 6 | BJ7: 6 | BK7: 6 | BL7: 6 | BM7: 6 | BN7: 6 | BO7: 6 | BP7: 6 | BQ7: 5 | BR7: 5 | BS7: 5 | BT7: 5 | BU7: 5 | BV7: 5 | BW7: 5 | BX7: 5 | BY7: 4 | BZ7: 4 | CA7: 4 | CB7: 3 | CC7: 4 | CD7: 6 | CE7: 6 | CF7: 6
A8: 星期天不上头条 | B8: 13 | C8: 11 | D8: 11 | E8: 11 | F8: 11 | G8: 11 | H8: 11 | I8: 11 | J8: 11 | K8: 11 | L8: 11 | M8: 11 | N8: 11 | O8: 11 | P8: 9 | Q8: 10 | R8: 13 | S8: 12 | T8: 8 | U8: 8 | V8: 10 | W8: 10 | X8: 11 | Y8: 9 | Z8: 10 | AA8: 9 | AB8: 7 | AC8: 7 | AD8: 8 | AE8: 7 | AF8: 7 | AG8: 7 | AH8: 7 | AI8: 7 | AJ8: 6 | AK8: 7 | AL8: 7 | AM8: 8 | AN8: 8 | AO8: 8 | AP8: 7 | AQ8: 6 | AR8: 9 | AS8: 9 | AT8: 9 | AU8: 9 | AV8: 7 | AW8: 7 | AX8: 7 | AY8: 7 | AZ8: 7 | BA8: 7 | BB8: 6 | BC8: 7 | BD8: 7 | BE8: 7 | BF8: 7 | BG8: 7 | BH8: 7 | BI8: 7 | BJ8: 7 | BK8: 7 | BL8: 7 | BM8: 7 | BN8: 10 | BO8: 10 | BP8: 10 | BQ8: 10 | BR8: 9 | BS8: 10 | BT8: 11 | BU8: 12 | BV8: 10 | BW8: 11 | BX8: 12 | BY8: 12 | BZ8: 10 | CA8: 7 | CB8: 9 | CC8: 7 | CD8: 7 | CE8: 8 | CF8: 7
A9: AMNESIA 失忆症 | B9: 10 | C9: 9 | D9: 9 | E9: 10 | F9: 10 | G9: 10 | H9: 10 | I9: 10 | J9: 10 | K9: 10 | L9: 10 | M9: 10 | N9: 10 | O9: 10 | P9: 11 | Q9: 13 | R9: 11 | S9: 11 | T9: 13 | U9: 12 | V9: 11 | W9: 13 | X9: 15 | Y9: 10 | Z9: 9 | AA9: 11 | AB9: 11 | AC9: 9 | AD9: 12 | AE9: 11 | AF9: 12 | AG9: 10 | AH9: 8 | AI9: 8 | AJ9: 10 | AK9: 11 | AL9: 10 | AM9: 10 | AN9: 10 | AO9: 10 | AP9: 10 | AQ9: 11 | AR9: 11 | AS9: 10 | AT9: 10 | AU9: 11 | AV9: 11 | AW9: 11 | AX9: 12 | AY9: 12 | AZ9: 13 | BA9: 13 | BB9: 12 | BC9: 13 | BD9: 13 | BE9: 13 | BF9: 13 | BG9: 15 | BH9: 14 | BI9: 14 | BJ9: 15 | BK9: 15 | BL9: 15 | BM9: 15 | BN9: 13 | BO9: 15 | BP9: 15 | BQ9: 14 | BR9: 14 | BS9: 14 | BT9: 12 | BU9: 13 | BV9: 13 | BW9: 12 | BX9: 11 | BY9: 11 | BZ9: 11 | CA9: 11 | CB9: 12 | CC9: 10 | CD9: 10 | CE9: 7 | CF9: 8
A10: 风华临安 | B10: 7 | C10: 7 | D10: 7 | E10: 7 | F10: 7 | G10: 7 | H10: 7 | I10: 7 | J10: 6 | K10: 7 | L10: 7 | M10: 6 | N10: 6 | O10: 5 | P10: 7 | Q10: 7 | R10: 8 | S10: 7 | T10: 12 | U10: 7 | V10: 8 | W10: 9 | X10: 7 | Y10: 11 | Z10: 8 | AA10: 12 | AB10: 10 | AC10: 10 | AD10: 11 | AE10: 16 | AF10: 14 | AG10: 11 | AH10: 11 | AI10: 11 | AJ10: 12 | AK10: 10 | AL10: 9 | AM10: 9 | AN10: 6 | AO10: 6 | AP10: 6 | AQ10: 7 | AR10: 6 | AS10: 7 | AT10: 7 | AU10: 8 | AV10: 8 | AW10: 8 | AX10: 8 | AY10: 8 | AZ10: 8 | BA10: 8 | BB10: 9 | BC10: 9 | BD10: 11 | BE10: 11 | BF10: 11 | BG10: 12 | BH10: 13 | BI10: 13 | BJ10: 13 | BK10: 13 | BL10: 13 | BM10: 13 | BN10: 15 | BO10: 14 | BP10: 13 | BQ10: 12 | BR10: 12 | BS10: 12 | BT10: 10 | BU10: 10 | BV10: 11 | BW10: 9 | BX10: 10 | BY10: 13 | BZ10: 13 | CA10: 13 | CB10: 10 | CC10: 9 | CD10: 9 | CE10: 9 | CF10: 9
A11: 怪我过分美丽 | B11: 9 | C11: 10 | D11: 10 | E11: 9 | F11: 9 | G11: 9 | H11: 9 | I11: 9 | J11: 9 | K11: 9 | L11: 8 | M11: 9 | N11: 8 | O11: 8 | P11: 8 | Q11: 11 | R11: 9 | S11: 8 | T11: 10 | U11: 9 | V11: 7 | W11: 8 | X11: 8 | Y11: 8 | Z11: 11 | AA11: 10 | AB11: 9 | AC11: 11 | AD11: 10 | AE11: 9 | AF11: 8 | AG11: 8 | AH11: 9 | AI11: 9 | AJ11: 8 | AK11: 9 | AL11: 8 | AM11: 7 | AN11: 9 | AO11: 9 | AP11: 9 | AQ11: 9 | AR11: 8 | AS11: 8 | AT11: 8 | AU11: 7 | AV11: 9 | AW11: 10 | AX11: 10 | AY11: 10 | AZ11: 11 | BA11: 11 | BB11: 11 | BC11: 10 | BD11: 9 | BE11: 9 | BF11: 9 | BG11: 10 | BH11: 10 | BI11: 10 | BJ11: 10 | BK11: 11 | BL11: 9 | BM11: 9 | BN11: 8 | BO11: 9 | BP11: 8 | BQ11: 9 | BR11: 10 | BS11: 9 | BT11: 9 | BU11: 11 | BV11: 12 | BW11: 10 | BX11: 13 | BY11: 10 | BZ11: 12 | CA11: 12 | CB11: 11 | CC11: 11 | CD11: 11 | CE11: 10 | CF11: 10
A12: 宫妃 | B12: 11 | C12: 13 | D12: 13 | E12: 13 | F12: 13 | G12: 13 | H12: 13 | I12: 13 | J12: 12 | K12: 14 | L12: 13 | M12: 12 | N12: 14 | O12: 14 | P12: 13 | Q12: 14 | R12: 16 | S12: 14 | T12: 15 | U12: 14 | V12: 12 | W12: 15 | X12: 14 | Y12: 13 | Z12: 15 | AA12: 19 | AB12: 20 | AC12: 20 | AD12: 23 | AE12: 23 | AF12: 19 | AG12: 19 | AH12: 17 | AI12: 16 | AJ12: 16 | AK12: 17 | AL12: 16 | AM12: 14 | AN12: 12 | AO12: 12 | AP12: 13 | AQ12: 12 | AR12: 13 | AS12: 13 | AT12: 12 | AU12: 12 | AV12: 12 | AW12: 13 | AX12: 13 | AY12: 13 | AZ12: 12 | BA12: 12 | BB12: 13 | BC12: 12 | BD12: 12 | BE12: 12 | BF12: 12 | BG12: 13 | BH12: 12 | BI12: 11 | BJ12: 11 | BK12: 9 | BL12: 11 | BM12: 11 | BN12: 11 | BO12: 11 | BP12: 12 | BQ12: 13 | BR12: 13 | BS12: 13 | BT12: 13 | BU12: 15 | BV12: 14 | BW12: 13 | BX12: 14 | BY12: 14 | BZ12: 14 | CA12: 14 | CB12: 13 | CC12: 13 | CD12: 13 | CE12: 11 | CF12: 11
A13: 勿扰修仙中 | B13: 14 | C13: 14 | D13: 12 | E13: 12 | F13: 12 | G13: 12 | H13: 12 | I13: 12 | J13: 13 | K13: 12 | L13: 12 | M13: 13 | N13: 12 | O13: 12 | P13: 10 | Q13: 9 | R13: 12 | S13: 10 | T13: 9 | U13: 13 | V13: 13 | W13: 14 | X13: 12 | Y13: 15 | Z13: 14 | AA13: 17 | AB13: 16 | AC13: 16 | AD13: 15 | AE13: 19 | AF13: 16 | AG13: 14 | AH13: 14 | AI13: 15 | AJ13: 14 | AK13: 14 | AL13: 14 | AM13: 13 | AN13: 13 | AO13: 13 | AP13: 12 | AQ13: 13 | AR13: 10 | AS13: 12 | AT13: 13 | AU13: 13 | AV13: 13 | AW13: 12 | AX13: 11 | AY13: 11 | AZ13: 10 | BA13: 10 | BB13: 10 | BC13: 11 | BD13: 10 | BE13: 10 | BF13: 10 | BG13: 9 | BH13: 8 | BI13: 9 | BJ13: 8 | BK13: 10 | BL13: 10 | BM13: 10 | BN13: 7 | BO13: 7 | BP13: 7 | BQ13: 7 | BR13: 7 | BS13: 7 | BT13: 7 | BU13: 8 | BV13: 8 | BW13: 7 | BX13: 8 | BY13: 8 | BZ13: 7 | CA13: 8 | CB13: 7 | CC13: 14 | CD13: 14 | CE13: 12 | CF13: 12
... A39: 妄情债 | B39: 24 | C39: 23 | D39: 27 | E39: 25 | F39: 26 | G39: 26 | H39: 26 | I39: 26 | J39: 25 | K39: 27 | L39: 27 | M39: 27 | N39: 29 | O39: 28 | P39: 28 | Q39: 31 | R39: 33 | S39: 33 | T39: 31 | U39: 36 | V39: 39 | W39: 35 | X39: 38 | Y39: 36 | Z39: 37 | AA39: 35 | AB39: 34 | AC39: 31 | AD39: 32 | AE39: 31 | AF39: 28 | AG39: 29 | AH39: 25 | AI39: 23 | AJ39: 24 | AK39: 22 | AL39: 24 | AM39: 25 | AN39: 28 | AO39: 27 | AP39: 25 | AQ39: 29 | AR39: 32 | AS39: 33 | AT39: 34 | AU39: 34 | AV39: 36 | AW39: 35 | AX39: 39 | AY39: 39 | AZ39: 39 | BA39: 41 | BB39: 44 | BC39: 42 | BD39: 45 | BE39: 45 | BF39: 46 | BG39: 43 | BH39: 43 | BI39: 42 | BJ39: 41 | BK39: 39 | BL39: 41 | BM39: 39 | BN39: 40 | BO39: 32 | BP39: 37 | BQ39: 37 | BR39: 37 | BS39: 38 | BT39: 39 | BU39: 36 | BV39: 36 | BW39: 36 | BX39: 41 | BY39: 41 | BZ39: 46 | CA39: 47 | CB39: 46 | CC39: 43 | CD39: 43 | CE39: 39 | CF39: 38
A40: 姐姐请带我回家 | B40: 116 | C40: 121 | D40: 117 | E40: 119 | F40: 117 | G40: 113 | H40: 110 | I40: 115 | J40: 104 | K40: 110 | L40: 111 | M40: 99 | N40: 92 | O40: 95 | P40: 70 | Q40: 96 | R40: 99 | S40: 109 | T40: 93 | U40: 87 | V40: 89 | W40: 72 | X40: 67 | Y40: 58 | Z40: 63 | AA40: 71 | AB40: 80 | AC40: 82 | AD40: 72 | AE40: 83 | AF40: 107 | AG40: 129 | AH40: 132 | AI40: 177 | AJ40: 172 | AY40: 197 | AZ40: 185 | BA40: 174 | BB40: 147 | BC40: 143 | BD40: 142 | BE40: 142 | BF40: 139 | BG40: 131 | BH40: 128 | BI40: 120 | BJ40: 112 | BK40: 107 | BL40: 102 | BM40: 95 | BN40: 93 | BO40: 96 | BP40: 102 | BQ40: 95 | BR40: 84 | BS40: 87 | BT40: 82 | BU40: 80 | BV40: 70 | BW40: 68 | BX40: 56 | BY40: 62 | BZ40: 61 | CA40: 57 | CB40: 55 | CC40: 49 | CD40: 38 | CE40: 37 | CF40: 39
A41: 末日之基地建设 | B41: 29 | C41: 28 | D41: 75 | E41: 77 | F41: 76 | G41: 76 | H41: 76 | I41: 74 | J41: 74 | K41: 71 | L41: 71 | M41: 75 | N41: 73 | O41: 74 | P41: 141 | Q41: 125 | R41: 171 | BI41: 85 | BJ41: 82 | BK41: 90 | BL41: 88 | BM41: 82 | BN41: 74 | BO41: 71 | BP41: 74 | BQ41: 66 | BR41: 70 | BS41: 69 | BT41: 65 | BU41: 64 | BV41: 63 | BX41: 161 | BY41: 29 | BZ41: 30 | CA41: 34 | CB41: 33 | CC41: 30 | CD41: 35 | CE41: 38 | CF41: 40
